Workbook

Sheet Read me
A1: PREMIER EXPORTS INTERNATIONAL
A2: BILLS REGISTER — HOW IT WORKS
B4: Every day, on the Bills sheet
B5: • New bill raised — next empty row: invoice no, invoice date, item, buyer, amount (US$).
B6: • Advance received — on that bill's row: Advance received (US$) and Advance date.
B7: • Payment realised — Realised (US$) and Realised date. When advance + realised reaches the amount,
B8: the bill turns Realised and leaves the Summary. A part payment leaves it open as Part realised.
B9: • Bank paid short and nothing more will come — Close as: Settled. The bill closes at the amount received.
B10: • Bill raised in error or withdrawn — Close as: Cancelled. It stays on the sheet, struck through,
B11: and counts nowhere. Partners can still see that it existed.
B12: • A wrong figure — click the cell and type over it. A line typed by mistake (never a real bill) —
B13: select its cells from Invoice no to Note and press Delete. The empty row is ignored.
B15: For the partners — the Summary sheet
B16: "As at" shows today's date by itself. Type a date to report as at another day; type =TODAY() to go back.
... B47: and KON as the item. Correct them if those are buyers.

Sheet Summary
B1: Premier Exports International | E1: AP X/453, NH-66 Highway, Chandiroor P.O.,
E2: Aroor, Alappuzha, Kerala - 688 537, India
E3: GSTIN 32AADFP3158P1ZZ
A5: BILLS ON HAND | G5: AS AT | H5: =TODAY() -> 46298
A6: EXPORT BILLS RECEIVABLE · BILLED, RECEIVED AND BALANCE DUE | G6: US$ → ₹ | H6: 90
A8: BILLS ON HAND | C8: BILLED | E8: RECEIVED AGAINST THEM | G8: BALANCE RECEIVABLE
A9: =COUNT(Bills!$R$7:$R$1006) -> 23 | C9: =SUMIFS(Bills!$E$7:$E$1006,Bills!$V$7:$V$1006,1) -> 1381574 | E9: =SUMIFS(Bills!$L$7:$L$1006,Bills!$V$7:$V$1006,1) -> 11000 | G9: =SUM(Bills!$T$7:$T$1006) -> 1370574
A10: ="of "&SUMPRODUCT(--(LEN(Bills!$O$7:$O$1006)>0))&" on the register" -> of 23 on the register | C10: =IF(FX="","Exchange rate not set","₹ "&IF(ABS(SUMIFS(Bills!$E$7:$E$1006,Bills!$V$7:$V$1006,1))*FX>=10000000,TEXT(SUMIFS(Bills!$E$7:$E$1006,Bills!$V$7:$V$1006,1)*FX/10000000,"0.00")&" Cr",IF(ABS(SUMIFS(Bills!$E$7:$E$1006,Bills!$V$7:$V$1006,1))*FX>=100000,TEXT(SUMIFS(Bills!$E$7:$E$1006,Bills!$V$7:$V$1006,1)*FX/100000,"0.00")&" L",TEXT(SUMIFS(Bills!$E$7:$E$1006,Bills!$V$7:$V$1006,1)*FX,"#,##0")))) -> ₹ 12.43 Cr | E10: =IF(FX="","Exchange rate not set","₹ "&IF(ABS(SUMIFS(Bills!$L$7:$L$1006,Bills!$V$7:$V$1006,1))*FX>=10000000,TEXT(SUMIFS(Bills!$L$7:$L$1006,Bills!$V$7:$V$1006,1)*FX/10000000,"0.00")&" Cr",IF(ABS(SUMIFS(Bills!$L$7:$L$1006,Bills!$V$7:$V$1006,1))*FX>=100000,TEXT(SUMIFS(Bills!$L$7:$L$1006,Bills!$V$7:$V$1006,1)*FX/100000,"0.00")&" L",TEXT(SUMIFS(Bills!$L$7:$L$1006,Bills!$V$7:$V$1006,1)*FX,"#,##0")))) -> ₹ 9.90 L | G10: =IF(FX="","Exchange rate not set","₹ "&IF(ABS(SUM(Bills!$T$7:$T$1006))*FX>=10000000,TEXT(SUM(Bills!$T$7:$T$1006)*FX/10000000,"0.00")&" Cr",IF(ABS(SUM(Bills!$T$7:$T$1006))*FX>=100000,TEXT(SUM(Bills!$T$7:$T$1006)*FX/100000,"0.00")&" L",TEXT(SUM(Bills!$T$7:$T$1006)*FX,"#,##0")))) -> ₹ 12.34 Cr
A11: ="Register: "&SUMPRODUCT(--(LEN(Bills!$O$7:$O$1006)>0))&" bills · "&COUNTIF(Bills!$O$7:$O$1006,"Realised")&" realised (US$ "&TEXT(SUMIFS(Bills!$E$7:$E$1006,Bills!$O$7:$O$1006,"Realised"),"#,##0")&") · "&COUNTIF(Bills!$O$7:$O$1006,"Cancelled")&" cancelled" -> Register: 23 bills · 0 realised (US$ 0) · 0 cancelled
A13: BALANCE BY BUYER — US$ | F13: AGEING OF BALANCE
A14: Buyer | B14: Bills | C14: Balance (US$) | D14: Balance (₹) | E14: Share | F14: Days outstanding | G14: Bills | H14: Balance (US$)
A15: =IF($J15="","",INDEX(Bills!$S$7:$S$1006,$J15)) -> Zoom | B15: =IF($J15="","",COUNTIFS(Bills!$S$7:$S$1006,$A15,Bills!$V$7:$V$1006,1)) -> 5 | C15: =IF($J15="","",SUMIFS(Bills!$T$7:$T$1006,Bills!$S$7:$S$1006,$A15)) -> 267456.08 | D15: =IF(OR($J15="",FX=""),"",$C15*FX) -> 24071047 | E15: =IF(OR($J15="",SUM(Bills!$T$7:$T$1006)=0),"",$C15/SUM(Bills!$T$7:$T$1006)) -> 0.19514166 | F15: 0–30 days | G15: =COUNTIFS(Bills!$Q$7:$Q$1006,$F15) -> 0 | H15: =SUMIFS(Bills!$T$7:$T$1006,Bills!$Q$7:$Q$1006,$F15) -> 0 | J15: =IFERROR(MATCH(LARGE(Bills!$U$7:$U$1006,1),Bills!$U$7:$U$1006,0),"") -> 1
A16: =IF($J16="","",INDEX(Bills!$S$7:$S$1006,$J16)) -> Shabeer | B16: =IF($J16="","",COUNTIFS(Bills!$S$7:$S$1006,$A16,Bills!$V$7:$V$1006,1)) -> 5 | C16: =IF($J16="","",SUMIFS(Bills!$T$7:$T$1006,Bills!$S$7:$S$1006,$A16)) -> 261580 | D16: =IF(OR($J16="",FX=""),"",$C16*FX) -> 23542200 | E16: =IF(OR($J16="",SUM(Bills!$T$7:$T$1006)=0),"",$C16/SUM(Bills!$T$7:$T$1006)) -> 0.19085435 | F16: 31–60 days | G16: =COUNTIFS(Bills!$Q$7:$Q$1006,$F16) -> 0 | H16: =SUMIFS(Bills!$T$7:$T$1006,Bills!$Q$7:$Q$1006,$F16) -> 0 | J16: =IFERROR(MATCH(LARGE(Bills!$U$7:$U$1006,2),Bills!$U$7:$U$1006,0),"") -> 4
A17: =IF($J17="","",INDEX(Bills!$S$7:$S$1006,$J17)) -> Aneesh | B17: =IF($J17="","",COUNTIFS(Bills!$S$7:$S$1006,$A17,Bills!$V$7:$V$1006,1)) -> 5 | C17: =IF($J17="","",SUMIFS(Bills!$T$7:$T$1006,Bills!$S$7:$S$1006,$A17)) -> 259866 | D17: =IF(OR($J17="",FX=""),"",$C17*FX) -> 23387940 | E17: =IF(OR($J17="",SUM(Bills!$T$7:$T$1006)=0),"",$C17/SUM(Bills!$T$7:$T$1006)) -> 0.18960377 | F17: 61–90 days | G17: =COUNTIFS(Bills!$Q$7:$Q$1006,$F17) -> 0 | H17: =SUMIFS(Bills!$T$7:$T$1006,Bills!$Q$7:$Q$1006,$F17) -> 0 | J17: =IFERROR(MATCH(LARGE(Bills!$U$7:$U$1006,3),Bills!$U$7:$U$1006,0),"") -> 7
A18: =IF($J18="","",INDEX(Bills!$S$7:$S$1006,$J18)) -> Buyer not noted | B18: =IF($J18="","",COUNTIFS(Bills!$S$7:$S$1006,$A18,Bills!$V$7:$V$1006,1)) -> 1 | C18: =IF($J18="","",SUMIFS(Bills!$T$7:$T$1006,Bills!$S$7:$S$1006,$A18)) -> 136312 | D18: =IF(OR($J18="",FX=""),"",$C18*FX) -> 12268080 | E18: =IF(OR($J18="",SUM(Bills!$T$7:$T$1006)=0),"",$C18/SUM(Bills!$T$7:$T$1006)) -> 0.099456142 | F18: Over 90 days | G18: =COUNTIFS(Bills!$Q$7:$Q$1006,$F18) -> 0 | H18: =SUMIFS(Bills!$T$7:$T$1006,Bills!$Q$7:$Q$1006,$F18) -> 0 | J18: =IFERROR(MATCH(LARGE(Bills!$U$7:$U$1006,4),Bills!$U$7:$U$1006,0),"") -> 6
A19: =IF($J19="","",INDEX(Bills!$S$7:$S$1006,$J19)) -> Kobe | B19: =IF($J19="","",COUNTIFS(Bills!$S$7:$S$1006,$A19,Bills!$V$7:$V$1006,1)) -> 1 | C19: =IF($J19="","",SUMIFS(Bills!$T$7:$T$1006,Bills!$S$7:$S$1006,$A19)) -> 122300 | D19: =IF(OR($J19="",FX=""),"",$C19*FX) -> 11007000 | E19: =IF(OR($J19="",SUM(Bills!$T$7:$T$1006)=0),"",$C19/SUM(Bills!$T$7:$T$1006)) -> 0.089232688 | F19: No invoice date | G19: =COUNTIFS(Bills!$Q$7:$Q$1006,$F19) -> 23 | H19: =SUMIFS(Bills!$T$7:$T$1006,Bills!$Q$7:$Q$1006,$F19) -> 1370574 | J19: =IFERROR(MATCH(LARGE(Bills!$U$7:$U$1006,5),Bills!$U$7:$U$1006,0),"") -> 18
A20: =IF($J20="","",INDEX(Bills!$S$7:$S$1006,$J20)) -> Jithin | B20: =IF($J20="","",COUNTIFS(Bills!$S$7:$S$1006,$A20,Bills!$V$7:$V$1006,1)) -> 2 | C20: =IF($J20="","",SUMIFS(Bills!$T$7:$T$1006,Bills!$S$7:$S$1006,$A20)) -> 104050 | D20: =IF(OR($J20="",FX=""),"",$C20*FX) -> 9364500 | E20: =IF(OR($J20="",SUM(Bills!$T$7:$T$1006)=0),"",$C20/SUM(Bills!$T$7:$T$1006)) -> 0.075917099 | F20: TOTAL | G20: =SUM(G15:G19) -> 23 | H20: =SUM(H15:H19) -> 1370574 | J20: =IFERROR(MATCH(LARGE(Bills!$U$7:$U$1006,6),Bills!$U$7:$U$1006,0),"") -> 17
A21: =IF($J21="","",INDEX(Bills!$S$7:$S$1006,$J21)) -> Irfan | B21: =IF($J21="","",COUNTIFS(Bills!$S$7:$S$1006,$A21,Bills!$V$7:$V$1006,1)) -> 1 | C21: =IF($J21="","",SUMIFS(Bills!$T$7:$T$1006,Bills!$S$7:$S$1006,$A21)) -> 57200 | D21: =IF(OR($J21="",FX=""),"",$C21*FX) -> 5148000 | E21: =IF(OR($J21="",SUM(Bills!$T$7:$T$1006)=0),"",$C21/SUM(Bills!$T$7:$T$1006)) -> 0.04173434 | J21: =IFERROR(MATCH(LARGE(Bills!$U$7:$U$1006,7),Bills!$U$7:$U$1006,0),"") -> 20
A22: =IF($J22="","",INDEX(Bills!$S$7:$S$1006,$J22)) -> Kaustuba, Bombay | B22: =IF($J22="","",COUNTIFS(Bills!$S$7:$S$1006,$A22,Bills!$V$7:$V$1006,1)) -> 1 | C22: =IF($J22="","",SUMIFS(Bills!$T$7:$T$1006,Bills!$S$7:$S$1006,$A22)) -> 55600 | D22: =IF(OR($J22="",FX=""),"",$C22*FX) -> 5004000 | E22: =IF(OR($J22="",SUM(Bills!$T$7:$T$1006)=0),"",$C22/SUM(Bills!$T$7:$T$1006)) -> 0.040566946 | F22: ADVANCES RECEIVED | J22: =IFERROR(MATCH(LARGE(Bills!$U$7:$U$1006,8),Bills!$U$7:$U$1006,0),"") -> 19
A23: =IF($J23="","",INDEX(Bills!$S$7:$S$1006,$J23)) -> part | B23: =IF($J23="","",COUNTIFS(Bills!$S$7:$S$1006,$A23,Bills!$V$7:$V$1006,1)) -> 1 | C23: =IF($J23="","",SUMIFS(Bills!$T$7:$T$1006,Bills!$S$7:$S$1006,$A23)) -> 53239.9 | D23: =IF(OR($J23="",FX=""),"",$C23*FX) -> 4791591 | E23: =IF(OR($J23="",SUM(Bills!$T$7:$T$1006)=0),"",$C23/SUM(Bills!$T$7:$T$1006)) -> 0.038844966 | F23: Invoice | G23: Buyer | H23: Advance (US$) | J23: =IFERROR(MATCH(LARGE(Bills!$U$7:$U$1006,9),Bills!$U$7:$U$1006,0),"") -> 15
A24: =IF($J24="","",INDEX(Bills!$S$7:$S$1006,$J24)) -> Ramiz | B24: =IF($J24="","",COUNTIFS(Bills!$S$7:$S$1006,$A24,Bills!$V$7:$V$1006,1)) -> 1 | C24: =IF($J24="","",SUMIFS(Bills!$T$7:$T$1006,Bills!$S$7:$S$1006,$A24)) -> 52970 | D24: =IF(OR($J24="",FX=""),"",$C24*FX) -> 4767300 | E24: =IF(OR($J24="",SUM(Bills!$T$7:$T$1006)=0),"",$C24/SUM(Bills!$T$7:$T$1006)) -> 0.038648041 | F24: =IF($K24="","",INDEX(Bills!$A$1:$A$1006,$K24)&"") -> PEI/47/2026-27 | G24: =IF($K24="","",INDEX(Bills!$S$1:$S$1006,$K24)) -> Jithin | H24: =IF($K24="","",INDEX(Bills!$F$1:$F$1006,$K24)) -> 3000 | J24: =IFERROR(MATCH(LARGE(Bills!$U$7:$U$1006,10),Bills!$U$7:$U$1006,0),"") -> 22 | K24: =IFERROR(SMALL(Bills!$W$7:$W$1006,1),"") -> 23
A25: =IF($J25="","",INDEX(Bills!$S$7:$S$1006,$J25)) | B25: =IF($J25="","",COUNTIFS(Bills!$S$7:$S$1006,$A25,Bills!$V$7:$V$1006,1)) | C25: =IF($J25="","",SUMIFS(Bills!$T$7:$T$1006,Bills!$S$7:$S$1006,$A25)) | D25: =IF(OR($J25="",FX=""),"",$C25*FX) | E25: =IF(OR($J25="",SUM(Bills!$T$7:$T$1006)=0),"",$C25/SUM(Bills!$T$7:$T$1006)) | F25: =IF($K25="","",INDEX(Bills!$A$1:$A$1006,$K25)&"") -> PEI/52/2026-27 | G25: =IF($K25="","",INDEX(Bills!$S$1:$S$1006,$K25)) -> Ramiz | H25: =IF($K25="","",INDEX(Bills!$F$1:$F$1006,$K25)) -> 5000 | J25: =IFERROR(MATCH(LARGE(Bills!$U$7:$U$1006,11),Bills!$U$7:$U$1006,0),"") | K25: =IFERROR(SMALL(Bills!$W$7:$W$1006,2),"") -> 28
A26: =IF($J26="","",INDEX(Bills!$S$7:$S$1006,$J26)) | B26: =IF($J26="","",COUNTIFS(Bills!$S$7:$S$1006,$A26,Bills!$V$7:$V$1006,1)) | C26: =IF($J26="","",SUMIFS(Bills!$T$7:$T$1006,Bills!$S$7:$S$1006,$A26)) | D26: =IF(OR($J26="",FX=""),"",$C26*FX) | E26: =IF(OR($J26="",SUM(Bills!$T$7:$T$1006)=0),"",$C26/SUM(Bills!$T$7:$T$1006)) | F26: =IF($K26="","",INDEX(Bills!$A$1:$A$1006,$K26)&"") -> PEI/53/2026-27 | G26: =IF($K26="","",INDEX(Bills!$S$1:$S$1006,$K26)) -> Jithin | H26: =IF($K26="","",INDEX(Bills!$F$1:$F$1006,$K26)) -> 3000 | J26: =IFERROR(MATCH(LARGE(Bills!$U$7:$U$1006,12),Bills!$U$7:$U$1006,0),"") | K26: =IFERROR(SMALL(Bills!$W$7:$W$1006,3),"") -> 29
A27: =IF(MAX(0,COUNT(Bills!$U$7:$U$1006)-12)>0,"Other buyers ("&MAX(0,COUNT(Bills!$U$7:$U$1006)-12)&")","") | B27: =IF(MAX(0,COUNT(Bills!$U$7:$U$1006)-12)>0,COUNT(Bills!$R$7:$R$1006)-SUM(B15:B26),"") | C27: =IF(MAX(0,COUNT(Bills!$U$7:$U$1006)-12)>0,SUM(Bills!$T$7:$T$1006)-SUM(C15:C26),"") | D27: =IF(OR(C27="",FX=""),"",C27*FX) | E27: =IF(OR(C27="",SUM(Bills!$T$7:$T$1006)=0),"",C27/SUM(Bills!$T$7:$T$1006)) | F27: =IF($K27="","",INDEX(Bills!$A$1:$A$1006,$K27)&"") | G27: =IF($K27="","",INDEX(Bills!$S$1:$S$1006,$K27)) | H27: =IF($K27="","",INDEX(Bills!$F$1:$F$1006,$K27)) | K27: =IFERROR(SMALL(Bills!$W$7:$W$1006,4),"")
A28: TOTAL | B28: =COUNT(Bills!$R$7:$R$1006) -> 23 | C28: =SUM(Bills!$T$7:$T$1006) -> 1370574 | D28: =IF(FX="","",C28*FX) -> 1.2335166e+08 | E28: =IF(C28=0,"",1) -> 1 | F28: =IF(COUNT(Bills!$W$7:$W$1006)=0,"None on open bills",COUNT(Bills!$W$7:$W$1006)&IF(COUNT(Bills!$W$7:$W$1006)=1," bill"," bills")&IF(COUNT(Bills!$W$7:$W$1006)>4,", "&(COUNT(Bills!$W$7:$W$1006)-4)&" not listed","")) -> 3 bills | H28: =SUMIFS(Bills!$F$7:$F$1006,Bills!$V$7:$V$1006,1) -> 11000
A29: =TRIM(IF(SUM(Bills!$Z$7:$Z$1006)>0,"Check Bills: "&SUM(Bills!$Z$7:$Z$1006)&" rows share an invoice no. ","")&IF(SUM(Bills!$Y$7:$Y$1006)>0,"Check Bills: "&SUM(Bills!$Y$7:$Y$1006)&" bills lack an invoice no or amount. ","")&IF(SUM(Bills!$X$7:$X$1006)>0,"Check Bills: "&SUM(Bills!$X$7:$X$1006)&" bills show more received than billed. ","")&IF(FX="","Exchange rate not set — rupee figures are blank.",""))
A31: BILLS ON HAND
A32: Invoice no | B32: Inv. date | C32: Item | D32: Buyer | E32: Amount (US$) | F32: Received (US$) | G32: Balance (US$) | H32: Balance (₹)
A33: ="TOTAL — "&COUNT(Bills!$R$7:$R$1006)&IF(COUNT(Bills!$R$7:$R$1006)=1," BILL"," BILLS")&" ON HAND" -> TOTAL — 23 BILLS ON HAND | E33: =SUMIFS(Bills!$E$7:$E$1006,Bills!$V$7:$V$1006,1) -> 1381574 | F33: =SUMIFS(Bills!$L$7:$L$1006,Bills!$V$7:$V$1006,1) -> 11000 | G33: =SUM(Bills!$T$7:$T$1006) -> 1370574 | H33: =IF(FX="","",G33*FX) -> 1.2335166e+08
A34: =IF($L34="","",IF(INDEX(Bills!$A$1:$A$1006,$L34)="","",INDEX(Bills!$A$1:$A$1006,$L34))) -> PEI/65/2025-26 | B34: =IF($L34="","",IF(INDEX(Bills!$B$1:$B$1006,$L34)="","",INDEX(Bills!$B$1:$B$1006,$L34))) | C34: =IF($L34="","",IF(INDEX(Bills!$C$1:$C$1006,$L34)="","",INDEX(Bills!$C$1:$C$1006,$L34))) -> Tuna | D34: =IF($L34="","",IF(INDEX(Bills!$D$1:$D$1006,$L34)="","",INDEX(Bills!$D$1:$D$1006,$L34))) -> Zoom | E34: =IF($L34="","",IF(INDEX(Bills!$E$1:$E$1006,$L34)="","",INDEX(Bills!$E$1:$E$1006,$L34))) -> 82360 | F34: =IF($L34="","",INDEX(Bills!$L$1:$L$1006,$L34)) -> 0 | G34: =IF($L34="","",INDEX(Bills!$M$1:$M$1006,$L34)) -> 82360 | H34: =IF($L34="","",INDEX(Bills!$N$1:$N$1006,$L34)) -> 7412400 | L34: =IFERROR(SMALL(Bills!$R$7:$R$1006,1),"") -> 7
A35: =IF($L35="","",IF(INDEX(Bills!$A$1:$A$1006,$L35)="","",INDEX(Bills!$A$1:$A$1006,$L35))) -> PEI/27/2026-27 | B35: =IF($L35="","",IF(INDEX(Bills!$B$1:$B$1006,$L35)="","",INDEX(Bills!$B$1:$B$1006,$L35))) | C35: =IF($L35="","",IF(INDEX(Bills!$C$1:$C$1006,$L35)="","",INDEX(Bills!$C$1:$C$1006,$L35))) -> Tuna | D35: =IF($L35="","",IF(INDEX(Bills!$D$1:$D$1006,$L35)="","",INDEX(Bills!$D$1:$D$1006,$L35))) -> Zoom | E35: =IF($L35="","",IF(INDEX(Bills!$E$1:$E$1006,$L35)="","",INDEX(Bills!$E$1:$E$1006,$L35))) -> 45820 | F35: =IF($L35="","",INDEX(Bills!$L$1:$L$1006,$L35)) -> 0 | G35: =IF($L35="","",INDEX(Bills!$M$1:$M$1006,$L35)) -> 45820 | H35: =IF($L35="","",INDEX(Bills!$N$1:$N$1006,$L35)) -> 4123800 | L35: =IFERROR(SMALL(Bills!$R$7:$R$1006,2),"") -> 8
A36: =IF($L36="","",IF(INDEX(Bills!$A$1:$A$1006,$L36)="","",INDEX(Bills!$A$1:$A$1006,$L36))) -> PEI/29/2026-27 | B36: =IF($L36="","",IF(INDEX(Bills!$B$1:$B$1006,$L36)="","",INDEX(Bills!$B$1:$B$1006,$L36))) | C36: =IF($L36="","",IF(INDEX(Bills!$C$1:$C$1006,$L36)="","",INDEX(Bills!$C$1:$C$1006,$L36))) -> Tuna | D36: =IF($L36="","",IF(INDEX(Bills!$D$1:$D$1006,$L36)="","",INDEX(Bills!$D$1:$D$1006,$L36))) -> Zoom | E36: =IF($L36="","",IF(INDEX(Bills!$E$1:$E$1006,$L36)="","",INDEX(Bills!$E$1:$E$1006,$L36))) -> 46476.08 | F36: =IF($L36="","",INDEX(Bills!$L$1:$L$1006,$L36)) -> 0 | G36: =IF($L36="","",INDEX(Bills!$M$1:$M$1006,$L36)) -> 46476.08 | H36: =IF($L36="","",INDEX(Bills!$N$1:$N$1006,$L36)) -> 4182847.2 | L36: =IFERROR(SMALL(Bills!$R$7:$R$1006,3),"") -> 9
A37: =IF($L37="","",IF(INDEX(Bills!$A$1:$A$1006,$L37)="","",INDEX(Bills!$A$1:$A$1006,$L37))) -> PEI/31/2026-27 | B37: =IF($L37="","",IF(INDEX(Bills!$B$1:$B$1006,$L37)="","",INDEX(Bills!$B$1:$B$1006,$L37))) | C37: =IF($L37="","",IF(INDEX(Bills!$C$1:$C$1006,$L37)="","",INDEX(Bills!$C$1:$C$1006,$L37))) -> Mackerel | D37: =IF($L37="","",IF(INDEX(Bills!$D$1:$D$1006,$L37)="","",INDEX(Bills!$D$1:$D$1006,$L37))) -> Shabeer | E37: =IF($L37="","",IF(INDEX(Bills!$E$1:$E$1006,$L37)="","",INDEX(Bills!$E$1:$E$1006,$L37))) -> 49720 | F37: =IF($L37="","",INDEX(Bills!$L$1:$L$1006,$L37)) -> 0 | G37: =IF($L37="","",INDEX(Bills!$M$1:$M$1006,$L37)) -> 49720 | H37: =IF($L37="","",INDEX(Bills!$N$1:$N$1006,$L37)) -> 4474800 | L37: =IFERROR(SMALL(Bills!$R$7:$R$1006,4),"") -> 10
A38: =IF($L38="","",IF(INDEX(Bills!$A$1:$A$1006,$L38)="","",INDEX(Bills!$A$1:$A$1006,$L38))) -> PEI/33/2026-27 | B38: =IF($L38="","",IF(INDEX(Bills!$B$1:$B$1006,$L38)="","",INDEX(Bills!$B$1:$B$1006,$L38))) | C38: =IF($L38="","",IF(INDEX(Bills!$C$1:$C$1006,$L38)="","",INDEX(Bills!$C$1:$C$1006,$L38))) -> Mackerel | D38: =IF($L38="","",IF(INDEX(Bills!$D$1:$D$1006,$L38)="","",INDEX(Bills!$D$1:$D$1006,$L38))) -> Shabeer | E38: =IF($L38="","",IF(INDEX(Bills!$E$1:$E$1006,$L38)="","",INDEX(Bills!$E$1:$E$1006,$L38))) -> 54060 | F38: =IF($L38="","",INDEX(Bills!$L$1:$L$1006,$L38)) -> 0 | G38: =IF($L38="","",INDEX(Bills!$M$1:$M$1006,$L38)) -> 54060 | H38: =IF($L38="","",INDEX(Bills!$N$1:$N$1006,$L38)) -> 4865400 | L38: =IFERROR(SMALL(Bills!$R$7:$R$1006,5),"") -> 11
A39: =IF($L39="","",IF(INDEX(Bills!$A$1:$A$1006,$L39)="","",INDEX(Bills!$A$1:$A$1006,$L39))) -> PEI/34/2026-27 | B39: =IF($L39="","",IF(INDEX(Bills!$B$1:$B$1006,$L39)="","",INDEX(Bills!$B$1:$B$1006,$L39))) | C39: =IF($L39="","",IF(INDEX(Bills!$C$1:$C$1006,$L39)="","",INDEX(Bills!$C$1:$C$1006,$L39))) -> Koyo | D39: =IF($L39="","",IF(INDEX(Bills!$D$1:$D$1006,$L39)="","",INDEX(Bills!$D$1:$D$1006,$L39))) | E39: =IF($L39="","",IF(INDEX(Bills!$E$1:$E$1006,$L39)="","",INDEX(Bills!$E$1:$E$1006,$L39))) -> 136312 | F39: =IF($L39="","",INDEX(Bills!$L$1:$L$1006,$L39)) -> 0 | G39: =IF($L39="","",INDEX(Bills!$M$1:$M$1006,$L39)) -> 136312 | H39: =IF($L39="","",INDEX(Bills!$N$1:$N$1006,$L39)) -> 12268080 | L39: =IFERROR(SMALL(Bills!$R$7:$R$1006,6),"") -> 12
A40: =IF($L40="","",IF(INDEX(Bills!$A$1:$A$1006,$L40)="","",INDEX(Bills!$A$1:$A$1006,$L40))) -> PEI/35/2026-27 | B40: =IF($L40="","",IF(INDEX(Bills!$B$1:$B$1006,$L40)="","",INDEX(Bills!$B$1:$B$1006,$L40))) | C40: =IF($L40="","",IF(INDEX(Bills!$C$1:$C$1006,$L40)="","",INDEX(Bills!$C$1:$C$1006,$L40))) -> Mackerel | D40: =IF($L40="","",IF(INDEX(Bills!$D$1:$D$1006,$L40)="","",INDEX(Bills!$D$1:$D$1006,$L40))) -> Aneesh | E40: =IF($L40="","",IF(INDEX(Bills!$E$1:$E$1006,$L40)="","",INDEX(Bills!$E$1:$E$1006,$L40))) -> 50482.5 | F40: =IF($L40="","",INDEX(Bills!$L$1:$L$1006,$L40)) -> 0 | G40: =IF($L40="","",INDEX(Bills!$M$1:$M$1006,$L40)) -> 50482.5 | H40: =IF($L40="","",INDEX(Bills!$N$1:$N$1006,$L40)) -> 4543425 | L40: =IFERROR(SMALL(Bills!$R$7:$R$1006,7),"") -> 13
A41: =IF($L41="","",IF(INDEX(Bills!$A$1:$A$1006,$L41)="","",INDEX(Bills!$A$1:$A$1006,$L41))) -> PEI/36/2026-27 | B41: =IF($L41="","",IF(INDEX(Bills!$B$1:$B$1006,$L41)="","",INDEX(Bills!$B$1:$B$1006,$L41))) | C41: =IF($L41="","",IF(INDEX(Bills!$C$1:$C$1006,$L41)="","",INDEX(Bills!$C$1:$C$1006,$L41))) -> Mackerel | D41: =IF($L41="","",IF(INDEX(Bills!$D$1:$D$1006,$L41)="","",INDEX(Bills!$D$1:$D$1006,$L41))) -> Shabeer | E41: =IF($L41="","",IF(INDEX(Bills!$E$1:$E$1006,$L41)="","",INDEX(Bills!$E$1:$E$1006,$L41))) -> 51500 | F41: =IF($L41="","",INDEX(Bills!$L$1:$L$1006,$L41)) -> 0 | G41: =IF($L41="","",INDEX(Bills!$M$1:$M$1006,$L41)) -> 51500 | H41: =IF($L41="","",INDEX(Bills!$N$1:$N$1006,$L41)) -> 4635000 | L41: =IFERROR(SMALL(Bills!$R$7:$R$1006,8),"") -> 14
A42: =IF($L42="","",IF(INDEX(Bills!$A$1:$A$1006,$L42)="","",INDEX(Bills!$A$1:$A$1006,$L42))) -> PEI/38/2026-27 | B42: =IF($L42="","",IF(INDEX(Bills!$B$1:$B$1006,$L42)="","",INDEX(Bills!$B$1:$B$1006,$L42))) | C42: =IF($L42="","",IF(INDEX(Bills!$C$1:$C$1006,$L42)="","",INDEX(Bills!$C$1:$C$1006,$L42))) -> Mackerel | D42: =IF($L42="","",IF(INDEX(Bills!$D$1:$D$1006,$L42)="","",INDEX(Bills!$D$1:$D$1006,$L42))) -> Aneesh | E42: =IF($L42="","",IF(INDEX(Bills!$E$1:$E$1006,$L42)="","",INDEX(Bills!$E$1:$E$1006,$L42))) -> 50700 | F42: =IF($L42="","",INDEX(Bills!$L$1:$L$1006,$L42)) -> 0 | G42: =IF($L42="","",INDEX(Bills!$M$1:$M$1006,$L42)) -> 50700 | H42: =IF($L42="","",INDEX(Bills!$N$1:$N$1006,$L42)) -> 4563000 | L42: =IFERROR(SMALL(Bills!$R$7:$R$1006,9),"") -> 15
A43: =IF($L43="","",IF(INDEX(Bills!$A$1:$A$1006,$L43)="","",INDEX(Bills!$A$1:$A$1006,$L43))) -> PEI/39/2026-27 | B43: =IF($L43="","",IF(INDEX(Bills!$B$1:$B$1006,$L43)="","",INDEX(Bills!$B$1:$B$1006,$L43))) | C43: =IF($L43="","",IF(INDEX(Bills!$C$1:$C$1006,$L43)="","",INDEX(Bills!$C$1:$C$1006,$L43))) -> Mackerel | D43: =IF($L43="","",IF(INDEX(Bills!$D$1:$D$1006,$L43)="","",INDEX(Bills!$D$1:$D$1006,$L43))) -> Shabeer | E43: =IF($L43="","",IF(INDEX(Bills!$E$1:$E$1006,$L43)="","",INDEX(Bills!$E$1:$E$1006,$L43))) -> 53300 | F43: =IF($L43="","",INDEX(Bills!$L$1:$L$1006,$L43)) -> 0 | G43: =IF($L43="","",INDEX(Bills!$M$1:$M$1006,$L43)) -> 53300 | H43: =IF($L43="","",INDEX(Bills!$N$1:$N$1006,$L43)) -> 4797000 | L43: =IFERROR(SMALL(Bills!$R$7:$R$1006,10),"") -> 16
A44: =IF($L44="","",IF(INDEX(Bills!$A$1:$A$1006,$L44)="","",INDEX(Bills!$A$1:$A$1006,$L44))) -> PEI/40/2026-27 | B44: =IF($L44="","",IF(INDEX(Bills!$B$1:$B$1006,$L44)="","",INDEX(Bills!$B$1:$B$1006,$L44))) | C44: =IF($L44="","",IF(INDEX(Bills!$C$1:$C$1006,$L44)="","",INDEX(Bills!$C$1:$C$1006,$L44))) -> Tuna | D44: =IF($L44="","",IF(INDEX(Bills!$D$1:$D$1006,$L44)="","",INDEX(Bills!$D$1:$D$1006,$L44))) -> Zoom | E44: =IF($L44="","",IF(INDEX(Bills!$E$1:$E$1006,$L44)="","",INDEX(Bills!$E$1:$E$1006,$L44))) -> 46400 | F44: =IF($L44="","",INDEX(Bills!$L$1:$L$1006,$L44)) -> 0 | G44: =IF($L44="","",INDEX(Bills!$M$1:$M$1006,$L44)) -> 46400 | H44: =IF($L44="","",INDEX(Bills!$N$1:$N$1006,$L44)) -> 4176000 | L44: =IFERROR(SMALL(Bills!$R$7:$R$1006,11),"") -> 17
...

Sheet Bills
A1: PREMIER EXPORTS INTERNATIONAL
A2: BILLS REGISTER — ONE ROW PER EXPORT BILL, OPEN OR CLOSED
A3: ="As at "&TEXT(AsAt,"dd/mm/yyyy")&" · US$ → ₹ "&IF(FX="","not set",TEXT(FX,"0.00"))&" · On hand: "&COUNT(Bills!$R$7:$R$1006)&" bills, US$ "&TEXT(SUM(Bills!$T$7:$T$1006),"#,##0.00")&" (set the date and rate on Summary)" -> As at 03/10/2026 · US$ → ₹ 90.00 · On hand: 23 bills, US$ 1,370,573.98 (set the date and rate on Summary)
A4: Type in the white columns (blue text). Received, balance, status and age are worked out. Close a bill by realising it, or with Close as: Settled / Cancelled — do not clear it.
A5: TYPE HERE | L5: WORKED OUT — LOCKED
A6: Invoice no | B6: Invoice date | C6: Item | D6: Buyer | E6: Amount (US$) | F6: Advance received (US$) | G6: Advance date | H6: Realised (US$) | I6: Realised date | J6: Close as | K6: Note | L6: Received (US$) | M6: Balance (US$) | N6: Balance (₹) | O6: Status | P6: Days out | Q6: Age | R6: List key | S6: Buyer key | T6: Open balance | U6: Buyer rank | V6: Open | W6: Advance key | X6: Over-received | Y6: Missing data | Z6: Duplicate inv.
A7: PEI/65/2025-26 | C7: Tuna | D7: Zoom | E7: 82360 | L7: =IF(OR($A7<>"",$E7<>""),N($F7)+N($H7),"") -> 0 | M7: =IF(OR($O7="",$O7="Cancelled",$O7="Amount missing"),"",IF($O7="Realised",0,$E7-N($F7)-N($H7))) -> 82360 | N7: =IF(OR($M7="",FX=""),"",$M7*FX) -> 7412400 | O7: =IF(NOT(OR($A7<>"",$E7<>"")),"",IF($J7="Cancelled","Cancelled",IF($E7="","Amount missing",IF(OR($J7="Settled",$E7-N($F7)-N($H7)<=0.005),"Realised",IF(N($H7)>0,"Part realised",IF(N($F7)>0,"Advance received","On hand")))))) -> On hand | P7: =IF(AND($V7=1,ISNUMBER($B7)),AsAt-$B7,"") | Q7: =IF($V7<>1,"",IF($P7="","No invoice date",IF($P7<=30,"0–30 days",IF($P7<=60,"31–60 days",IF($P7<=90,"61–90 days","Over 90 days"))))) -> No invoice date | R7: =IF($V7=1,ROW(),"") -> 7 | S7: =IF(OR($A7<>"",$E7<>""),IF(TRIM($D7)="","Buyer not noted",TRIM($D7)),"") -> Zoom | T7: =IF(AND($V7=1,ISNUMBER($M7)),$M7,0) -> 82360 | U7: =IF($V7=1,IF(COUNTIFS($S$7:$S7,$S7,$V$7:$V7,1)=1,SUMIFS($T$7:$T$1006,$S$7:$S$1006,$S7)-ROW()/1000000000,""),"") -> 267456.08 | V7: =IF(OR($O7="On hand",$O7="Advance received",$O7="Part realised",$O7="Amount missing"),1,0) -> 1 | W7: =IF(AND($V7=1,N($F7)>0),ROW(),"") | X7: =IF(AND(OR($A7<>"",$E7<>""),$O7<>"Cancelled",ISNUMBER($E7),N($F7)+N($H7)>$E7+0.005),1,0) -> 0 | Y7: =IF(AND(OR($A7<>"",$E7<>""),OR($A7="",$E7="")),1,0) -> 0 | Z7: =IF(AND($A7<>"",COUNTIF($A$7:$A$1006,$A7)>1),1,0) -> 0
A8: PEI/27/2026-27 | C8: Tuna | D8: Zoom | E8: 45820 | L8: =IF(OR($A8<>"",$E8<>""),N($F8)+N($H8),"") -> 0 | M8: =IF(OR($O8="",$O8="Cancelled",$O8="Amount missing"),"",IF($O8="Realised",0,$E8-N($F8)-N($H8))) -> 45820 | N8: =IF(OR($M8="",FX=""),"",$M8*FX) -> 4123800 | O8: =IF(NOT(OR($A8<>"",$E8<>"")),"",IF($J8="Cancelled","Cancelled",IF($E8="","Amount missing",IF(OR($J8="Settled",$E8-N($F8)-N($H8)<=0.005),"Realised",IF(N($H8)>0,"Part realised",IF(N($F8)>0,"Advance received","On hand")))))) -> On hand | P8: =IF(AND($V8=1,ISNUMBER($B8)),AsAt-$B8,"") | Q8: =IF($V8<>1,"",IF($P8="","No invoice date",IF($P8<=30,"0–30 days",IF($P8<=60,"31–60 days",IF($P8<=90,"61–90 days","Over 90 days"))))) -> No invoice date | R8: =IF($V8=1,ROW(),"") -> 8 | S8: =IF(OR($A8<>"",$E8<>""),IF(TRIM($D8)="","Buyer not noted",TRIM($D8)),"") -> Zoom | T8: =IF(AND($V8=1,ISNUMBER($M8)),$M8,0) -> 45820 | U8: =IF($V8=1,IF(COUNTIFS($S$7:$S8,$S8,$V$7:$V8,1)=1,SUMIFS($T$7:$T$1006,$S$7:$S$1006,$S8)-ROW()/1000000000,""),"") | V8: =IF(OR($O8="On hand",$O8="Advance received",$O8="Part realised",$O8="Amount missing"),1,0) -> 1 | W8: =IF(AND($V8=1,N($F8)>0),ROW(),"") | X8: =IF(AND(OR($A8<>"",$E8<>""),$O8<>"Cancelled",ISNUMBER($E8),N($F8)+N($H8)>$E8+0.005),1,0) -> 0 | Y8: =IF(AND(OR($A8<>"",$E8<>""),OR($A8="",$E8="")),1,0) -> 0 | Z8: =IF(AND($A8<>"",COUNTIF($A$7:$A$1006,$A8)>1),1,0) -> 0
A9: PEI/29/2026-27 | C9: Tuna | D9: Zoom | E9: 46476.08 | L9: =IF(OR($A9<>"",$E9<>""),N($F9)+N($H9),"") -> 0 | M9: =IF(OR($O9="",$O9="Cancelled",$O9="Amount missing"),"",IF($O9="Realised",0,$E9-N($F9)-N($H9))) -> 46476.08 | N9: =IF(OR($M9="",FX=""),"",$M9*FX) -> 4182847.2 | O9: =IF(NOT(OR($A9<>"",$E9<>"")),"",IF($J9="Cancelled","Cancelled",IF($E9="","Amount missing",IF(OR($J9="Settled",$E9-N($F9)-N($H9)<=0.005),"Realised",IF(N($H9)>0,"Part realised",IF(N($F9)>0,"Advance received","On hand")))))) -> On hand | P9: =IF(AND($V9=1,ISNUMBER($B9)),AsAt-$B9,"") | Q9: =IF($V9<>1,"",IF($P9="","No invoice date",IF($P9<=30,"0–30 days",IF($P9<=60,"31–60 days",IF($P9<=90,"61–90 days","Over 90 days"))))) -> No invoice date | R9: =IF($V9=1,ROW(),"") -> 9 | S9: =IF(OR($A9<>"",$E9<>""),IF(TRIM($D9)="","Buyer not noted",TRIM($D9)),"") -> Zoom | T9: =IF(AND($V9=1,ISNUMBER($M9)),$M9,0) -> 46476.08 | U9: =IF($V9=1,IF(COUNTIFS($S$7:$S9,$S9,$V$7:$V9,1)=1,SUMIFS($T$7:$T$1006,$S$7:$S$1006,$S9)-ROW()/1000000000,""),"") | V9: =IF(OR($O9="On hand",$O9="Advance received",$O9="Part realised",$O9="Amount missing"),1,0) -> 1 | W9: =IF(AND($V9=1,N($F9)>0),ROW(),"") | X9: =IF(AND(OR($A9<>"",$E9<>""),$O9<>"Cancelled",ISNUMBER($E9),N($F9)+N($H9)>$E9+0.005),1,0) -> 0 | Y9: =IF(AND(OR($A9<>"",$E9<>""),OR($A9="",$E9="")),1,0) -> 0 | Z9: =IF(AND($A9<>"",COUNTIF($A$7:$A$1006,$A9)>1),1,0) -> 0
A10: PEI/31/2026-27 | C10: Mackerel | D10: Shabeer | E10: 49720 | L10: =IF(OR($A10<>"",$E10<>""),N($F10)+N($H10),"") -> 0 | M10: =IF(OR($O10="",$O10="Cancelled",$O10="Amount missing"),"",IF($O10="Realised",0,$E10-N($F10)-N($H10))) -> 49720 | N10: =IF(OR($M10="",FX=""),"",$M10*FX) -> 4474800 | O10: =IF(NOT(OR($A10<>"",$E10<>"")),"",IF($J10="Cancelled","Cancelled",IF($E10="","Amount missing",IF(OR($J10="Settled",$E10-N($F10)-N($H10)<=0.005),"Realised",IF(N($H10)>0,"Part realised",IF(N($F10)>0,"Advance received","On hand")))))) -> On hand | P10: =IF(AND($V10=1,ISNUMBER($B10)),AsAt-$B10,"") | Q10: =IF($V10<>1,"",IF($P10="","No invoice date",IF($P10<=30,"0–30 days",IF($P10<=60,"31–60 days",IF($P10<=90,"61–90 days","Over 90 days"))))) -> No invoice date | R10: =IF($V10=1,ROW(),"") -> 10 | S10: =IF(OR($A10<>"",$E10<>""),IF(TRIM($D10)="","Buyer not noted",TRIM($D10)),"") -> Shabeer | T10: =IF(AND($V10=1,ISNUMBER($M10)),$M10,0) -> 49720 | U10: =IF($V10=1,IF(COUNTIFS($S$7:$S10,$S10,$V$7:$V10,1)=1,SUMIFS($T$7:$T$1006,$S$7:$S$1006,$S10)-ROW()/1000000000,""),"") -> 261580 | V10: =IF(OR($O10="On hand",$O10="Advance received",$O10="Part realised",$O10="Amount missing"),1,0) -> 1 | W10: =IF(AND($V10=1,N($F10)>0),ROW(),"") | X10: =IF(AND(OR($A10<>"",$E10<>""),$O10<>"Cancelled",ISNUMBER($E10),N($F10)+N($H10)>$E10+0.005),1,0) -> 0 | Y10: =IF(AND(OR($A10<>"",$E10<>""),OR($A10="",$E10="")),1,0) -> 0 | Z10: =IF(AND($A10<>"",COUNTIF($A$7:$A$1006,$A10)>1),1,0) -> 0
A11: PEI/33/2026-27 | C11: Mackerel | D11: Shabeer | E11: 54060 | L11: =IF(OR($A11<>"",$E11<>""),N($F11)+N($H11),"") -> 0 | M11: =IF(OR($O11="",$O11="Cancelled",$O11="Amount missing"),"",IF($O11="Realised",0,$E11-N($F11)-N($H11))) -> 54060 | N11: =IF(OR($M11="",FX=""),"",$M11*FX) -> 4865400 | O11: =IF(NOT(OR($A11<>"",$E11<>"")),"",IF($J11="Cancelled","Cancelled",IF($E11="","Amount missing",IF(OR($J11="Settled",$E11-N($F11)-N($H11)<=0.005),"Realised",IF(N($H11)>0,"Part realised",IF(N($F11)>0,"Advance received","On hand")))))) -> On hand | P11: =IF(AND($V11=1,ISNUMBER($B11)),AsAt-$B11,"") | Q11: =IF($V11<>1,"",IF($P11="","No invoice date",IF($P11<=30,"0–30 days",IF($P11<=60,"31–60 days",IF($P11<=90,"61–90 days","Over 90 days"))))) -> No invoice date | R11: =IF($V11=1,ROW(),"") -> 11 | S11: =IF(OR($A11<>"",$E11<>""),IF(TRIM($D11)="","Buyer not noted",TRIM($D11)),"") -> Shabeer | T11: =IF(AND($V11=1,ISNUMBER($M11)),$M11,0) -> 54060 | U11: =IF($V11=1,IF(COUNTIFS($S$7:$S11,$S11,$V$7:$V11,1)=1,SUMIFS($T$7:$T$1006,$S$7:$S$1006,$S11)-ROW()/1000000000,""),"") | V11: =IF(OR($O11="On hand",$O11="Advance received",$O11="Part realised",$O11="Amount missing"),1,0) -> 1 | W11: =IF(AND($V11=1,N($F11)>0),ROW(),"") | X11: =IF(AND(OR($A11<>"",$E11<>""),$O11<>"Cancelled",ISNUMBER($E11),N($F11)+N($H11)>$E11+0.005),1,0) -> 0 | Y11: =IF(AND(OR($A11<>"",$E11<>""),OR($A11="",$E11="")),1,0) -> 0 | Z11: =IF(AND($A11<>"",COUNTIF($A$7:$A$1006,$A11)>1),1,0) -> 0
A12: PEI/34/2026-27 | C12: Koyo | E12: 136312 | L12: =IF(OR($A12<>"",$E12<>""),N($F12)+N($H12),"") -> 0 | M12: =IF(OR($O12="",$O12="Cancelled",$O12="Amount missing"),"",IF($O12="Realised",0,$E12-N($F12)-N($H12))) -> 136312 | N12: =IF(OR($M12="",FX=""),"",$M12*FX) -> 12268080 | O12: =IF(NOT(OR($A12<>"",$E12<>"")),"",IF($J12="Cancelled","Cancelled",IF($E12="","Amount missing",IF(OR($J12="Settled",$E12-N($F12)-N($H12)<=0.005),"Realised",IF(N($H12)>0,"Part realised",IF(N($F12)>0,"Advance received","On hand")))))) -> On hand | P12: =IF(AND($V12=1,ISNUMBER($B12)),AsAt-$B12,"") | Q12: =IF($V12<>1,"",IF($P12="","No invoice date",IF($P12<=30,"0–30 days",IF($P12<=60,"31–60 days",IF($P12<=90,"61–90 days","Over 90 days"))))) -> No invoice date | R12: =IF($V12=1,ROW(),"") -> 12 | S12: =IF(OR($A12<>"",$E12<>""),IF(TRIM($D12)="","Buyer not noted",TRIM($D12)),"") -> Buyer not noted | T12: =IF(AND($V12=1,ISNUMBER($M12)),$M12,0) -> 136312 | U12: =IF($V12=1,IF(COUNTIFS($S$7:$S12,$S12,$V$7:$V12,1)=1,SUMIFS($T$7:$T$1006,$S$7:$S$1006,$S12)-ROW()/1000000000,""),"") -> 136312 | V12: =IF(OR($O12="On hand",$O12="Advance received",$O12="Part realised",$O12="Amount missing"),1,0) -> 1 | W12: =IF(AND($V12=1,N($F12)>0),ROW(),"") | X12: =IF(AND(OR($A12<>"",$E12<>""),$O12<>"Cancelled",ISNUMBER($E12),N($F12)+N($H12)>$E12+0.005),1,0) -> 0 | Y12: =IF(AND(OR($A12<>"",$E12<>""),OR($A12="",$E12="")),1,0) -> 0 | Z12: =IF(AND($A12<>"",COUNTIF($A$7:$A$1006,$A12)>1),1,0) -> 0
A13: PEI/35/2026-27 | C13: Mackerel | D13: Aneesh | E13: 50482.5 | K13: Original ✓ | L13: =IF(OR($A13<>"",$E13<>""),N($F13)+N($H13),"") -> 0 | M13: =IF(OR($O13="",$O13="Cancelled",$O13="Amount missing"),"",IF($O13="Realised",0,$E13-N($F13)-N($H13))) -> 50482.5 | N13: =IF(OR($M13="",FX=""),"",$M13*FX) -> 4543425 | O13: =IF(NOT(OR($A13<>"",$E13<>"")),"",IF($J13="Cancelled","Cancelled",IF($E13="","Amount missing",IF(OR($J13="Settled",$E13-N($F13)-N($H13)<=0.005),"Realised",IF(N($H13)>0,"Part realised",IF(N($F13)>0,"Advance received","On hand")))))) -> On hand | P13: =IF(AND($V13=1,ISNUMBER($B13)),AsAt-$B13,"") | Q13: =IF($V13<>1,"",IF($P13="","No invoice date",IF($P13<=30,"0–30 days",IF($P13<=60,"31–60 days",IF($P13<=90,"61–90 days","Over 90 days"))))) -> No invoice date | R13: =IF($V13=1,ROW(),"") -> 13 | S13: =IF(OR($A13<>"",$E13<>""),IF(TRIM($D13)="","Buyer not noted",TRIM($D13)),"") -> Aneesh | T13: =IF(AND($V13=1,ISNUMBER($M13)),$M13,0) -> 50482.5 | U13: =IF($V13=1,IF(COUNTIFS($S$7:$S13,$S13,$V$7:$V13,1)=1,SUMIFS($T$7:$T$1006,$S$7:$S$1006,$S13)-ROW()/1000000000,""),"") -> 259866 | V13: =IF(OR($O13="On hand",$O13="Advance received",$O13="Part realised",$O13="Amount missing"),1,0) -> 1 | W13: =IF(AND($V13=1,N($F13)>0),ROW(),"") | X13: =IF(AND(OR($A13<>"",$E13<>""),$O13<>"Cancelled",ISNUMBER($E13),N($F13)+N($H13)>$E13+0.005),1,0) -> 0 | Y13: =IF(AND(OR($A13<>"",$E13<>""),OR($A13="",$E13="")),1,0) -> 0 | Z13: =IF(AND($A13<>"",COUNTIF($A$7:$A$1006,$A13)>1),1,0) -> 0
A14: PEI/36/2026-27 | C14: Mackerel | D14: Shabeer | E14: 51500 | K14: Original ✓ | L14: =IF(OR($A14<>"",$E14<>""),N($F14)+N($H14),"") -> 0 | M14: =IF(OR($O14="",$O14="Cancelled",$O14="Amount missing"),"",IF($O14="Realised",0,$E14-N($F14)-N($H14))) -> 51500 | N14: =IF(OR($M14="",FX=""),"",$M14*FX) -> 4635000 | O14: =IF(NOT(OR($A14<>"",$E14<>"")),"",IF($J14="Cancelled","Cancelled",IF($E14="","Amount missing",IF(OR($J14="Settled",$E14-N($F14)-N($H14)<=0.005),"Realised",IF(N($H14)>0,"Part realised",IF(N($F14)>0,"Advance received","On hand")))))) -> On hand | P14: =IF(AND($V14=1,ISNUMBER($B14)),AsAt-$B14,"") | Q14: =IF($V14<>1,"",IF($P14="","No invoice date",IF($P14<=30,"0–30 days",IF($P14<=60,"31–60 days",IF($P14<=90,"61–90 days","Over 90 days"))))) -> No invoice date | R14: =IF($V14=1,ROW(),"") -> 14 | S14: =IF(OR($A14<>"",$E14<>""),IF(TRIM($D14)="","Buyer not noted",TRIM($D14)),"") -> Shabeer | T14: =IF(AND($V14=1,ISNUMBER($M14)),$M14,0) -> 51500 | U14: =IF($V14=1,IF(COUNTIFS($S$7:$S14,$S14,$V$7:$V14,1)=1,SUMIFS($T$7:$T$1006,$S$7:$S$1006,$S14)-ROW()/1000000000,""),"") | V14: =IF(OR($O14="On hand",$O14="Advance received",$O14="Part realised",$O14="Amount missing"),1,0) -> 1 | W14: =IF(AND($V14=1,N($F14)>0),ROW(),"") | X14: =IF(AND(OR($A14<>"",$E14<>""),$O14<>"Cancelled",ISNUMBER($E14),N($F14)+N($H14)>$E14+0.005),1,0) -> 0 | Y14: =IF(AND(OR($A14<>"",$E14<>""),OR($A14="",$E14="")),1,0) -> 0 | Z14: =IF(AND($A14<>"",COUNTIF($A$7:$A$1006,$A14)>1),1,0) -> 0
A15: PEI/38/2026-27 | C15: Mackerel | D15: Aneesh | E15: 50700 | K15: Original ✓ | L15: =IF(OR($A15<>"",$E15<>""),N($F15)+N($H15),"") -> 0 | M15: =IF(OR($O15="",$O15="Cancelled",$O15="Amount missing"),"",IF($O15="Realised",0,$E15-N($F15)-N($H15))) -> 50700 | N15: =IF(OR($M15="",FX=""),"",$M15*FX) -> 4563000 | O15: =IF(NOT(OR($A15<>"",$E15<>"")),"",IF($J15="Cancelled","Cancelled",IF($E15="","Amount missing",IF(OR($J15="Settled",$E15-N($F15)-N($H15)<=0.005),"Realised",IF(N($H15)>0,"Part realised",IF(N($F15)>0,"Advance received","On hand")))))) -> On hand | P15: =IF(AND($V15=1,ISNUMBER($B15)),AsAt-$B15,"") | Q15: =IF($V15<>1,"",IF($P15="","No invoice date",IF($P15<=30,"0–30 days",IF($P15<=60,"31–60 days",IF($P15<=90,"61–90 days","Over 90 days"))))) -> No invoice date | R15: =IF($V15=1,ROW(),"") -> 15 | S15: =IF(OR($A15<>"",$E15<>""),IF(TRIM($D15)="","Buyer not noted",TRIM($D15)),"") -> Aneesh | T15: =IF(AND($V15=1,ISNUMBER($M15)),$M15,0) -> 50700 | U15: =IF($V15=1,IF(COUNTIFS($S$7:$S15,$S15,$V$7:$V15,1)=1,SUMIFS($T$7:$T$1006,$S$7:$S$1006,$S15)-ROW()/1000000000,""),"") | V15: =IF(OR($O15="On hand",$O15="Advance received",$O15="Part realised",$O15="Amount missing"),1,0) -> 1 | W15: =IF(AND($V15=1,N($F15)>0),ROW(),"") | X15: =IF(AND(OR($A15<>"",$E15<>""),$O15<>"Cancelled",ISNUMBER($E15),N($F15)+N($H15)>$E15+0.005),1,0) -> 0 | Y15: =IF(AND(OR($A15<>"",$E15<>""),OR($A15="",$E15="")),1,0) -> 0 | Z15: =IF(AND($A15<>"",COUNTIF($A$7:$A$1006,$A15)>1),1,0) -> 0
A16: PEI/39/2026-27 | C16: Mackerel | D16: Shabeer | E16: 53300 | K16: Original ✓ | L16: =IF(OR($A16<>"",$E16<>""),N($F16)+N($H16),"") -> 0 | M16: =IF(OR($O16="",$O16="Cancelled",$O16="Amount missing"),"",IF($O16="Realised",0,$E16-N($F16)-N($H16))) -> 53300 | N16: =IF(OR($M16="",FX=""),"",$M16*FX) -> 4797000 | O16: =IF(NOT(OR($A16<>"",$E16<>"")),"",IF($J16="Cancelled","Cancelled",IF($E16="","Amount missing",IF(OR($J16="Settled",$E16-N($F16)-N($H16)<=0.005),"Realised",IF(N($H16)>0,"Part realised",IF(N($F16)>0,"Advance received","On hand")))))) -> On hand | P16: =IF(AND($V16=1,ISNUMBER($B16)),AsAt-$B16,"") | Q16: =IF($V16<>1,"",IF($P16="","No invoice date",IF($P16<=30,"0–30 days",IF($P16<=60,"31–60 days",IF($P16<=90,"61–90 days","Over 90 days"))))) -> No invoice date | R16: =IF($V16=1,ROW(),"") -> 16 | S16: =IF(OR($A16<>"",$E16<>""),IF(TRIM($D16)="","Buyer not noted",TRIM($D16)),"") -> Shabeer | T16: =IF(AND($V16=1,ISNUMBER($M16)),$M16,0) -> 53300 | U16: =IF($V16=1,IF(COUNTIFS($S$7:$S16,$S16,$V$7:$V16,1)=1,SUMIFS($T$7:$T$1006,$S$7:$S$1006,$S16)-ROW()/1000000000,""),"") | V16: =IF(OR($O16="On hand",$O16="Advance received",$O16="Part realised",$O16="Amount missing"),1,0) -> 1 | W16: =IF(AND($V16=1,N($F16)>0),ROW(),"") | X16: =IF(AND(OR($A16<>"",$E16<>""),$O16<>"Cancelled",ISNUMBER($E16),N($F16)+N($H16)>$E16+0.005),1,0) -> 0 | Y16: =IF(AND(OR($A16<>"",$E16<>""),OR($A16="",$E16="")),1,0) -> 0 | Z16: =IF(AND($A16<>"",COUNTIF($A$7:$A$1006,$A16)>1),1,0) -> 0
A17: PEI/40/2026-27 | C17: Tuna | D17: Zoom | E17: 46400 | L17: =IF(OR($A17<>"",$E17<>""),N($F17)+N($H17),"") -> 0 | M17: =IF(OR($O17="",$O17="Cancelled",$O17="Amount missing"),"",IF($O17="Realised",0,$E17-N($F17)-N($H17))) -> 46400 | N17: =IF(OR($M17="",FX=""),"",$M17*FX) -> 4176000 | O17: =IF(NOT(OR($A17<>"",$E17<>"")),"",IF($J17="Cancelled","Cancelled",IF($E17="","Amount missing",IF(OR($J17="Settled",$E17-N($F17)-N($H17)<=0.005),"Realised",IF(N($H17)>0,"Part realised",IF(N($F17)>0,"Advance received","On hand")))))) -> On hand | P17: =IF(AND($V17=1,ISNUMBER($B17)),AsAt-$B17,"") | Q17: =IF($V17<>1,"",IF($P17="","No invoice date",IF($P17<=30,"0–30 days",IF($P17<=60,"31–60 days",IF($P17<=90,"61–90 days","Over 90 days"))))) -> No invoice date | R17: =IF($V17=1,ROW(),"") -> 17 | S17: =IF(OR($A17<>"",$E17<>""),IF(TRIM($D17)="","Buyer not noted",TRIM($D17)),"") -> Zoom | T17: =IF(AND($V17=1,ISNUMBER($M17)),$M17,0) -> 46400 | U17: =IF($V17=1,IF(COUNTIFS($S$7:$S17,$S17,$V$7:$V17,1)=1,SUMIFS($T$7:$T$1006,$S$7:$S$1006,$S17)-ROW()/1000000000,""),"") | V17: =IF(OR($O17="On hand",$O17="Advance received",$O17="Part realised",$O17="Amount missing"),1,0) -> 1 | W17: =IF(AND($V17=1,N($F17)>0),ROW(),"") | X17: =IF(AND(OR($A17<>"",$E17<>""),$O17<>"Cancelled",ISNUMBER($E17),N($F17)+N($H17)>$E17+0.005),1,0) -> 0 | Y17: =IF(AND(OR($A17<>"",$E17<>""),OR($A17="",$E17="")),1,0) -> 0 | Z17: =IF(AND($A17<>"",COUNTIF($A$7:$A$1006,$A17)>1),1,0) -> 0
A18: PEI/41/2026-27 | C18: Mackerel | D18: Aneesh | E18: 53067 | K18: Original ✓ | L18: =IF(OR($A18<>"",$E18<>""),N($F18)+N($H18),"") -> 0 | M18: =IF(OR($O18="",$O18="Cancelled",$O18="Amount missing"),"",IF($O18="Realised",0,$E18-N($F18)-N($H18))) -> 53067 | N18: =IF(OR($M18="",FX=""),"",$M18*FX) -> 4776030 | O18: =IF(NOT(OR($A18<>"",$E18<>"")),"",IF($J18="Cancelled","Cancelled",IF($E18="","Amount missing",IF(OR($J18="Settled",$E18-N($F18)-N($H18)<=0.005),"Realised",IF(N($H18)>0,"Part realised",IF(N($F18)>0,"Advance received","On hand")))))) -> On hand | P18: =IF(AND($V18=1,ISNUMBER($B18)),AsAt-$B18,"") | Q18: =IF($V18<>1,"",IF($P18="","No invoice date",IF($P18<=30,"0–30 days",IF($P18<=60,"31–60 days",IF($P18<=90,"61–90 days","Over 90 days"))))) -> No invoice date | R18: =IF($V18=1,ROW(),"") -> 18 | S18: =IF(OR($A18<>"",$E18<>""),IF(TRIM($D18)="","Buyer not noted",TRIM($D18)),"") -> Aneesh | T18: =IF(AND($V18=1,ISNUMBER($M18)),$M18,0) -> 53067 | U18: =IF($V18=1,IF(COUNTIFS($S$7:$S18,$S18,$V$7:$V18,1)=1,SUMIFS($T$7:$T$1006,$S$7:$S$1006,$S18)-ROW()/1000000000,""),"") | V18: =IF(OR($O18="On hand",$O18="Advance received",$O18="Part realised",$O18="Amount missing"),1,0) -> 1 | W18: =IF(AND($V18=1,N($F18)>0),ROW(),"") | X18: =IF(AND(OR($A18<>"",$E18<>""),$O18<>"Cancelled",ISNUMBER($E18),N($F18)+N($H18)>$E18+0.005),1,0) -> 0 | Y18: =IF(AND(OR($A18<>"",$E18<>""),OR($A18="",$E18="")),1,0) -> 0 | Z18: =IF(AND($A18<>"",COUNTIF($A$7:$A$1006,$A18)>1),1,0) -> 0
A19: PEI/42/2026-27 | C19: Mackerel | D19: Shabeer | E19: 53000 | L19: =IF(OR($A19<>"",$E19<>""),N($F19)+N($H19),"") -> 0 | M19: =IF(OR($O19="",$O19="Cancelled",$O19="Amount missing"),"",IF($O19="Realised",0,$E19-N($F19)-N($H19))) -> 53000 | N19: =IF(OR($M19="",FX=""),"",$M19*FX) -> 4770000 | O19: =IF(NOT(OR($A19<>"",$E19<>"")),"",IF($J19="Cancelled","Cancelled",IF($E19="","Amount missing",IF(OR($J19="Settled",$E19-N($F19)-N($H19)<=0.005),"Realised",IF(N($H19)>0,"Part realised",IF(N($F19)>0,"Advance received","On hand")))))) -> On hand | P19: =IF(AND($V19=1,ISNUMBER($B19)),AsAt-$B19,"") | Q19: =IF($V19<>1,"",IF($P19="","No invoice date",IF($P19<=30,"0–30 days",IF($P19<=60,"31–60 days",IF($P19<=90,"61–90 days","Over 90 days"))))) -> No invoice date | R19: =IF($V19=1,ROW(),"") -> 19 | S19: =IF(OR($A19<>"",$E19<>""),IF(TRIM($D19)="","Buyer not noted",TRIM($D19)),"") -> Shabeer | T19: =IF(AND($V19=1,ISNUMBER($M19)),$M19,0) -> 53000 | U19: =IF($V19=1,IF(COUNTIFS($S$7:$S19,$S19,$V$7:$V19,1)=1,SUMIFS($T$7:$T$1006,$S$7:$S$1006,$S19)-ROW()/1000000000,""),"") | V19: =IF(OR($O19="On hand",$O19="Advance received",$O19="Part realised",$O19="Amount missing"),1,0) -> 1 | W19: =IF(AND($V19=1,N($F19)>0),ROW(),"") | X19: =IF(AND(OR($A19<>"",$E19<>""),$O19<>"Cancelled",ISNUMBER($E19),N($F19)+N($H19)>$E19+0.005),1,0) -> 0 | Y19: =IF(AND(OR($A19<>"",$E19<>""),OR($A19="",$E19="")),1,0) -> 0 | Z19: =IF(AND($A19<>"",COUNTIF($A$7:$A$1006,$A19)>1),1,0) -> 0
A20: PEI/43/2026-27 | C20: Mackerel | D20: Aneesh | E20: 52915 | L20: =IF(OR($A20<>"",$E20<>""),N($F20)+N($H20),"") -> 0 | M20: =IF(OR($O20="",$O20="Cancelled",$O20="Amount missing"),"",IF($O20="Realised",0,$E20-N($F20)-N($H20))) -> 52915 | N20: =IF(OR($M20="",FX=""),"",$M20*FX) -> 4762350 | O20: =IF(NOT(OR($A20<>"",$E20<>"")),"",IF($J20="Cancelled","Cancelled",IF($E20="","Amount missing",IF(OR($J20="Settled",$E20-N($F20)-N($H20)<=0.005),"Realised",IF(N($H20)>0,"Part realised",IF(N($F20)>0,"Advance received","On hand")))))) -> On hand | P20: =IF(AND($V20=1,ISNUMBER($B20)),AsAt-$B20,"") | Q20: =IF($V20<>1,"",IF($P20="","No invoice date",IF($P20<=30,"0–30 days",IF($P20<=60,"31–60 days",IF($P20<=90,"61–90 days","Over 90 days"))))) -> No invoice date | R20: =IF($V20=1,ROW(),"") -> 20 | S20: =IF(OR($A20<>"",$E20<>""),IF(TRIM($D20)="","Buyer not noted",TRIM($D20)),"") -> Aneesh | T20: =IF(AND($V20=1,ISNUMBER($M20)),$M20,0) -> 52915 | U20: =IF($V20=1,IF(COUNTIFS($S$7:$S20,$S20,$V$7:$V20,1)=1,SUMIFS($T$7:$T$1006,$S$7:$S$1006,$S20)-ROW()/1000000000,""),"") | V20: =IF(OR($O20="On hand",$O20="Advance received",$O20="Part realised",$O20="Amount missing"),1,0) -> 1 | W20: =IF(AND($V20=1,N($F20)>0),ROW(),"") | X20: =IF(AND(OR($A20<>"",$E20<>""),$O20<>"Cancelled",ISNUMBER($E20),N($F20)+N($H20)>$E20+0.005),1,0) -> 0 | Y20: =IF(AND(OR($A20<>"",$E20<>""),OR($A20="",$E20="")),1,0) -> 0 | Z20: =IF(AND($A20<>"",COUNTIF($A$7:$A$1006,$A20)>1),1,0) -> 0
A21: PEI/44/2026-27 | C21: Nippon | D21: part | E21: 53239.9 | L21: =IF(OR($A21<>"",$E21<>""),N($F21)+N($H21),"") -> 0 | M21: =IF(OR($O21="",$O21="Cancelled",$O21="Amount missing"),"",IF($O21="Realised",0,$E21-N($F21)-N($H21))) -> 53239.9 | N21: =IF(OR($M21="",FX=""),"",$M21*FX) -> 4791591 | O21: =IF(NOT(OR($A21<>"",$E21<>"")),"",IF($J21="Cancelled","Cancelled",IF($E21="","Amount missing",IF(OR($J21="Settled",$E21-N($F21)-N($H21)<=0.005),"Realised",IF(N($H21)>0,"Part realised",IF(N($F21)>0,"Advance received","On hand")))))) -> On hand | P21: =IF(AND($V21=1,ISNUMBER($B21)),AsAt-$B21,"") | Q21: =IF($V21<>1,"",IF($P21="","No invoice date",IF($P21<=30,"0–30 days",IF($P21<=60,"31–60 days",IF($P21<=90,"61–90 days","Over 90 days"))))) -> No invoice date | R21: =IF($V21=1,ROW(),"") -> 21 | S21: =IF(OR($A21<>"",$E21<>""),IF(TRIM($D21)="","Buyer not noted",TRIM($D21)),"") -> part | T21: =IF(AND($V21=1,ISNUMBER($M21)),$M21,0) -> 53239.9 | U21: =IF($V21=1,IF(COUNTIFS($S$7:$S21,$S21,$V$7:$V21,1)=1,SUMIFS($T$7:$T$1006,$S$7:$S$1006,$S21)-ROW()/1000000000,""),"") -> 53239.9 | V21: =IF(OR($O21="On hand",$O21="Advance received",$O21="Part realised",$O21="Amount missing"),1,0) -> 1 | W21: =IF(AND($V21=1,N($F21)>0),ROW(),"") | X21: =IF(AND(OR($A21<>"",$E21<>""),$O21<>"Cancelled",ISNUMBER($E21),N($F21)+N($H21)>$E21+0.005),1,0) -> 0 | Y21: =IF(AND(OR($A21<>"",$E21<>""),OR($A21="",$E21="")),1,0) -> 0 | Z21: =IF(AND($A21<>"",COUNTIF($A$7:$A$1006,$A21)>1),1,0) -> 0
A22: PEI/46/2026-27 | C22: Tuna | D22: Zoom | E22: 46400 | L22: =IF(OR($A22<>"",$E22<>""),N($F22)+N($H22),"") -> 0 | M22: =IF(OR($O22="",$O22="Cancelled",$O22="Amount missing"),"",IF($O22="Realised",0,$E22-N($F22)-N($H22))) -> 46400 | N22: =IF(OR($M22="",FX=""),"",$M22*FX) -> 4176000 | O22: =IF(NOT(OR($A22<>"",$E22<>"")),"",IF($J22="Cancelled","Cancelled",IF($E22="","Amount missing",IF(OR($J22="Settled",$E22-N($F22)-N($H22)<=0.005),"Realised",IF(N($H22)>0,"Part realised",IF(N($F22)>0,"Advance received","On hand")))))) -> On hand | P22: =IF(AND($V22=1,ISNUMBER($B22)),AsAt-$B22,"") | Q22: =IF($V22<>1,"",IF($P22="","No invoice date",IF($P22<=30,"0–30 days",IF($P22<=60,"31–60 days",IF($P22<=90,"61–90 days","Over 90 days"))))) -> No invoice date | R22: =IF($V22=1,ROW(),"") -> 22 | S22: =IF(OR($A22<>"",$E22<>""),IF(TRIM($D22)="","Buyer not noted",TRIM($D22)),"") -> Zoom | T22: =IF(AND($V22=1,ISNUMBER($M22)),$M22,0) -> 46400 | U22: =IF($V22=1,IF(COUNTIFS($S$7:$S22,$S22,$V$7:$V22,1)=1,SUMIFS($T$7:$T$1006,$S$7:$S$1006,$S22)-ROW()/1000000000,""),"") | V22: =IF(OR($O22="On hand",$O22="Advance received",$O22="Part realised",$O22="Amount missing"),1,0) -> 1 | W22: =IF(AND($V22=1,N($F22)>0),ROW(),"") | X22: =IF(AND(OR($A22<>"",$E22<>""),$O22<>"Cancelled",ISNUMBER($E22),N($F22)+N($H22)>$E22+0.005),1,0) -> 0 | Y22: =IF(AND(OR($A22<>"",$E22<>""),OR($A22="",$E22="")),1,0) -> 0 | Z22: =IF(AND($A22<>"",COUNTIF($A$7:$A$1006,$A22)>1),1,0) -> 0
A23: PEI/47/2026-27 | C23: Mackerel | D23: Jithin | E23: 54450 | F23: 3000 | L23: =IF(OR($A23<>"",$E23<>""),N($F23)+N($H23),"") -> 3000 | M23: =IF(OR($O23="",$O23="Cancelled",$O23="Amount missing"),"",IF($O23="Realised",0,$E23-N($F23)-N($H23))) -> 51450 | N23: =IF(OR($M23="",FX=""),"",$M23*FX) -> 4630500 | O23: =IF(NOT(OR($A23<>"",$E23<>"")),"",IF($J23="Cancelled","Cancelled",IF($E23="","Amount missing",IF(OR($J23="Settled",$E23-N($F23)-N($H23)<=0.005),"Realised",IF(N($H23)>0,"Part realised",IF(N($F23)>0,"Advance received","On hand")))))) -> Advance received | P23: =IF(AND($V23=1,ISNUMBER($B23)),AsAt-$B23,"") | Q23: =IF($V23<>1,"",IF($P23="","No invoice date",IF($P23<=30,"0–30 days",IF($P23<=60,"31–60 days",IF($P23<=90,"61–90 days","Over 90 days"))))) -> No invoice date | R23: =IF($V23=1,ROW(),"") -> 23 | S23: =IF(OR($A23<>"",$E23<>""),IF(TRIM($D23)="","Buyer not noted",TRIM($D23)),"") -> Jithin | T23: =IF(AND($V23=1,ISNUMBER($M23)),$M23,0) -> 51450 | U23: =IF($V23=1,IF(COUNTIFS($S$7:$S23,$S23,$V$7:$V23,1)=1,SUMIFS($T$7:$T$1006,$S$7:$S$1006,$S23)-ROW()/1000000000,""),"") -> 104050 | V23: =IF(OR($O23="On hand",$O23="Advance received",$O23="Part realised",$O23="Amount missing"),1,0) -> 1 | W23: =IF(AND($V23=1,N($F23)>0),ROW(),"") -> 23 | X23: =IF(AND(OR($A23<>"",$E23<>""),$O23<>"Cancelled",ISNUMBER($E23),N($F23)+N($H23)>$E23+0.005),1,0) -> 0 | Y23: =IF(AND(OR($A23<>"",$E23<>""),OR($A23="",$E23="")),1,0) -> 0 | Z23: =IF(AND($A23<>"",COUNTIF($A$7:$A$1006,$A23)>1),1,0) -> 0
A24: PEI/48/2026-27 | C24: KON | D24: Kobe | E24: 122300 | L24: =IF(OR($A24<>"",$E24<>""),N($F24)+N($H24),"") -> 0 | M24: =IF(OR($O24="",$O24="Cancelled",$O24="Amount missing"),"",IF($O24="Realised",0,$E24-N($F24)-N($H24))) -> 122300 | N24: =IF(OR($M24="",FX=""),"",$M24*FX) -> 11007000 | O24: =IF(NOT(OR($A24<>"",$E24<>"")),"",IF($J24="Cancelled","Cancelled",IF($E24="","Amount missing",IF(OR($J24="Settled",$E24-N($F24)-N($H24)<=0.005),"Realised",IF(N($H24)>0,"Part realised",IF(N($F24)>0,"Advance received","On hand")))))) -> On hand | P24: =IF(AND($V24=1,ISNUMBER($B24)),AsAt-$B24,"") | Q24: =IF($V24<>1,"",IF($P24="","No invoice date",IF($P24<=30,"0–30 days",IF($P24<=60,"31–60 days",IF($P24<=90,"61–90 days","Over 90 days"))))) -> No invoice date | R24: =IF($V24=1,ROW(),"") -> 24 | S24: =IF(OR($A24<>"",$E24<>""),IF(TRIM($D24)="","Buyer not noted",TRIM($D24)),"") -> Kobe | T24: =IF(AND($V24=1,ISNUMBER($M24)),$M24,0) -> 122300 | U24: =IF($V24=1,IF(COUNTIFS($S$7:$S24,$S24,$V$7:$V24,1)=1,SUMIFS($T$7:$T$1006,$S$7:$S$1006,$S24)-ROW()/1000000000,""),"") -> 122300 | V24: =IF(OR($O24="On hand",$O24="Advance received",$O24="Part realised",$O24="Amount missing"),1,0) -> 1 | W24: =IF(AND($V24=1,N($F24)>0),ROW(),"") | X24: =IF(AND(OR($A24<>"",$E24<>""),$O24<>"Cancelled",ISNUMBER($E24),N($F24)+N($H24)>$E24+0.005),1,0) -> 0 | Y24: =IF(AND(OR($A24<>"",$E24<>""),OR($A24="",$E24="")),1,0) -> 0 | Z24: =IF(AND($A24<>"",COUNTIF($A$7:$A$1006,$A24)>1),1,0) -> 0
A25: PEI/49/2026-27 | C25: Mackerel | D25: Kaustuba, Bombay | E25: 55600 | L25: =IF(OR($A25<>"",$E25<>""),N($F25)+N($H25),"") -> 0 | M25: =IF(OR($O25="",$O25="Cancelled",$O25="Amount missing"),"",IF($O25="Realised",0,$E25-N($F25)-N($H25))) -> 55600 | N25: =IF(OR($M25="",FX=""),"",$M25*FX) -> 5004000 | O25: =IF(NOT(OR($A25<>"",$E25<>"")),"",IF($J25="Cancelled","Cancelled",IF($E25="","Amount missing",IF(OR($J25="Settled",$E25-N($F25)-N($H25)<=0.005),"Realised",IF(N($H25)>0,"Part realised",IF(N($F25)>0,"Advance received","On hand")))))) -> On hand | P25: =IF(AND($V25=1,ISNUMBER($B25)),AsAt-$B25,"") | Q25: =IF($V25<>1,"",IF($P25="","No invoice date",IF($P25<=30,"0–30 days",IF($P25<=60,"31–60 days",IF($P25<=90,"61–90 days","Over 90 days"))))) -> No invoice date | R25: =IF($V25=1,ROW(),"") -> 25 | S25: =IF(OR($A25<>"",$E25<>""),IF(TRIM($D25)="","Buyer not noted",TRIM($D25)),"") -> Kaustuba, Bombay | T25: =IF(AND($V25=1,ISNUMBER($M25)),$M25,0) -> 55600 | U25: =IF($V25=1,IF(COUNTIFS($S$7:$S25,$S25,$V$7:$V25,1)=1,SUMIFS($T$7:$T$1006,$S$7:$S$1006,$S25)-ROW()/1000000000,""),"") -> 55600 | V25: =IF(OR($O25="On hand",$O25="Advance received",$O25="Part realised",$O25="Amount missing"),1,0) -> 1 | W25: =IF(AND($V25=1,N($F25)>0),ROW(),"") | X25: =IF(AND(OR($A25<>"",$E25<>""),$O25<>"Cancelled",ISNUMBER($E25),N($F25)+N($H25)>$E25+0.005),1,0) -> 0 | Y25: =IF(AND(OR($A25<>"",$E25<>""),OR($A25="",$E25="")),1,0) -> 0 | Z25: =IF(AND($A25<>"",COUNTIF($A$7:$A$1006,$A25)>1),1,0) -> 0
A26: PEI/50/2026-27 | C26: Mackerel | D26: Irfan | E26: 57200 | L26: =IF(OR($A26<>"",$E26<>""),N($F26)+N($H26),"") -> 0 | M26: =IF(OR($O26="",$O26="Cancelled",$O26="Amount missing"),"",IF($O26="Realised",0,$E26-N($F26)-N($H26))) -> 57200 | N26: =IF(OR($M26="",FX=""),"",$M26*FX) -> 5148000 | O26: =IF(NOT(OR($A26<>"",$E26<>"")),"",IF($J26="Cancelled","Cancelled",IF($E26="","Amount missing",IF(OR($J26="Settled",$E26-N($F26)-N($H26)<=0.005),"Realised",IF(N($H26)>0,"Part realised",IF(N($F26)>0,"Advance received","On hand")))))) -> On hand | P26: =IF(AND($V26=1,ISNUMBER($B26)),AsAt-$B26,"") | Q26: =IF($V26<>1,"",IF($P26="","No invoice date",IF($P26<=30,"0–30 days",IF($P26<=60,"31–60 days",IF($P26<=90,"61–90 days","Over 90 days"))))) -> No invoice date | R26: =IF($V26=1,ROW(),"") -> 26 | S26: =IF(OR($A26<>"",$E26<>""),IF(TRIM($D26)="","Buyer not noted",TRIM($D26)),"") -> Irfan | T26: =IF(AND($V26=1,ISNUMBER($M26)),$M26,0) -> 57200 | U26: =IF($V26=1,IF(COUNTIFS($S$7:$S26,$S26,$V$7:$V26,1)=1,SUMIFS($T$7:$T$1006,$S$7:$S$1006,$S26)-ROW()/1000000000,""),"") -> 57200 | V26: =IF(OR($O26="On hand",$O26="Advance received",$O26="Part realised",$O26="Amount missing"),1,0) -> 1 | W26: =IF(AND($V26=1,N($F26)>0),ROW(),"") | X26: =IF(AND(OR($A26<>"",$E26<>""),$O26<>"Cancelled",ISNUMBER($E26),N($F26)+N($H26)>$E26+0.005),1,0) -> 0 | Y26: =IF(AND(OR($A26<>"",$E26<>""),OR($A26="",$E26="")),1,0) -> 0 | Z26: =IF(AND($A26<>"",COUNTIF($A$7:$A$1006,$A26)>1),1,0) -> 0
A27: PEI/51/2026-27 | C27: Mackerel | D27: Aneesh | E27: 52701.5 | L27: =IF(OR($A27<>"",$E27<>""),N($F27)+N($H27),"") -> 0 | M27: =IF(OR($O27="",$O27="Cancelled",$O27="Amount missing"),"",IF($O27="Realised",0,$E27-N($F27)-N($H27))) -> 52701.5 | N27: =IF(OR($M27="",FX=""),"",$M27*FX) -> 4743135 | O27: =IF(NOT(OR($A27<>"",$E27<>"")),"",IF($J27="Cancelled","Cancelled",IF($E27="","Amount missing",IF(OR($J27="Settled",$E27-N($F27)-N($H27)<=0.005),"Realised",IF(N($H27)>0,"Part realised",IF(N($F27)>0,"Advance received","On hand")))))) -> On hand | P27: =IF(AND($V27=1,ISNUMBER($B27)),AsAt-$B27,"") | Q27: =IF($V27<>1,"",IF($P27="","No invoice date",IF($P27<=30,"0–30 days",IF($P27<=60,"31–60 days",IF($P27<=90,"61–90 days","Over 90 days"))))) -> No invoice date | R27: =IF($V27=1,ROW(),"") -> 27 | S27: =IF(OR($A27<>"",$E27<>""),IF(TRIM($D27)="","Buyer not noted",TRIM($D27)),"") -> Aneesh | T27: =IF(AND($V27=1,ISNUMBER($M27)),$M27,0) -> 52701.5 | U27: =IF($V27=1,IF(COUNTIFS($S$7:$S27,$S27,$V$7:$V27,1)=1,SUMIFS($T$7:$T$1006,$S$7:$S$1006,$S27)-ROW()/1000000000,""),"") | V27: =IF(OR($O27="On hand",$O27="Advance received",$O27="Part realised",$O27="Amount missing"),1,0) -> 1 | W27: =IF(AND($V27=1,N($F27)>0),ROW(),"") | X27: =IF(AND(OR($A27<>"",$E27<>""),$O27<>"Cancelled",ISNUMBER($E27),N($F27)+N($H27)>$E27+0.005),1,0) -> 0 | Y27: =IF(AND(OR($A27<>"",$E27<>""),OR($A27="",$E27="")),1,0) -> 0 | Z27: =IF(AND($A27<>"",COUNTIF($A$7:$A$1006,$A27)>1),1,0) -> 0
A28: PEI/52/2026-27 | C28: Mackerel | D28: Ramiz | E28: 57970 | F28: 5000 | L28: =IF(OR($A28<>"",$E28<>""),N($F28)+N($H28),"") -> 5000 | M28: =IF(OR($O28="",$O28="Cancelled",$O28="Amount missing"),"",IF($O28="Realised",0,$E28-N($F28)-N($H28))) -> 52970 | N28: =IF(OR($M28="",FX=""),"",$M28*FX) -> 4767300 | O28: =IF(NOT(OR($A28<>"",$E28<>"")),"",IF($J28="Cancelled","Cancelled",IF($E28="","Amount missing",IF(OR($J28="Settled",$E28-N($F28)-N($H28)<=0.005),"Realised",IF(N($H28)>0,"Part realised",IF(N($F28)>0,"Advance received","On hand")))))) -> Advance received | P28: =IF(AND($V28=1,ISNUMBER($B28)),AsAt-$B28,"") | Q28: =IF($V28<>1,"",IF($P28="","No invoice date",IF($P28<=30,"0–30 days",IF($P28<=60,"31–60 days",IF($P28<=90,"61–90 days","Over 90 days"))))) -> No invoice date | R28: =IF($V28=1,ROW(),"") -> 28 | S28: =IF(OR($A28<>"",$E28<>""),IF(TRIM($D28)="","Buyer not noted",TRIM($D28)),"") -> Ramiz | T28: =IF(AND($V28=1,ISNUMBER($M28)),$M28,0) -> 52970 | U28: =IF($V28=1,IF(COUNTIFS($S$7:$S28,$S28,$V$7:$V28,1)=1,SUMIFS($T$7:$T$1006,$S$7:$S$1006,$S28)-ROW()/1000000000,""),"") -> 52970 | V28: =IF(OR($O28="On hand",$O28="Advance received",$O28="Part realised",$O28="Amount missing"),1,0) -> 1 | W28: =IF(AND($V28=1,N($F28)>0),ROW(),"") -> 28 | X28: =IF(AND(OR($A28<>"",$E28<>""),$O28<>"Cancelled",ISNUMBER($E28),N($F28)+N($H28)>$E28+0.005),1,0) -> 0 | Y28: =IF(AND(OR($A28<>"",$E28<>""),OR($A28="",$E28="")),1,0) -> 0 | Z28: =IF(AND($A28<>"",COUNTIF($A$7:$A$1006,$A28)>1),1,0) -> 0
A29: PEI/53/2026-27 | C29: Mackerel | D29: Jithin | E29: 55600 | F29: 3000 | L29: =IF(OR($A29<>"",$E29<>""),N($F29)+N($H29),"") -> 3000 | M29: =IF(OR($O29="",$O29="Cancelled",$O29="Amount missing"),"",IF($O29="Realised",0,$E29-N($F29)-N($H29))) -> 52600 | N29: =IF(OR($M29="",FX=""),"",$M29*FX) -> 4734000 | O29: =IF(NOT(OR($A29<>"",$E29<>"")),"",IF($J29="Cancelled","Cancelled",IF($E29="","Amount missing",IF(OR($J29="Settled",$E29-N($F29)-N($H29)<=0.005),"Realised",IF(N($H29)>0,"Part realised",IF(N($F29)>0,"Advance received","On hand")))))) -> Advance received | P29: =IF(AND($V29=1,ISNUMBER($B29)),AsAt-$B29,"") | Q29: =IF($V29<>1,"",IF($P29="","No invoice date",IF($P29<=30,"0–30 days",IF($P29<=60,"31–60 days",IF($P29<=90,"61–90 days","Over 90 days"))))) -> No invoice date | R29: =IF($V29=1,ROW(),"") -> 29 | S29: =IF(OR($A29<>"",$E29<>""),IF(TRIM($D29)="","Buyer not noted",TRIM($D29)),"") -> Jithin | T29: =IF(AND($V29=1,ISNUMBER($M29)),$M29,0) -> 52600 | U29: =IF($V29=1,IF(COUNTIFS($S$7:$S29,$S29,$V$7:$V29,1)=1,SUMIFS($T$7:$T$1006,$S$7:$S$1006,$S29)-ROW()/1000000000,""),"") | V29: =IF(OR($O29="On hand",$O29="Advance received",$O29="Part realised",$O29="Amount missing"),1,0) -> 1 | W29: =IF(AND($V29=1,N($F29)>0),ROW(),"") -> 29 | X29: =IF(AND(OR($A29<>"",$E29<>""),$O29<>"Cancelled",ISNUMBER($E29),N($F29)+N($H29)>$E29+0.005),1,0) -> 0 | Y29: =IF(AND(OR($A29<>"",$E29<>""),OR($A29="",$E29="")),1,0) -> 0 | Z29: =IF(AND($A29<>"",COUNTIF($A$7:$A$1006,$A29)>1),1,0) -> 0
L30: =IF(OR($A30<>"",$E30<>""),N($F30)+N($H30),"") | M30: =IF(OR($O30="",$O30="Cancelled",$O30="Amount missing"),"",IF($O30="Realised",0,$E30-N($F30)-N($H30))) | N30: =IF(OR($M30="",FX=""),"",$M30*FX) | O30: =IF(NOT(OR($A30<>"",$E30<>"")),"",IF($J30="Cancelled","Cancelled",IF($E30="","Amount missing",IF(OR($J30="Settled",$E30-N($F30)-N($H30)<=0.005),"Realised",IF(N($H30)>0,"Part realised",IF(N($F30)>0,"Advance received","On hand")))))) | P30: =IF(AND($V30=1,ISNUMBER($B30)),AsAt-$B30,"") | Q30: =IF($V30<>1,"",IF($P30="","No invoice date",IF($P30<=30,"0–30 days",IF($P30<=60,"31–60 days",IF($P30<=90,"61–90 days","Over 90 days"))))) | R30: =IF($V30=1,ROW(),"") | S30: =IF(OR($A30<>"",$E30<>""),IF(TRIM($D30)="","Buyer not noted",TRIM($D30)),"") | T30: =IF(AND($V30=1,ISNUMBER($M30)),$M30,0) -> 0 | U30: =IF($V30=1,IF(COUNTIFS($S$7:$S30,$S30,$V$7:$V30,1)=1,SUMIFS($T$7:$T$1006,$S$7:$S$1006,$S30)-ROW()/1000000000,""),"") | V30: =IF(OR($O30="On hand",$O30="Advance received",$O30="Part realised",$O30="Amount missing"),1,0) -> 0 | W30: =IF(AND($V30=1,N($F30)>0),ROW(),"") | X30: =IF(AND(OR($A30<>"",$E30<>""),$O30<>"Cancelled",ISNUMBER($E30),N($F30)+N($H30)>$E30+0.005),1,0) -> 0 | Y30: =IF(AND(OR($A30<>"",$E30<>""),OR($A30="",$E30="")),1,0) -> 0 | Z30: =IF(AND($A30<>"",COUNTIF($A$7:$A$1006,$A30)>1),1,0) -> 0
L31: =IF(OR($A31<>"",$E31<>""),N($F31)+N($H31),"") | M31: =IF(OR($O31="",$O31="Cancelled",$O31="Amount missing"),"",IF($O31="Realised",0,$E31-N($F31)-N($H31))) | N31: =IF(OR($M31="",FX=""),"",$M31*FX) | O31: =IF(NOT(OR($A31<>"",$E31<>"")),"",IF($J31="Cancelled","Cancelled",IF($E31="","Amount missing",IF(OR($J31="Settled",$E31-N($F31)-N($H31)<=0.005),"Realised",IF(N($H31)>0,"Part realised",IF(N($F31)>0,"Advance received","On hand")))))) | P31: =IF(AND($V31=1,ISNUMBER($B31)),AsAt-$B31,"") | Q31: =IF($V31<>1,"",IF($P31="","No invoice date",IF($P31<=30,"0–30 days",IF($P31<=60,"31–60 days",IF($P31<=90,"61–90 days","Over 90 days"))))) | R31: =IF($V31=1,ROW(),"") | S31: =IF(OR($A31<>"",$E31<>""),IF(TRIM($D31)="","Buyer not noted",TRIM($D31)),"") | T31: =IF(AND($V31=1,ISNUMBER($M31)),$M31,0) -> 0 | U31: =IF($V31=1,IF(COUNTIFS($S$7:$S31,$S31,$V$7:$V31,1)=1,SUMIFS($T$7:$T$1006,$S$7:$S$1006,$S31)-ROW()/1000000000,""),"") | V31: =IF(OR($O31="On hand",$O31="Advance received",$O31="Part realised",$O31="Amount missing"),1,0) -> 0 | W31: =IF(AND($V31=1,N($F31)>0),ROW(),"") | X31: =IF(AND(OR($A31<>"",$E31<>""),$O31<>"Cancelled",ISNUMBER($E31),N($F31)+N($H31)>$E31+0.005),1,0) -> 0 | Y31: =IF(AND(OR($A31<>"",$E31<>""),OR($A31="",$E31="")),1,0) -> 0 | Z31: =IF(AND($A31<>"",COUNTIF($A$7:$A$1006,$A31)>1),1,0) -> 0
L32: =IF(OR($A32<>"",$E32<>""),N($F32)+N($H32),"") | M32: =IF(OR($O32="",$O32="Cancelled",$O32="Amount missing"),"",IF($O32="Realised",0,$E32-N($F32)-N($H32))) | N32: =IF(OR($M32="",FX=""),"",$M32*FX) | O32: =IF(NOT(OR($A32<>"",$E32<>"")),"",IF($J32="Cancelled","Cancelled",IF($E32="","Amount missing",IF(OR($J32="Settled",$E32-N($F32)-N($H32)<=0.005),"Realised",IF(N($H32)>0,"Part realised",IF(N($F32)>0,"Advance received","On hand")))))) | P32: =IF(AND($V32=1,ISNUMBER($B32)),AsAt-$B32,"") | Q32: =IF($V32<>1,"",IF($P32="","No invoice date",IF($P32<=30,"0–30 days",IF($P32<=60,"31–60 days",IF($P32<=90,"61–90 days","Over 90 days"))))) | R32: =IF($V32=1,ROW(),"") | S32: =IF(OR($A32<>"",$E32<>""),IF(TRIM($D32)="","Buyer not noted",TRIM($D32)),"") | T32: =IF(AND($V32=1,ISNUMBER($M32)),$M32,0) -> 0 | U32: =IF($V32=1,IF(COUNTIFS($S$7:$S32,$S32,$V$7:$V32,1)=1,SUMIFS($T$7:$T$1006,$S$7:$S$1006,$S32)-ROW()/1000000000,""),"") | V32: =IF(OR($O32="On hand",$O32="Advance received",$O32="Part realised",$O32="Amount missing"),1,0) -> 0 | W32: =IF(AND($V32=1,N($F32)>0),ROW(),"") | X32: =IF(AND(OR($A32<>"",$E32<>""),$O32<>"Cancelled",ISNUMBER($E32),N($F32)+N($H32)>$E32+0.005),1,0) -> 0 | Y32: =IF(AND(OR($A32<>"",$E32<>""),OR($A32="",$E32="")),1,0) -> 0 | Z32: =IF(AND($A32<>"",COUNTIF($A$7:$A$1006,$A32)>1),1,0) -> 0
