Workbook

Sheet Read me
A1: PREMIER EXPORTS INTERNATIONAL
A2: STOCK REGISTER — HOW IT WORKS
B4: Every day, in one minute
B5: 1. Open 'Daily Entry' and add one row per product that moved.
B6: 2. Type the date, pick the product from the dropdown, enter slabs produced and/or shipped.
B7: 3. On 'Stock', set the Statement date and the US$ → ₹ exchange rate for today.
B8: 4. Open 'Daily Report' and save it as PDF — that is the directors' copy.
B10: Sending the report
B11: 'Daily Report' is already sized to one A4 page. In Excel: File ▸ Export ▸ Create PDF/XPS
B12: (or File ▸ Save a Copy and choose PDF), pick "Selected sheet", and send that file.
B13: Nothing else needs installing — Excel writes the PDF itself.
B15: Why you never re-type an opening balance
B16: Opening balance is a fixed baseline, not a daily figure.
B17: Closing balance = opening balance + production to date − shipment to date,
... B57: statement dated 20/08/26, supplied by Premier Exports International.

Sheet Stock
A1: PREMIER EXPORTS INTERNATIONAL
A2: STOCK REGISTER — LIVE POSITION
A3: Statement date | C3: 46254 | D3: ← set to today; drives the two "today" columns and the Daily Report
A4: US$ → ₹ exchange rate | D4: ← rupees per US dollar; converts the export rates into the value column
A5: Opening balance is a frozen baseline — never re-key it. Closing follows from the dated rows on 'Daily Entry'.
A7: Brand | B7: Product | C7: Opening Balance | D7: Today's Production | E7: Today's Shipment | F7: Production to Date | G7: Shipment to Date | H7: Closing Balance | I7: Rate / Slab (US$) | J7: Stock Value (₹) | L7: Key (do not edit) | M7: Moved today | N7: Rank
A8: Blue Dolphin | B8: PD PVN 100/200 | C8: 11459 | D8: =IF($A8="","",SUMIFS('Daily Entry'!$C$7:$C$5000,'Daily Entry'!$B$7:$B$5000,$L8,'Daily Entry'!$A$7:$A$5000,$C$3)) -> 1068 | E8: =IF($A8="","",SUMIFS('Daily Entry'!$D$7:$D$5000,'Daily Entry'!$B$7:$B$5000,$L8,'Daily Entry'!$A$7:$A$5000,$C$3)) -> 0 | F8: =IF($A8="","",SUMIFS('Daily Entry'!$C$7:$C$5000,'Daily Entry'!$B$7:$B$5000,$L8)) -> 1068 | G8: =IF($A8="","",SUMIFS('Daily Entry'!$D$7:$D$5000,'Daily Entry'!$B$7:$B$5000,$L8)) -> 0 | H8: =IF($A8="","",$C8+$F8-$G8) -> 12527 | J8: =IF(OR($A8="",$I8="",$C$4=""),"",$H8*$I8*$C$4) | L8: =IF($A8="","",$A8&" - "&$B8) -> Blue Dolphin - PD PVN 100/200 | M8: =IF($A8="",0,IF(OR($D8<>0,$E8<>0),1,0)) -> 1 | N8: =IF($M8=1,SUM($M$8:$M8),"") -> 1
A9: Blue Dolphin | B9: PD KKD 100/200 | C9: 517 | D9: =IF($A9="","",SUMIFS('Daily Entry'!$C$7:$C$5000,'Daily Entry'!$B$7:$B$5000,$L9,'Daily Entry'!$A$7:$A$5000,$C$3)) -> 65 | E9: =IF($A9="","",SUMIFS('Daily Entry'!$D$7:$D$5000,'Daily Entry'!$B$7:$B$5000,$L9,'Daily Entry'!$A$7:$A$5000,$C$3)) -> 0 | F9: =IF($A9="","",SUMIFS('Daily Entry'!$C$7:$C$5000,'Daily Entry'!$B$7:$B$5000,$L9)) -> 65 | G9: =IF($A9="","",SUMIFS('Daily Entry'!$D$7:$D$5000,'Daily Entry'!$B$7:$B$5000,$L9)) -> 0 | H9: =IF($A9="","",$C9+$F9-$G9) -> 582 | J9: =IF(OR($A9="",$I9="",$C$4=""),"",$H9*$I9*$C$4) | L9: =IF($A9="","",$A9&" - "&$B9) -> Blue Dolphin - PD KKD 100/200 | M9: =IF($A9="",0,IF(OR($D9<>0,$E9<>0),1,0)) -> 1 | N9: =IF($M9=1,SUM($M$8:$M9),"") -> 2
A10: Blue Dolphin | B10: PUD PVN 200/300 | C10: 2262 | D10: =IF($A10="","",SUMIFS('Daily Entry'!$C$7:$C$5000,'Daily Entry'!$B$7:$B$5000,$L10,'Daily Entry'!$A$7:$A$5000,$C$3)) -> 267 | E10: =IF($A10="","",SUMIFS('Daily Entry'!$D$7:$D$5000,'Daily Entry'!$B$7:$B$5000,$L10,'Daily Entry'!$A$7:$A$5000,$C$3)) -> 0 | F10: =IF($A10="","",SUMIFS('Daily Entry'!$C$7:$C$5000,'Daily Entry'!$B$7:$B$5000,$L10)) -> 267 | G10: =IF($A10="","",SUMIFS('Daily Entry'!$D$7:$D$5000,'Daily Entry'!$B$7:$B$5000,$L10)) -> 0 | H10: =IF($A10="","",$C10+$F10-$G10) -> 2529 | J10: =IF(OR($A10="",$I10="",$C$4=""),"",$H10*$I10*$C$4) | L10: =IF($A10="","",$A10&" - "&$B10) -> Blue Dolphin - PUD PVN 200/300 | M10: =IF($A10="",0,IF(OR($D10<>0,$E10<>0),1,0)) -> 1 | N10: =IF($M10=1,SUM($M$8:$M10),"") -> 3
A11: Blue Dolphin | B11: PUD KKD 200/300 | C11: 2835 | D11: =IF($A11="","",SUMIFS('Daily Entry'!$C$7:$C$5000,'Daily Entry'!$B$7:$B$5000,$L11,'Daily Entry'!$A$7:$A$5000,$C$3)) -> 0 | E11: =IF($A11="","",SUMIFS('Daily Entry'!$D$7:$D$5000,'Daily Entry'!$B$7:$B$5000,$L11,'Daily Entry'!$A$7:$A$5000,$C$3)) -> 0 | F11: =IF($A11="","",SUMIFS('Daily Entry'!$C$7:$C$5000,'Daily Entry'!$B$7:$B$5000,$L11)) -> 0 | G11: =IF($A11="","",SUMIFS('Daily Entry'!$D$7:$D$5000,'Daily Entry'!$B$7:$B$5000,$L11)) -> 0 | H11: =IF($A11="","",$C11+$F11-$G11) -> 2835 | J11: =IF(OR($A11="",$I11="",$C$4=""),"",$H11*$I11*$C$4) | L11: =IF($A11="","",$A11&" - "&$B11) -> Blue Dolphin - PUD KKD 200/300 | M11: =IF($A11="",0,IF(OR($D11<>0,$E11<>0),1,0)) -> 0 | N11: =IF($M11=1,SUM($M$8:$M11),"")
A12: Blue Dolphin | B12: PUD PVN 300/500 | C12: 1673 | D12: =IF($A12="","",SUMIFS('Daily Entry'!$C$7:$C$5000,'Daily Entry'!$B$7:$B$5000,$L12,'Daily Entry'!$A$7:$A$5000,$C$3)) -> 0 | E12: =IF($A12="","",SUMIFS('Daily Entry'!$D$7:$D$5000,'Daily Entry'!$B$7:$B$5000,$L12,'Daily Entry'!$A$7:$A$5000,$C$3)) -> 0 | F12: =IF($A12="","",SUMIFS('Daily Entry'!$C$7:$C$5000,'Daily Entry'!$B$7:$B$5000,$L12)) -> 0 | G12: =IF($A12="","",SUMIFS('Daily Entry'!$D$7:$D$5000,'Daily Entry'!$B$7:$B$5000,$L12)) -> 0 | H12: =IF($A12="","",$C12+$F12-$G12) -> 1673 | J12: =IF(OR($A12="",$I12="",$C$4=""),"",$H12*$I12*$C$4) | L12: =IF($A12="","",$A12&" - "&$B12) -> Blue Dolphin - PUD PVN 300/500 | M12: =IF($A12="",0,IF(OR($D12<>0,$E12<>0),1,0)) -> 0 | N12: =IF($M12=1,SUM($M$8:$M12),"")
A13: Blue Dolphin | B13: PUD KKD 300/500 | C13: 7542 | D13: =IF($A13="","",SUMIFS('Daily Entry'!$C$7:$C$5000,'Daily Entry'!$B$7:$B$5000,$L13,'Daily Entry'!$A$7:$A$5000,$C$3)) -> 0 | E13: =IF($A13="","",SUMIFS('Daily Entry'!$D$7:$D$5000,'Daily Entry'!$B$7:$B$5000,$L13,'Daily Entry'!$A$7:$A$5000,$C$3)) -> 0 | F13: =IF($A13="","",SUMIFS('Daily Entry'!$C$7:$C$5000,'Daily Entry'!$B$7:$B$5000,$L13)) -> 0 | G13: =IF($A13="","",SUMIFS('Daily Entry'!$D$7:$D$5000,'Daily Entry'!$B$7:$B$5000,$L13)) -> 0 | H13: =IF($A13="","",$C13+$F13-$G13) -> 7542 | J13: =IF(OR($A13="",$I13="",$C$4=""),"",$H13*$I13*$C$4) | L13: =IF($A13="","",$A13&" - "&$B13) -> Blue Dolphin - PUD KKD 300/500 | M13: =IF($A13="",0,IF(OR($D13<>0,$E13<>0),1,0)) -> 0 | N13: =IF($M13=1,SUM($M$8:$M13),"")
A14: Blue Dolphin | B14: PD PVN 200/300 | C14: 2357 | D14: =IF($A14="","",SUMIFS('Daily Entry'!$C$7:$C$5000,'Daily Entry'!$B$7:$B$5000,$L14,'Daily Entry'!$A$7:$A$5000,$C$3)) -> 0 | E14: =IF($A14="","",SUMIFS('Daily Entry'!$D$7:$D$5000,'Daily Entry'!$B$7:$B$5000,$L14,'Daily Entry'!$A$7:$A$5000,$C$3)) -> 0 | F14: =IF($A14="","",SUMIFS('Daily Entry'!$C$7:$C$5000,'Daily Entry'!$B$7:$B$5000,$L14)) -> 0 | G14: =IF($A14="","",SUMIFS('Daily Entry'!$D$7:$D$5000,'Daily Entry'!$B$7:$B$5000,$L14)) -> 0 | H14: =IF($A14="","",$C14+$F14-$G14) -> 2357 | J14: =IF(OR($A14="",$I14="",$C$4=""),"",$H14*$I14*$C$4) | L14: =IF($A14="","",$A14&" - "&$B14) -> Blue Dolphin - PD PVN 200/300 | M14: =IF($A14="",0,IF(OR($D14<>0,$E14<>0),1,0)) -> 0 | N14: =IF($M14=1,SUM($M$8:$M14),"")
A15: Primus Japan | B15: PUD KZN 40/60 | C15: 64 | D15: =IF($A15="","",SUMIFS('Daily Entry'!$C$7:$C$5000,'Daily Entry'!$B$7:$B$5000,$L15,'Daily Entry'!$A$7:$A$5000,$C$3)) -> 29 | E15: =IF($A15="","",SUMIFS('Daily Entry'!$D$7:$D$5000,'Daily Entry'!$B$7:$B$5000,$L15,'Daily Entry'!$A$7:$A$5000,$C$3)) -> 0 | F15: =IF($A15="","",SUMIFS('Daily Entry'!$C$7:$C$5000,'Daily Entry'!$B$7:$B$5000,$L15)) -> 29 | G15: =IF($A15="","",SUMIFS('Daily Entry'!$D$7:$D$5000,'Daily Entry'!$B$7:$B$5000,$L15)) -> 0 | H15: =IF($A15="","",$C15+$F15-$G15) -> 93 | J15: =IF(OR($A15="",$I15="",$C$4=""),"",$H15*$I15*$C$4) | L15: =IF($A15="","",$A15&" - "&$B15) -> Primus Japan - PUD KZN 40/60 | M15: =IF($A15="",0,IF(OR($D15<>0,$E15<>0),1,0)) -> 1 | N15: =IF($M15=1,SUM($M$8:$M15),"") -> 4
A16: Primus Japan | B16: PUD KZN 60/80 | C16: 191 | D16: =IF($A16="","",SUMIFS('Daily Entry'!$C$7:$C$5000,'Daily Entry'!$B$7:$B$5000,$L16,'Daily Entry'!$A$7:$A$5000,$C$3)) -> 39 | E16: =IF($A16="","",SUMIFS('Daily Entry'!$D$7:$D$5000,'Daily Entry'!$B$7:$B$5000,$L16,'Daily Entry'!$A$7:$A$5000,$C$3)) -> 0 | F16: =IF($A16="","",SUMIFS('Daily Entry'!$C$7:$C$5000,'Daily Entry'!$B$7:$B$5000,$L16)) -> 39 | G16: =IF($A16="","",SUMIFS('Daily Entry'!$D$7:$D$5000,'Daily Entry'!$B$7:$B$5000,$L16)) -> 0 | H16: =IF($A16="","",$C16+$F16-$G16) -> 230 | J16: =IF(OR($A16="",$I16="",$C$4=""),"",$H16*$I16*$C$4) | L16: =IF($A16="","",$A16&" - "&$B16) -> Primus Japan - PUD KZN 60/80 | M16: =IF($A16="",0,IF(OR($D16<>0,$E16<>0),1,0)) -> 1 | N16: =IF($M16=1,SUM($M$8:$M16),"") -> 5
A17: Primus Japan | B17: PUD PVN 80/120 | C17: 16849 | D17: =IF($A17="","",SUMIFS('Daily Entry'!$C$7:$C$5000,'Daily Entry'!$B$7:$B$5000,$L17,'Daily Entry'!$A$7:$A$5000,$C$3)) -> 0 | E17: =IF($A17="","",SUMIFS('Daily Entry'!$D$7:$D$5000,'Daily Entry'!$B$7:$B$5000,$L17,'Daily Entry'!$A$7:$A$5000,$C$3)) -> 0 | F17: =IF($A17="","",SUMIFS('Daily Entry'!$C$7:$C$5000,'Daily Entry'!$B$7:$B$5000,$L17)) -> 0 | G17: =IF($A17="","",SUMIFS('Daily Entry'!$D$7:$D$5000,'Daily Entry'!$B$7:$B$5000,$L17)) -> 0 | H17: =IF($A17="","",$C17+$F17-$G17) -> 16849 | J17: =IF(OR($A17="",$I17="",$C$4=""),"",$H17*$I17*$C$4) | L17: =IF($A17="","",$A17&" - "&$B17) -> Primus Japan - PUD PVN 80/120 | M17: =IF($A17="",0,IF(OR($D17<>0,$E17<>0),1,0)) -> 0 | N17: =IF($M17=1,SUM($M$8:$M17),"")
A18: Primus Japan | B18: PUD KZN 80/120 | C18: 466 | D18: =IF($A18="","",SUMIFS('Daily Entry'!$C$7:$C$5000,'Daily Entry'!$B$7:$B$5000,$L18,'Daily Entry'!$A$7:$A$5000,$C$3)) -> 50 | E18: =IF($A18="","",SUMIFS('Daily Entry'!$D$7:$D$5000,'Daily Entry'!$B$7:$B$5000,$L18,'Daily Entry'!$A$7:$A$5000,$C$3)) -> 0 | F18: =IF($A18="","",SUMIFS('Daily Entry'!$C$7:$C$5000,'Daily Entry'!$B$7:$B$5000,$L18)) -> 50 | G18: =IF($A18="","",SUMIFS('Daily Entry'!$D$7:$D$5000,'Daily Entry'!$B$7:$B$5000,$L18)) -> 0 | H18: =IF($A18="","",$C18+$F18-$G18) -> 516 | J18: =IF(OR($A18="",$I18="",$C$4=""),"",$H18*$I18*$C$4) | L18: =IF($A18="","",$A18&" - "&$B18) -> Primus Japan - PUD KZN 80/120 | M18: =IF($A18="",0,IF(OR($D18<>0,$E18<>0),1,0)) -> 1 | N18: =IF($M18=1,SUM($M$8:$M18),"") -> 6
A19: Primus Japan | B19: PUD NRN 80/120 | C19: 69 | D19: =IF($A19="","",SUMIFS('Daily Entry'!$C$7:$C$5000,'Daily Entry'!$B$7:$B$5000,$L19,'Daily Entry'!$A$7:$A$5000,$C$3)) -> 3 | E19: =IF($A19="","",SUMIFS('Daily Entry'!$D$7:$D$5000,'Daily Entry'!$B$7:$B$5000,$L19,'Daily Entry'!$A$7:$A$5000,$C$3)) -> 0 | F19: =IF($A19="","",SUMIFS('Daily Entry'!$C$7:$C$5000,'Daily Entry'!$B$7:$B$5000,$L19)) -> 3 | G19: =IF($A19="","",SUMIFS('Daily Entry'!$D$7:$D$5000,'Daily Entry'!$B$7:$B$5000,$L19)) -> 0 | H19: =IF($A19="","",$C19+$F19-$G19) -> 72 | J19: =IF(OR($A19="",$I19="",$C$4=""),"",$H19*$I19*$C$4) | L19: =IF($A19="","",$A19&" - "&$B19) -> Primus Japan - PUD NRN 80/120 | M19: =IF($A19="",0,IF(OR($D19<>0,$E19<>0),1,0)) -> 1 | N19: =IF($M19=1,SUM($M$8:$M19),"") -> 7
... A49: China | B49: PUD KKD 500/800 | C49: 1920 | D49: =IF($A49="","",SUMIFS('Daily Entry'!$C$7:$C$5000,'Daily Entry'!$B$7:$B$5000,$L49,'Daily Entry'!$A$7:$A$5000,$C$3)) -> 0 | E49: =IF($A49="","",SUMIFS('Daily Entry'!$D$7:$D$5000,'Daily Entry'!$B$7:$B$5000,$L49,'Daily Entry'!$A$7:$A$5000,$C$3)) -> 0 | F49: =IF($A49="","",SUMIFS('Daily Entry'!$C$7:$C$5000,'Daily Entry'!$B$7:$B$5000,$L49)) -> 0 | G49: =IF($A49="","",SUMIFS('Daily Entry'!$D$7:$D$5000,'Daily Entry'!$B$7:$B$5000,$L49)) -> 0 | H49: =IF($A49="","",$C49+$F49-$G49) -> 1920 | J49: =IF(OR($A49="",$I49="",$C$4=""),"",$H49*$I49*$C$4) | L49: =IF($A49="","",$A49&" - "&$B49) -> China - PUD KKD 500/800 | M49: =IF($A49="",0,IF(OR($D49<>0,$E49<>0),1,0)) -> 0 | N49: =IF($M49=1,SUM($M$8:$M49),"")
D50: =IF($A50="","",SUMIFS('Daily Entry'!$C$7:$C$5000,'Daily Entry'!$B$7:$B$5000,$L50,'Daily Entry'!$A$7:$A$5000,$C$3)) | E50: =IF($A50="","",SUMIFS('Daily Entry'!$D$7:$D$5000,'Daily Entry'!$B$7:$B$5000,$L50,'Daily Entry'!$A$7:$A$5000,$C$3)) | F50: =IF($A50="","",SUMIFS('Daily Entry'!$C$7:$C$5000,'Daily Entry'!$B$7:$B$5000,$L50)) | G50: =IF($A50="","",SUMIFS('Daily Entry'!$D$7:$D$5000,'Daily Entry'!$B$7:$B$5000,$L50)) | H50: =IF($A50="","",$C50+$F50-$G50) | J50: =IF(OR($A50="",$I50="",$C$4=""),"",$H50*$I50*$C$4) | L50: =IF($A50="","",$A50&" - "&$B50) | M50: =IF($A50="",0,IF(OR($D50<>0,$E50<>0),1,0)) -> 0 | N50: =IF($M50=1,SUM($M$8:$M50),"")
D51: =IF($A51="","",SUMIFS('Daily Entry'!$C$7:$C$5000,'Daily Entry'!$B$7:$B$5000,$L51,'Daily Entry'!$A$7:$A$5000,$C$3)) | E51: =IF($A51="","",SUMIFS('Daily Entry'!$D$7:$D$5000,'Daily Entry'!$B$7:$B$5000,$L51,'Daily Entry'!$A$7:$A$5000,$C$3)) | F51: =IF($A51="","",SUMIFS('Daily Entry'!$C$7:$C$5000,'Daily Entry'!$B$7:$B$5000,$L51)) | G51: =IF($A51="","",SUMIFS('Daily Entry'!$D$7:$D$5000,'Daily Entry'!$B$7:$B$5000,$L51)) | H51: =IF($A51="","",$C51+$F51-$G51) | J51: =IF(OR($A51="",$I51="",$C$4=""),"",$H51*$I51*$C$4) | L51: =IF($A51="","",$A51&" - "&$B51) | M51: =IF($A51="",0,IF(OR($D51<>0,$E51<>0),1,0)) -> 0 | N51: =IF($M51=1,SUM($M$8:$M51),"")
D52: =IF($A52="","",SUMIFS('Daily Entry'!$C$7:$C$5000,'Daily Entry'!$B$7:$B$5000,$L52,'Daily Entry'!$A$7:$A$5000,$C$3)) | E52: =IF($A52="","",SUMIFS('Daily Entry'!$D$7:$D$5000,'Daily Entry'!$B$7:$B$5000,$L52,'Daily Entry'!$A$7:$A$5000,$C$3)) | F52: =IF($A52="","",SUMIFS('Daily Entry'!$C$7:$C$5000,'Daily Entry'!$B$7:$B$5000,$L52)) | G52: =IF($A52="","",SUMIFS('Daily Entry'!$D$7:$D$5000,'Daily Entry'!$B$7:$B$5000,$L52)) | H52: =IF($A52="","",$C52+$F52-$G52) | J52: =IF(OR($A52="",$I52="",$C$4=""),"",$H52*$I52*$C$4) | L52: =IF($A52="","",$A52&" - "&$B52) | M52: =IF($A52="",0,IF(OR($D52<>0,$E52<>0),1,0)) -> 0 | N52: =IF($M52=1,SUM($M$8:$M52),"")
D53: =IF($A53="","",SUMIFS('Daily Entry'!$C$7:$C$5000,'Daily Entry'!$B$7:$B$5000,$L53,'Daily Entry'!$A$7:$A$5000,$C$3)) | E53: =IF($A53="","",SUMIFS('Daily Entry'!$D$7:$D$5000,'Daily Entry'!$B$7:$B$5000,$L53,'Daily Entry'!$A$7:$A$5000,$C$3)) | F53: =IF($A53="","",SUMIFS('Daily Entry'!$C$7:$C$5000,'Daily Entry'!$B$7:$B$5000,$L53)) | G53: =IF($A53="","",SUMIFS('Daily Entry'!$D$7:$D$5000,'Daily Entry'!$B$7:$B$5000,$L53)) | H53: =IF($A53="","",$C53+$F53-$G53) | J53: =IF(OR($A53="",$I53="",$C$4=""),"",$H53*$I53*$C$4) | L53: =IF($A53="","",$A53&" - "&$B53) | M53: =IF($A53="",0,IF(OR($D53<>0,$E53<>0),1,0)) -> 0 | N53: =IF($M53=1,SUM($M$8:$M53),"")
D54: =IF($A54="","",SUMIFS('Daily Entry'!$C$7:$C$5000,'Daily Entry'!$B$7:$B$5000,$L54,'Daily Entry'!$A$7:$A$5000,$C$3)) | E54: =IF($A54="","",SUMIFS('Daily Entry'!$D$7:$D$5000,'Daily Entry'!$B$7:$B$5000,$L54,'Daily Entry'!$A$7:$A$5000,$C$3)) | F54: =IF($A54="","",SUMIFS('Daily Entry'!$C$7:$C$5000,'Daily Entry'!$B$7:$B$5000,$L54)) | G54: =IF($A54="","",SUMIFS('Daily Entry'!$D$7:$D$5000,'Daily Entry'!$B$7:$B$5000,$L54)) | H54: =IF($A54="","",$C54+$F54-$G54) | J54: =IF(OR($A54="",$I54="",$C$4=""),"",$H54*$I54*$C$4) | L54: =IF($A54="","",$A54&" - "&$B54) | M54: =IF($A54="",0,IF(OR($D54<>0,$E54<>0),1,0)) -> 0 | N54: =IF($M54=1,SUM($M$8:$M54),"")
D55: =IF($A55="","",SUMIFS('Daily Entry'!$C$7:$C$5000,'Daily Entry'!$B$7:$B$5000,$L55,'Daily Entry'!$A$7:$A$5000,$C$3)) | E55: =IF($A55="","",SUMIFS('Daily Entry'!$D$7:$D$5000,'Daily Entry'!$B$7:$B$5000,$L55,'Daily Entry'!$A$7:$A$5000,$C$3)) | F55: =IF($A55="","",SUMIFS('Daily Entry'!$C$7:$C$5000,'Daily Entry'!$B$7:$B$5000,$L55)) | G55: =IF($A55="","",SUMIFS('Daily Entry'!$D$7:$D$5000,'Daily Entry'!$B$7:$B$5000,$L55)) | H55: =IF($A55="","",$C55+$F55-$G55) | J55: =IF(OR($A55="",$I55="",$C$4=""),"",$H55*$I55*$C$4) | L55: =IF($A55="","",$A55&" - "&$B55) | M55: =IF($A55="",0,IF(OR($D55<>0,$E55<>0),1,0)) -> 0 | N55: =IF($M55=1,SUM($M$8:$M55),"")
D56: =IF($A56="","",SUMIFS('Daily Entry'!$C$7:$C$5000,'Daily Entry'!$B$7:$B$5000,$L56,'Daily Entry'!$A$7:$A$5000,$C$3)) | E56: =IF($A56="","",SUMIFS('Daily Entry'!$D$7:$D$5000,'Daily Entry'!$B$7:$B$5000,$L56,'Daily Entry'!$A$7:$A$5000,$C$3)) | F56: =IF($A56="","",SUMIFS('Daily Entry'!$C$7:$C$5000,'Daily Entry'!$B$7:$B$5000,$L56)) | G56: =IF($A56="","",SUMIFS('Daily Entry'!$D$7:$D$5000,'Daily Entry'!$B$7:$B$5000,$L56)) | H56: =IF($A56="","",$C56+$F56-$G56) | J56: =IF(OR($A56="",$I56="",$C$4=""),"",$H56*$I56*$C$4) | L56: =IF($A56="","",$A56&" - "&$B56) | M56: =IF($A56="",0,IF(OR($D56<>0,$E56<>0),1,0)) -> 0 | N56: =IF($M56=1,SUM($M$8:$M56),"")
D57: =IF($A57="","",SUMIFS('Daily Entry'!$C$7:$C$5000,'Daily Entry'!$B$7:$B$5000,$L57,'Daily Entry'!$A$7:$A$5000,$C$3)) | E57: =IF($A57="","",SUMIFS('Daily Entry'!$D$7:$D$5000,'Daily Entry'!$B$7:$B$5000,$L57,'Daily Entry'!$A$7:$A$5000,$C$3)) | F57: =IF($A57="","",SUMIFS('Daily Entry'!$C$7:$C$5000,'Daily Entry'!$B$7:$B$5000,$L57)) | G57: =IF($A57="","",SUMIFS('Daily Entry'!$D$7:$D$5000,'Daily Entry'!$B$7:$B$5000,$L57)) | H57: =IF($A57="","",$C57+$F57-$G57) | J57: =IF(OR($A57="",$I57="",$C$4=""),"",$H57*$I57*$C$4) | L57: =IF($A57="","",$A57&" - "&$B57) | M57: =IF($A57="",0,IF(OR($D57<>0,$E57<>0),1,0)) -> 0 | N57: =IF($M57=1,SUM($M$8:$M57),"")
D58: =IF($A58="","",SUMIFS('Daily Entry'!$C$7:$C$5000,'Daily Entry'!$B$7:$B$5000,$L58,'Daily Entry'!$A$7:$A$5000,$C$3)) | E58: =IF($A58="","",SUMIFS('Daily Entry'!$D$7:$D$5000,'Daily Entry'!$B$7:$B$5000,$L58,'Daily Entry'!$A$7:$A$5000,$C$3)) | F58: =IF($A58="","",SUMIFS('Daily Entry'!$C$7:$C$5000,'Daily Entry'!$B$7:$B$5000,$L58)) | G58: =IF($A58="","",SUMIFS('Daily Entry'!$D$7:$D$5000,'Daily Entry'!$B$7:$B$5000,$L58)) | H58: =IF($A58="","",$C58+$F58-$G58) | J58: =IF(OR($A58="",$I58="",$C$4=""),"",$H58*$I58*$C$4) | L58: =IF($A58="","",$A58&" - "&$B58) | M58: =IF($A58="",0,IF(OR($D58<>0,$E58<>0),1,0)) -> 0 | N58: =IF($M58=1,SUM($M$8:$M58),"")
D59: =IF($A59="","",SUMIFS('Daily Entry'!$C$7:$C$5000,'Daily Entry'!$B$7:$B$5000,$L59,'Daily Entry'!$A$7:$A$5000,$C$3)) | E59: =IF($A59="","",SUMIFS('Daily Entry'!$D$7:$D$5000,'Daily Entry'!$B$7:$B$5000,$L59,'Daily Entry'!$A$7:$A$5000,$C$3)) | F59: =IF($A59="","",SUMIFS('Daily Entry'!$C$7:$C$5000,'Daily Entry'!$B$7:$B$5000,$L59)) | G59: =IF($A59="","",SUMIFS('Daily Entry'!$D$7:$D$5000,'Daily Entry'!$B$7:$B$5000,$L59)) | H59: =IF($A59="","",$C59+$F59-$G59) | J59: =IF(OR($A59="",$I59="",$C$4=""),"",$H59*$I59*$C$4) | L59: =IF($A59="","",$A59&" - "&$B59) | M59: =IF($A59="",0,IF(OR($D59<>0,$E59<>0),1,0)) -> 0 | N59: =IF($M59=1,SUM($M$8:$M59),"")
D60: =IF($A60="","",SUMIFS('Daily Entry'!$C$7:$C$5000,'Daily Entry'!$B$7:$B$5000,$L60,'Daily Entry'!$A$7:$A$5000,$C$3)) | E60: =IF($A60="","",SUMIFS('Daily Entry'!$D$7:$D$5000,'Daily Entry'!$B$7:$B$5000,$L60,'Daily Entry'!$A$7:$A$5000,$C$3)) | F60: =IF($A60="","",SUMIFS('Daily Entry'!$C$7:$C$5000,'Daily Entry'!$B$7:$B$5000,$L60)) | G60: =IF($A60="","",SUMIFS('Daily Entry'!$D$7:$D$5000,'Daily Entry'!$B$7:$B$5000,$L60)) | H60: =IF($A60="","",$C60+$F60-$G60) | J60: =IF(OR($A60="",$I60="",$C$4=""),"",$H60*$I60*$C$4) | L60: =IF($A60="","",$A60&" - "&$B60) | M60: =IF($A60="",0,IF(OR($D60<>0,$E60<>0),1,0)) -> 0 | N60: =IF($M60=1,SUM($M$8:$M60),"")
D61: =IF($A61="","",SUMIFS('Daily Entry'!$C$7:$C$5000,'Daily Entry'!$B$7:$B$5000,$L61,'Daily Entry'!$A$7:$A$5000,$C$3)) | E61: =IF($A61="","",SUMIFS('Daily Entry'!$D$7:$D$5000,'Daily Entry'!$B$7:$B$5000,$L61,'Daily Entry'!$A$7:$A$5000,$C$3)) | F61: =IF($A61="","",SUMIFS('Daily Entry'!$C$7:$C$5000,'Daily Entry'!$B$7:$B$5000,$L61)) | G61: =IF($A61="","",SUMIFS('Daily Entry'!$D$7:$D$5000,'Daily Entry'!$B$7:$B$5000,$L61)) | H61: =IF($A61="","",$C61+$F61-$G61) | J61: =IF(OR($A61="",$I61="",$C$4=""),"",$H61*$I61*$C$4) | L61: =IF($A61="","",$A61&" - "&$B61) | M61: =IF($A61="",0,IF(OR($D61<>0,$E61<>0),1,0)) -> 0 | N61: =IF($M61=1,SUM($M$8:$M61),"")
... D69: =IF($A69="","",SUMIFS('Daily Entry'!$C$7:$C$5000,'Daily Entry'!$B$7:$B$5000,$L69,'Daily Entry'!$A$7:$A$5000,$C$3)) | E69: =IF($A69="","",SUMIFS('Daily Entry'!$D$7:$D$5000,'Daily Entry'!$B$7:$B$5000,$L69,'Daily Entry'!$A$7:$A$5000,$C$3)) | F69: =IF($A69="","",SUMIFS('Daily Entry'!$C$7:$C$5000,'Daily Entry'!$B$7:$B$5000,$L69)) | G69: =IF($A69="","",SUMIFS('Daily Entry'!$D$7:$D$5000,'Daily Entry'!$B$7:$B$5000,$L69)) | H69: =IF($A69="","",$C69+$F69-$G69) | J69: =IF(OR($A69="",$I69="",$C$4=""),"",$H69*$I69*$C$4) | L69: =IF($A69="","",$A69&" - "&$B69) | M69: =IF($A69="",0,IF(OR($D69<>0,$E69<>0),1,0)) -> 0 | N69: =IF($M69=1,SUM($M$8:$M69),"")
A70: GRAND TOTAL | C70: =SUM(C8:C69) -> 102870 | D70: =SUM(D8:D69) -> 4880 | E70: =SUM(E8:E69) -> 0 | F70: =SUM(F8:F69) -> 4880 | G70: =SUM(G8:G69) -> 0 | H70: =SUM(H8:H69) -> 107750 | J70: =IF(SUM(J8:J69)=0,"",SUM(J8:J69))
A72: Closing Balance = Opening Balance + Production to Date − Shipment to Date Stock Value = Closing Balance × Rate per Slab

Sheet Daily Entry
A1: PREMIER EXPORTS INTERNATIONAL
A2: DAILY ENTRY — ADD ONE ROW PER PRODUCT THAT MOVED
A4: After production, add a row below: date, product from the dropdown, slabs produced and/or shipped. Never delete past rows — they are what the closing position is built from. | G4: Rows that will not reach Stock: | J4: =SUMPRODUCT((B7:B5000<>"")*(COUNTIF(Stock!$L$8:$L$69,B7:B5000)=0)) -> 0 | K4: ← must stay at 0; anything else is a mistyped product
A6: Date | B6: Item (pick from list) | C6: Production (slabs) | D6: Shipment (slabs) | E6: Note
A7: 46254 | B7: Blue Dolphin - PD PVN 100/200 | C7: 1068 | D7: 0 | E7: Day's production per statement 20/08/26
A8: 46254 | B8: Blue Dolphin - PD KKD 100/200 | C8: 65 | D8: 0
A9: 46254 | B9: Blue Dolphin - PUD PVN 200/300 | C9: 267 | D9: 0
A10: 46254 | B10: Primus Japan - PUD KZN 40/60 | C10: 29 | D10: 0
A11: 46254 | B11: Primus Japan - PUD KZN 60/80 | C11: 39 | D11: 0
A12: 46254 | B12: Primus Japan - PUD KZN 80/120 | C12: 50 | D12: 0
A13: 46254 | B13: Primus Japan - PUD NRN 80/120 | C13: 3 | D13: 0
A14: 46254 | B14: Primus Japan - PUD KZN 100/200 | C14: 50 | D14: 0
A15: 46254 | B15: Primus Japan - PUD KZN 200/300 | C15: 33 | D15: 0
A16: 46254 | B16: Primus Japan - PUD PVN 300/500 | C16: 156 | D16: 0
A17: 46254 | B17: Primus Japan - PUD KKD 300/500 | C17: 596 | D17: 0
A18: 46254 | B18: Primus EU - BKN | C18: 52 | D18: 0
A19: 46254 | B19: THT Brand - PUD PVN 80/120 | C19: 1872 | D19: 0
A20: 46254 | B20: THT Brand - PUD PVN 100/200 | C20: 600 | D20: 0

Sheet Summary
A1: PREMIER EXPORTS INTERNATIONAL
A2: SUMMARY BY BRAND
A4: Closing Stock | C4: Stock Value | E4: Stock Value (US$)
A5: =Stock!$H$70 -> 107750 | C5: =IF(Stock!$J$70="","—",Stock!$J$70) -> — | E5: =IF(OR(Stock!$C$4="",Stock!$J$70=""),"—",Stock!$J$70/Stock!$C$4) -> —
A6: slabs | C6: at the export rates and exchange rate on Stock | E6: the same stock at the export prices
A8: Brand | B8: Opening Balance | C8: Today's Production | D8: Today's Shipment | E8: Closing Balance | F8: Stock Value (₹)
A9: Blue Dolphin | B9: =IF($A9="","",SUMIF(Stock!$A$8:$A$69,$A9,Stock!$C$8:$C$69)) -> 28645 | C9: =IF($A9="","",SUMIF(Stock!$A$8:$A$69,$A9,Stock!$D$8:$D$69)) -> 1400 | D9: =IF($A9="","",SUMIF(Stock!$A$8:$A$69,$A9,Stock!$E$8:$E$69)) -> 0 | E9: =IF($A9="","",SUMIF(Stock!$A$8:$A$69,$A9,Stock!$H$8:$H$69)) -> 30045 | F9: =IF(OR($A9="",SUMIF(Stock!$A$8:$A$69,$A9,Stock!$J$8:$J$69)=0),"",SUMIF(Stock!$A$8:$A$69,$A9,Stock!$J$8:$J$69))
A10: Primus Japan | B10: =IF($A10="","",SUMIF(Stock!$A$8:$A$69,$A10,Stock!$C$8:$C$69)) -> 29316 | C10: =IF($A10="","",SUMIF(Stock!$A$8:$A$69,$A10,Stock!$D$8:$D$69)) -> 956 | D10: =IF($A10="","",SUMIF(Stock!$A$8:$A$69,$A10,Stock!$E$8:$E$69)) -> 0 | E10: =IF($A10="","",SUMIF(Stock!$A$8:$A$69,$A10,Stock!$H$8:$H$69)) -> 30272 | F10: =IF(OR($A10="",SUMIF(Stock!$A$8:$A$69,$A10,Stock!$J$8:$J$69)=0),"",SUMIF(Stock!$A$8:$A$69,$A10,Stock!$J$8:$J$69))
A11: Primus EU | B11: =IF($A11="","",SUMIF(Stock!$A$8:$A$69,$A11,Stock!$C$8:$C$69)) -> 26619 | C11: =IF($A11="","",SUMIF(Stock!$A$8:$A$69,$A11,Stock!$D$8:$D$69)) -> 52 | D11: =IF($A11="","",SUMIF(Stock!$A$8:$A$69,$A11,Stock!$E$8:$E$69)) -> 0 | E11: =IF($A11="","",SUMIF(Stock!$A$8:$A$69,$A11,Stock!$H$8:$H$69)) -> 26671 | F11: =IF(OR($A11="",SUMIF(Stock!$A$8:$A$69,$A11,Stock!$J$8:$J$69)=0),"",SUMIF(Stock!$A$8:$A$69,$A11,Stock!$J$8:$J$69))
A12: AMF Brand | B12: =IF($A12="","",SUMIF(Stock!$A$8:$A$69,$A12,Stock!$C$8:$C$69)) -> 1534 | C12: =IF($A12="","",SUMIF(Stock!$A$8:$A$69,$A12,Stock!$D$8:$D$69)) -> 0 | D12: =IF($A12="","",SUMIF(Stock!$A$8:$A$69,$A12,Stock!$E$8:$E$69)) -> 0 | E12: =IF($A12="","",SUMIF(Stock!$A$8:$A$69,$A12,Stock!$H$8:$H$69)) -> 1534 | F12: =IF(OR($A12="",SUMIF(Stock!$A$8:$A$69,$A12,Stock!$J$8:$J$69)=0),"",SUMIF(Stock!$A$8:$A$69,$A12,Stock!$J$8:$J$69))
A13: THT Brand | B13: =IF($A13="","",SUMIF(Stock!$A$8:$A$69,$A13,Stock!$C$8:$C$69)) -> 13126 | C13: =IF($A13="","",SUMIF(Stock!$A$8:$A$69,$A13,Stock!$D$8:$D$69)) -> 2472 | D13: =IF($A13="","",SUMIF(Stock!$A$8:$A$69,$A13,Stock!$E$8:$E$69)) -> 0 | E13: =IF($A13="","",SUMIF(Stock!$A$8:$A$69,$A13,Stock!$H$8:$H$69)) -> 15598 | F13: =IF(OR($A13="",SUMIF(Stock!$A$8:$A$69,$A13,Stock!$J$8:$J$69)=0),"",SUMIF(Stock!$A$8:$A$69,$A13,Stock!$J$8:$J$69))
A14: Deepsea | B14: =IF($A14="","",SUMIF(Stock!$A$8:$A$69,$A14,Stock!$C$8:$C$69)) -> 670 | C14: =IF($A14="","",SUMIF(Stock!$A$8:$A$69,$A14,Stock!$D$8:$D$69)) -> 0 | D14: =IF($A14="","",SUMIF(Stock!$A$8:$A$69,$A14,Stock!$E$8:$E$69)) -> 0 | E14: =IF($A14="","",SUMIF(Stock!$A$8:$A$69,$A14,Stock!$H$8:$H$69)) -> 670 | F14: =IF(OR($A14="",SUMIF(Stock!$A$8:$A$69,$A14,Stock!$J$8:$J$69)=0),"",SUMIF(Stock!$A$8:$A$69,$A14,Stock!$J$8:$J$69))
A15: China | B15: =IF($A15="","",SUMIF(Stock!$A$8:$A$69,$A15,Stock!$C$8:$C$69)) -> 2960 | C15: =IF($A15="","",SUMIF(Stock!$A$8:$A$69,$A15,Stock!$D$8:$D$69)) -> 0 | D15: =IF($A15="","",SUMIF(Stock!$A$8:$A$69,$A15,Stock!$E$8:$E$69)) -> 0 | E15: =IF($A15="","",SUMIF(Stock!$A$8:$A$69,$A15,Stock!$H$8:$H$69)) -> 2960 | F15: =IF(OR($A15="",SUMIF(Stock!$A$8:$A$69,$A15,Stock!$J$8:$J$69)=0),"",SUMIF(Stock!$A$8:$A$69,$A15,Stock!$J$8:$J$69))
A16: Shrimp Whole 5x3kgs | B16: =IF($A16="","",SUMIF(Stock!$A$8:$A$69,$A16,Stock!$C$8:$C$69)) -> 0 | C16: =IF($A16="","",SUMIF(Stock!$A$8:$A$69,$A16,Stock!$D$8:$D$69)) -> 0 | D16: =IF($A16="","",SUMIF(Stock!$A$8:$A$69,$A16,Stock!$E$8:$E$69)) -> 0 | E16: =IF($A16="","",SUMIF(Stock!$A$8:$A$69,$A16,Stock!$H$8:$H$69)) -> 0 | F16: =IF(OR($A16="",SUMIF(Stock!$A$8:$A$69,$A16,Stock!$J$8:$J$69)=0),"",SUMIF(Stock!$A$8:$A$69,$A16,Stock!$J$8:$J$69))
B17: =IF($A17="","",SUMIF(Stock!$A$8:$A$69,$A17,Stock!$C$8:$C$69)) | C17: =IF($A17="","",SUMIF(Stock!$A$8:$A$69,$A17,Stock!$D$8:$D$69)) | D17: =IF($A17="","",SUMIF(Stock!$A$8:$A$69,$A17,Stock!$E$8:$E$69)) | E17: =IF($A17="","",SUMIF(Stock!$A$8:$A$69,$A17,Stock!$H$8:$H$69)) | F17: =IF(OR($A17="",SUMIF(Stock!$A$8:$A$69,$A17,Stock!$J$8:$J$69)=0),"",SUMIF(Stock!$A$8:$A$69,$A17,Stock!$J$8:$J$69))
B18: =IF($A18="","",SUMIF(Stock!$A$8:$A$69,$A18,Stock!$C$8:$C$69)) | C18: =IF($A18="","",SUMIF(Stock!$A$8:$A$69,$A18,Stock!$D$8:$D$69)) | D18: =IF($A18="","",SUMIF(Stock!$A$8:$A$69,$A18,Stock!$E$8:$E$69)) | E18: =IF($A18="","",SUMIF(Stock!$A$8:$A$69,$A18,Stock!$H$8:$H$69)) | F18: =IF(OR($A18="",SUMIF(Stock!$A$8:$A$69,$A18,Stock!$J$8:$J$69)=0),"",SUMIF(Stock!$A$8:$A$69,$A18,Stock!$J$8:$J$69))
B19: =IF($A19="","",SUMIF(Stock!$A$8:$A$69,$A19,Stock!$C$8:$C$69)) | C19: =IF($A19="","",SUMIF(Stock!$A$8:$A$69,$A19,Stock!$D$8:$D$69)) | D19: =IF($A19="","",SUMIF(Stock!$A$8:$A$69,$A19,Stock!$E$8:$E$69)) | E19: =IF($A19="","",SUMIF(Stock!$A$8:$A$69,$A19,Stock!$H$8:$H$69)) | F19: =IF(OR($A19="",SUMIF(Stock!$A$8:$A$69,$A19,Stock!$J$8:$J$69)=0),"",SUMIF(Stock!$A$8:$A$69,$A19,Stock!$J$8:$J$69))
A20: GRAND TOTAL | B20: =SUM(B9:B19) -> 102870 | C20: =SUM(C9:C19) -> 4880 | D20: =SUM(D9:D19) -> 0 | E20: =SUM(E9:E19) -> 107750 | F20: =IF(SUM(F9:F19)=0,"",SUM(F9:F19))
A22: =IF(ROUND(SUM($E$9:$E$19),2)<>ROUND(Stock!$H$70,2),"A brand used on Stock is missing from this list — type it into a blank row above, or the totals understate the stock.","")
A23: Brand totals read straight off 'Stock', so they can never disagree with it.

Sheet Daily Report
B1: Premier Exports International | E1: AP X/453, NH-66 Highway, Chandiroor P.O.,
E2: Aroor, Alappuzha, Kerala - 688 537, India
E3: GSTIN 32AADFP3158P1ZZ
A5: DAILY STOCK REPORT | E5: =Stock!$C$3 -> 46254
A6: PURCHASE & PROCESSING · PRODUCTION | E6: STATEMENT DATE
A8: OPENING BALANCE | B8: TODAY'S PRODUCTION | C8: TODAY'S SHIPMENT | D8: CLOSING BALANCE | E8: =IF(Stock!$C$4="","STOCK VALUE (₹)","STOCK VALUE (₹) AT "&TEXT(Stock!$C$4,"0.00")&" / US$") -> STOCK VALUE (₹)
A9: =Stock!$C$70 -> 102870 | B9: =Stock!$D$70 -> 4880 | C9: =Stock!$E$70 -> 0 | D9: =Stock!$H$70 -> 107750 | E9: =IF(Stock!$C$4="","Exchange rate not set",IF(Stock!$J$70="","Export rates not entered",Stock!$J$70)) -> Exchange rate not set
A10: =IF(ROUND(Summary!$E$20,2)<>ROUND(Stock!$H$70,2),"A brand on Stock is missing from the Summary list — this report understates the total. Add it before sending.","")
A11: POSITION BY BRAND
A12: Brand | B12: Opening Balance | C12: Today's Production | D12: Today's Shipment | E12: Closing Balance | F12: Stock Value (₹)
A13: =IF(Summary!$A$9="","",Summary!$A$9) -> Blue Dolphin | B13: =IF(Summary!$A$9="","",Summary!$B$9) -> 28645 | C13: =IF(Summary!$A$9="","",Summary!$C$9) -> 1400 | D13: =IF(Summary!$A$9="","",Summary!$D$9) -> 0 | E13: =IF(Summary!$A$9="","",Summary!$E$9) -> 30045 | F13: =IF(Summary!$A$9="","",Summary!$F$9)
A14: =IF(Summary!$A$10="","",Summary!$A$10) -> Primus Japan | B14: =IF(Summary!$A$10="","",Summary!$B$10) -> 29316 | C14: =IF(Summary!$A$10="","",Summary!$C$10) -> 956 | D14: =IF(Summary!$A$10="","",Summary!$D$10) -> 0 | E14: =IF(Summary!$A$10="","",Summary!$E$10) -> 30272 | F14: =IF(Summary!$A$10="","",Summary!$F$10)
A15: =IF(Summary!$A$11="","",Summary!$A$11) -> Primus EU | B15: =IF(Summary!$A$11="","",Summary!$B$11) -> 26619 | C15: =IF(Summary!$A$11="","",Summary!$C$11) -> 52 | D15: =IF(Summary!$A$11="","",Summary!$D$11) -> 0 | E15: =IF(Summary!$A$11="","",Summary!$E$11) -> 26671 | F15: =IF(Summary!$A$11="","",Summary!$F$11)
A16: =IF(Summary!$A$12="","",Summary!$A$12) -> AMF Brand | B16: =IF(Summary!$A$12="","",Summary!$B$12) -> 1534 | C16: =IF(Summary!$A$12="","",Summary!$C$12) -> 0 | D16: =IF(Summary!$A$12="","",Summary!$D$12) -> 0 | E16: =IF(Summary!$A$12="","",Summary!$E$12) -> 1534 | F16: =IF(Summary!$A$12="","",Summary!$F$12)
A17: =IF(Summary!$A$13="","",Summary!$A$13) -> THT Brand | B17: =IF(Summary!$A$13="","",Summary!$B$13) -> 13126 | C17: =IF(Summary!$A$13="","",Summary!$C$13) -> 2472 | D17: =IF(Summary!$A$13="","",Summary!$D$13) -> 0 | E17: =IF(Summary!$A$13="","",Summary!$E$13) -> 15598 | F17: =IF(Summary!$A$13="","",Summary!$F$13)
A18: =IF(Summary!$A$14="","",Summary!$A$14) -> Deepsea | B18: =IF(Summary!$A$14="","",Summary!$B$14) -> 670 | C18: =IF(Summary!$A$14="","",Summary!$C$14) -> 0 | D18: =IF(Summary!$A$14="","",Summary!$D$14) -> 0 | E18: =IF(Summary!$A$14="","",Summary!$E$14) -> 670 | F18: =IF(Summary!$A$14="","",Summary!$F$14)
A19: =IF(Summary!$A$15="","",Summary!$A$15) -> China | B19: =IF(Summary!$A$15="","",Summary!$B$15) -> 2960 | C19: =IF(Summary!$A$15="","",Summary!$C$15) -> 0 | D19: =IF(Summary!$A$15="","",Summary!$D$15) -> 0 | E19: =IF(Summary!$A$15="","",Summary!$E$15) -> 2960 | F19: =IF(Summary!$A$15="","",Summary!$F$15)
A20: =IF(Summary!$A$16="","",Summary!$A$16) -> Shrimp Whole 5x3kgs | B20: =IF(Summary!$A$16="","",Summary!$B$16) -> 0 | C20: =IF(Summary!$A$16="","",Summary!$C$16) -> 0 | D20: =IF(Summary!$A$16="","",Summary!$D$16) -> 0 | E20: =IF(Summary!$A$16="","",Summary!$E$16) -> 0 | F20: =IF(Summary!$A$16="","",Summary!$F$16)
A21: =IF(Summary!$A$17="","",Summary!$A$17) | B21: =IF(Summary!$A$17="","",Summary!$B$17) | C21: =IF(Summary!$A$17="","",Summary!$C$17) | D21: =IF(Summary!$A$17="","",Summary!$D$17) | E21: =IF(Summary!$A$17="","",Summary!$E$17) | F21: =IF(Summary!$A$17="","",Summary!$F$17)
A22: =IF(Summary!$A$18="","",Summary!$A$18) | B22: =IF(Summary!$A$18="","",Summary!$B$18) | C22: =IF(Summary!$A$18="","",Summary!$C$18) | D22: =IF(Summary!$A$18="","",Summary!$D$18) | E22: =IF(Summary!$A$18="","",Summary!$E$18) | F22: =IF(Summary!$A$18="","",Summary!$F$18)
A23: =IF(Summary!$A$19="","",Summary!$A$19) | B23: =IF(Summary!$A$19="","",Summary!$B$19) | C23: =IF(Summary!$A$19="","",Summary!$C$19) | D23: =IF(Summary!$A$19="","",Summary!$D$19) | E23: =IF(Summary!$A$19="","",Summary!$E$19) | F23: =IF(Summary!$A$19="","",Summary!$F$19)
A24: =Summary!$A$20 -> GRAND TOTAL | B24: =Summary!$B$20 -> 102870 | C24: =Summary!$C$20 -> 4880 | D24: =Summary!$D$20 -> 0 | E24: =Summary!$E$20 -> 107750 | F24: =Summary!$F$20
A26: TODAY'S MOVEMENTS
A27: Brand | B27: Product | C27: Production | D27: Shipment | E27: Closing Balance
A28: =IF($H28="","",INDEX(Stock!$A$8:$A$69,$H28)) -> Blue Dolphin | B28: =IF($H28="","",INDEX(Stock!$B$8:$B$69,$H28)) -> PD PVN 100/200 | C28: =IF($H28="","",INDEX(Stock!$D$8:$D$69,$H28)) -> 1068 | D28: =IF($H28="","",INDEX(Stock!$E$8:$E$69,$H28)) -> 0 | E28: =IF($H28="","",INDEX(Stock!$H$8:$H$69,$H28)) -> 12527 | H28: =IFERROR(MATCH(1,Stock!$N$8:$N$69,0),"") -> 1
A29: =IF($H29="","",INDEX(Stock!$A$8:$A$69,$H29)) -> Blue Dolphin | B29: =IF($H29="","",INDEX(Stock!$B$8:$B$69,$H29)) -> PD KKD 100/200 | C29: =IF($H29="","",INDEX(Stock!$D$8:$D$69,$H29)) -> 65 | D29: =IF($H29="","",INDEX(Stock!$E$8:$E$69,$H29)) -> 0 | E29: =IF($H29="","",INDEX(Stock!$H$8:$H$69,$H29)) -> 582 | H29: =IFERROR(MATCH(2,Stock!$N$8:$N$69,0),"") -> 2
A30: =IF($H30="","",INDEX(Stock!$A$8:$A$69,$H30)) -> Blue Dolphin | B30: =IF($H30="","",INDEX(Stock!$B$8:$B$69,$H30)) -> PUD PVN 200/300 | C30: =IF($H30="","",INDEX(Stock!$D$8:$D$69,$H30)) -> 267 | D30: =IF($H30="","",INDEX(Stock!$E$8:$E$69,$H30)) -> 0 | E30: =IF($H30="","",INDEX(Stock!$H$8:$H$69,$H30)) -> 2529 | H30: =IFERROR(MATCH(3,Stock!$N$8:$N$69,0),"") -> 3
A31: =IF($H31="","",INDEX(Stock!$A$8:$A$69,$H31)) -> Primus Japan | B31: =IF($H31="","",INDEX(Stock!$B$8:$B$69,$H31)) -> PUD KZN 40/60 | C31: =IF($H31="","",INDEX(Stock!$D$8:$D$69,$H31)) -> 29 | D31: =IF($H31="","",INDEX(Stock!$E$8:$E$69,$H31)) -> 0 | E31: =IF($H31="","",INDEX(Stock!$H$8:$H$69,$H31)) -> 93 | H31: =IFERROR(MATCH(4,Stock!$N$8:$N$69,0),"") -> 8
A32: =IF($H32="","",INDEX(Stock!$A$8:$A$69,$H32)) -> Primus Japan | B32: =IF($H32="","",INDEX(Stock!$B$8:$B$69,$H32)) -> PUD KZN 60/80 | C32: =IF($H32="","",INDEX(Stock!$D$8:$D$69,$H32)) -> 39 | D32: =IF($H32="","",INDEX(Stock!$E$8:$E$69,$H32)) -> 0 | E32: =IF($H32="","",INDEX(Stock!$H$8:$H$69,$H32)) -> 230 | H32: =IFERROR(MATCH(5,Stock!$N$8:$N$69,0),"") -> 9
A33: =IF($H33="","",INDEX(Stock!$A$8:$A$69,$H33)) -> Primus Japan | B33: =IF($H33="","",INDEX(Stock!$B$8:$B$69,$H33)) -> PUD KZN 80/120 | C33: =IF($H33="","",INDEX(Stock!$D$8:$D$69,$H33)) -> 50 | D33: =IF($H33="","",INDEX(Stock!$E$8:$E$69,$H33)) -> 0 | E33: =IF($H33="","",INDEX(Stock!$H$8:$H$69,$H33)) -> 516 | H33: =IFERROR(MATCH(6,Stock!$N$8:$N$69,0),"") -> 11
A34: =IF($H34="","",INDEX(Stock!$A$8:$A$69,$H34)) -> Primus Japan | B34: =IF($H34="","",INDEX(Stock!$B$8:$B$69,$H34)) -> PUD NRN 80/120 | C34: =IF($H34="","",INDEX(Stock!$D$8:$D$69,$H34)) -> 3 | D34: =IF($H34="","",INDEX(Stock!$E$8:$E$69,$H34)) -> 0 | E34: =IF($H34="","",INDEX(Stock!$H$8:$H$69,$H34)) -> 72 | H34: =IFERROR(MATCH(7,Stock!$N$8:$N$69,0),"") -> 12
A35: =IF($H35="","",INDEX(Stock!$A$8:$A$69,$H35)) -> Primus Japan | B35: =IF($H35="","",INDEX(Stock!$B$8:$B$69,$H35)) -> PUD KZN 100/200 | C35: =IF($H35="","",INDEX(Stock!$D$8:$D$69,$H35)) -> 50 | D35: =IF($H35="","",INDEX(Stock!$E$8:$E$69,$H35)) -> 0 | E35: =IF($H35="","",INDEX(Stock!$H$8:$H$69,$H35)) -> 4259 | H35: =IFERROR(MATCH(8,Stock!$N$8:$N$69,0),"") -> 15
A36: =IF($H36="","",INDEX(Stock!$A$8:$A$69,$H36)) -> Primus Japan | B36: =IF($H36="","",INDEX(Stock!$B$8:$B$69,$H36)) -> PUD KZN 200/300 | C36: =IF($H36="","",INDEX(Stock!$D$8:$D$69,$H36)) -> 33 | D36: =IF($H36="","",INDEX(Stock!$E$8:$E$69,$H36)) -> 0 | E36: =IF($H36="","",INDEX(Stock!$H$8:$H$69,$H36)) -> 1113 | H36: =IFERROR(MATCH(9,Stock!$N$8:$N$69,0),"") -> 18
A37: =IF($H37="","",INDEX(Stock!$A$8:$A$69,$H37)) -> Primus Japan | B37: =IF($H37="","",INDEX(Stock!$B$8:$B$69,$H37)) -> PUD PVN 300/500 | C37: =IF($H37="","",INDEX(Stock!$D$8:$D$69,$H37)) -> 156 | D37: =IF($H37="","",INDEX(Stock!$E$8:$E$69,$H37)) -> 0 | E37: =IF($H37="","",INDEX(Stock!$H$8:$H$69,$H37)) -> 577 | H37: =IFERROR(MATCH(10,Stock!$N$8:$N$69,0),"") -> 19
A38: =IF($H38="","",INDEX(Stock!$A$8:$A$69,$H38)) -> Primus Japan | B38: =IF($H38="","",INDEX(Stock!$B$8:$B$69,$H38)) -> PUD KKD 300/500 | C38: =IF($H38="","",INDEX(Stock!$D$8:$D$69,$H38)) -> 596 | D38: =IF($H38="","",INDEX(Stock!$E$8:$E$69,$H38)) -> 0 | E38: =IF($H38="","",INDEX(Stock!$H$8:$H$69,$H38)) -> 1176 | H38: =IFERROR(MATCH(11,Stock!$N$8:$N$69,0),"") -> 20
A39: =IF($H39="","",INDEX(Stock!$A$8:$A$69,$H39)) -> Primus EU | B39: =IF($H39="","",INDEX(Stock!$B$8:$B$69,$H39)) -> BKN | C39: =IF($H39="","",INDEX(Stock!$D$8:$D$69,$H39)) -> 52 | D39: =IF($H39="","",INDEX(Stock!$E$8:$E$69,$H39)) -> 0 | E39: =IF($H39="","",INDEX(Stock!$H$8:$H$69,$H39)) -> 15182 | H39: =IFERROR(MATCH(12,Stock!$N$8:$N$69,0),"") -> 28
A40: =IF($H40="","",INDEX(Stock!$A$8:$A$69,$H40)) -> THT Brand | B40: =IF($H40="","",INDEX(Stock!$B$8:$B$69,$H40)) -> PUD PVN 80/120 | C40: =IF($H40="","",INDEX(Stock!$D$8:$D$69,$H40)) -> 1872 | D40: =IF($H40="","",INDEX(Stock!$E$8:$E$69,$H40)) -> 0 | E40: =IF($H40="","",INDEX(Stock!$H$8:$H$69,$H40)) -> 3261 | H40: =IFERROR(MATCH(13,Stock!$N$8:$N$69,0),"") -> 35
A41: =IF($H41="","",INDEX(Stock!$A$8:$A$69,$H41)) -> THT Brand | B41: =IF($H41="","",INDEX(Stock!$B$8:$B$69,$H41)) -> PUD PVN 100/200 | C41: =IF($H41="","",INDEX(Stock!$D$8:$D$69,$H41)) -> 600 | D41: =IF($H41="","",INDEX(Stock!$E$8:$E$69,$H41)) -> 0 | E41: =IF($H41="","",INDEX(Stock!$H$8:$H$69,$H41)) -> 7655 | H41: =IFERROR(MATCH(14,Stock!$N$8:$N$69,0),"") -> 36
A42: =IF($H42="","",INDEX(Stock!$A$8:$A$69,$H42)) | B42: =IF($H42="","",INDEX(Stock!$B$8:$B$69,$H42)) | C42: =IF($H42="","",INDEX(Stock!$D$8:$D$69,$H42)) | D42: =IF($H42="","",INDEX(Stock!$E$8:$E$69,$H42)) | E42: =IF($H42="","",INDEX(Stock!$H$8:$H$69,$H42)) | H42: =IFERROR(MATCH(15,Stock!$N$8:$N$69,0),"")
A43: =IF($H43="","",INDEX(Stock!$A$8:$A$69,$H43)) | B43: =IF($H43="","",INDEX(Stock!$B$8:$B$69,$H43)) | C43: =IF($H43="","",INDEX(Stock!$D$8:$D$69,$H43)) | D43: =IF($H43="","",INDEX(Stock!$E$8:$E$69,$H43)) | E43: =IF($H43="","",INDEX(Stock!$H$8:$H$69,$H43)) | H43: =IFERROR(MATCH(16,Stock!$N$8:$N$69,0),"")
...
