Workbook
Name Products: OFFSET(Stock!$O$8,0,0,MAX(1,COUNTA(Stock!$A$8:$A$101)),1)
Name CartonList: OFFSET('Carton Stock'!$B$8,0,0,MAX(1,COUNTA('Carton Stock'!$B$8:$B$47)),1)

Sheet Read me
A1: PREMIER EXPORTS INTERNATIONAL
A2: STOCK REGISTER — HOW IT WORKS
B4: Every day, in one minute
B5: 1. On 'Daily Entry' add one row per product that moved — date, product from the
B6: dropdown, and the quantity in that product's own unit.
B7: 2. On 'Stock' set the Statement date and the US$ → ₹ rate for today.
B8: 3. Open 'Daily Report' — it has already rebuilt itself.
B9: 4. File ▸ Export ▸ Create PDF/XPS, "Selected sheet" — that is the directors' copy.
B11: Units: slabs and kilos are not the same thing
B12: Every product carries a Unit and a Kg / Unit on the Stock sheet.
B13: Slab, 2.00 - the shrimp brands — Blue Dolphin, Primus, AMF, THT, China, Deep Sea
B14: Kg, 1.00 - tuna and mackerel, where the balance is already in kilos
B15: Slab, other - squid, cuttlefish and shrimp whole, whose slab weight varies by buyer
B16: Because a slab and a kilo cannot be added together, every total in this workbook is
... B54: Cartons used are rounded up for each product: a part-filled carton is a carton used.

Sheet Stock
A1: PREMIER EXPORTS INTERNATIONAL
A2: STOCK REGISTER — LIVE POSITION
A3: Statement Date | E3: 46324 | F3: ← today; drives the two "today" columns and the Daily Report
A4: $ → ₹ Exchange Rate | E4: 94 | F4: ← rupees per US dollar; converts the per-kilo export rates
A5: Balances are counted in each product's own unit. Only kilos are comparable across products, so every total is taken in kilos.
A7: Brand | B7: Product | C7: Unit | D7: Kg / Unit | E7: Opening Balance | F7: Today's Production | G7: Today's Shipment | H7: Production to Date | I7: Shipment to Date | J7: Closing Balance | K7: Closing Stock (Kg) | L7: Rate / Kg ($) | M7: Stock Value (₹) | O7: Key (do not edit) | P7: Moved today | Q7: Rank | R7: Brand seq | S7: Opening kg | T7: Prod kg today | U7: Ship kg today | V7: Prod kg to date | W7: Ship kg to date | X7: Needs Kg/Unit | Y7: Duplicate key
A8: Blue Dolphin | B8: PD PVN 100/200 | C8: Slab | D8: 2 | E8: 11459 | F8: =IF($A8="","",SUMIFS('Daily Entry'!$C$7:$C$5003,'Daily Entry'!$B$7:$B$5003,$O8,'Daily Entry'!$A$7:$A$5003,$E$3)) | G8: =IF($A8="","",SUMIFS('Daily Entry'!$D$7:$D$5003,'Daily Entry'!$B$7:$B$5003,$O8,'Daily Entry'!$A$7:$A$5003,$E$3)) | H8: =IF($A8="","",SUMIFS('Daily Entry'!$C$7:$C$5003,'Daily Entry'!$B$7:$B$5003,$O8)) | I8: =IF($A8="","",SUMIFS('Daily Entry'!$D$7:$D$5003,'Daily Entry'!$B$7:$B$5003,$O8)) | J8: =IF($A8="","",$E8+$H8-$I8) | K8: =IF(OR($A8="",$D8=""),"",$J8*$D8) | L8: 7.25 | M8: =IF(OR($A8="",$D8="",$L8="",$E$4=""),"",$K8*$L8*$E$4) | O8: =IF($A8="","",$A8&" - "&$B8) | P8: =IF($A8="",0,IF(OR($F8<>0,$G8<>0),1,0)) | Q8: =IF($P8=1,SUM($P$8:$P8),"") | R8: =IF($A8="","",$A8&"#"&COUNTIF($A$8:$A8,$A8)) | S8: =IF(OR($A8="",$D8=""),0,$E8*$D8) | T8: =IF(OR($A8="",$D8=""),0,$F8*$D8) | U8: =IF(OR($A8="",$D8=""),0,$G8*$D8) | V8: =IF(OR($A8="",$D8=""),0,$H8*$D8) | W8: =IF(OR($A8="",$D8=""),0,$I8*$D8) | X8: =IF(AND($A8<>"",$D8=""),1,0) | Y8: =IF($A8="",0,IF(COUNTIF($O$8:$O$101,$O8)>1,1,0))
A9: Blue Dolphin | B9: PD KKD 100/200 | C9: Slab | D9: 2 | E9: 517 | F9: =IF($A9="","",SUMIFS('Daily Entry'!$C$7:$C$5003,'Daily Entry'!$B$7:$B$5003,$O9,'Daily Entry'!$A$7:$A$5003,$E$3)) | G9: =IF($A9="","",SUMIFS('Daily Entry'!$D$7:$D$5003,'Daily Entry'!$B$7:$B$5003,$O9,'Daily Entry'!$A$7:$A$5003,$E$3)) | H9: =IF($A9="","",SUMIFS('Daily Entry'!$C$7:$C$5003,'Daily Entry'!$B$7:$B$5003,$O9)) | I9: =IF($A9="","",SUMIFS('Daily Entry'!$D$7:$D$5003,'Daily Entry'!$B$7:$B$5003,$O9)) | J9: =IF($A9="","",$E9+$H9-$I9) | K9: =IF(OR($A9="",$D9=""),"",$J9*$D9) | L9: 7.25 | M9: =IF(OR($A9="",$D9="",$L9="",$E$4=""),"",$K9*$L9*$E$4) | O9: =IF($A9="","",$A9&" - "&$B9) | P9: =IF($A9="",0,IF(OR($F9<>0,$G9<>0),1,0)) | Q9: =IF($P9=1,SUM($P$8:$P9),"") | R9: =IF($A9="","",$A9&"#"&COUNTIF($A$8:$A9,$A9)) | S9: =IF(OR($A9="",$D9=""),0,$E9*$D9) | T9: =IF(OR($A9="",$D9=""),0,$F9*$D9) | U9: =IF(OR($A9="",$D9=""),0,$G9*$D9) | V9: =IF(OR($A9="",$D9=""),0,$H9*$D9) | W9: =IF(OR($A9="",$D9=""),0,$I9*$D9) | X9: =IF(AND($A9<>"",$D9=""),1,0) | Y9: =IF($A9="",0,IF(COUNTIF($O$8:$O$101,$O9)>1,1,0))
A10: Blue Dolphin | B10: PD PVN 200/300 | C10: Slab | D10: 2 | E10: 2357 | F10: =IF($A10="","",SUMIFS('Daily Entry'!$C$7:$C$5003,'Daily Entry'!$B$7:$B$5003,$O10,'Daily Entry'!$A$7:$A$5003,$E$3)) | G10: =IF($A10="","",SUMIFS('Daily Entry'!$D$7:$D$5003,'Daily Entry'!$B$7:$B$5003,$O10,'Daily Entry'!$A$7:$A$5003,$E$3)) | H10: =IF($A10="","",SUMIFS('Daily Entry'!$C$7:$C$5003,'Daily Entry'!$B$7:$B$5003,$O10)) | I10: =IF($A10="","",SUMIFS('Daily Entry'!$D$7:$D$5003,'Daily Entry'!$B$7:$B$5003,$O10)) | J10: =IF($A10="","",$E10+$H10-$I10) | K10: =IF(OR($A10="",$D10=""),"",$J10*$D10) | L10: 6.65 | M10: =IF(OR($A10="",$D10="",$L10="",$E$4=""),"",$K10*$L10*$E$4) | O10: =IF($A10="","",$A10&" - "&$B10) | P10: =IF($A10="",0,IF(OR($F10<>0,$G10<>0),1,0)) | Q10: =IF($P10=1,SUM($P$8:$P10),"") | R10: =IF($A10="","",$A10&"#"&COUNTIF($A$8:$A10,$A10)) | S10: =IF(OR($A10="",$D10=""),0,$E10*$D10) | T10: =IF(OR($A10="",$D10=""),0,$F10*$D10) | U10: =IF(OR($A10="",$D10=""),0,$G10*$D10) | V10: =IF(OR($A10="",$D10=""),0,$H10*$D10) | W10: =IF(OR($A10="",$D10=""),0,$I10*$D10) | X10: =IF(AND($A10<>"",$D10=""),1,0) | Y10: =IF($A10="",0,IF(COUNTIF($O$8:$O$101,$O10)>1,1,0))
A11: Blue Dolphin | B11: PD KKD 200/300 | C11: Slab | D11: 2 | E11: 0 | F11: =IF($A11="","",SUMIFS('Daily Entry'!$C$7:$C$5003,'Daily Entry'!$B$7:$B$5003,$O11,'Daily Entry'!$A$7:$A$5003,$E$3)) | G11: =IF($A11="","",SUMIFS('Daily Entry'!$D$7:$D$5003,'Daily Entry'!$B$7:$B$5003,$O11,'Daily Entry'!$A$7:$A$5003,$E$3)) | H11: =IF($A11="","",SUMIFS('Daily Entry'!$C$7:$C$5003,'Daily Entry'!$B$7:$B$5003,$O11)) | I11: =IF($A11="","",SUMIFS('Daily Entry'!$D$7:$D$5003,'Daily Entry'!$B$7:$B$5003,$O11)) | J11: =IF($A11="","",$E11+$H11-$I11) | K11: =IF(OR($A11="",$D11=""),"",$J11*$D11) | L11: 6.65 | M11: =IF(OR($A11="",$D11="",$L11="",$E$4=""),"",$K11*$L11*$E$4) | O11: =IF($A11="","",$A11&" - "&$B11) | P11: =IF($A11="",0,IF(OR($F11<>0,$G11<>0),1,0)) | Q11: =IF($P11=1,SUM($P$8:$P11),"") | R11: =IF($A11="","",$A11&"#"&COUNTIF($A$8:$A11,$A11)) | S11: =IF(OR($A11="",$D11=""),0,$E11*$D11) | T11: =IF(OR($A11="",$D11=""),0,$F11*$D11) | U11: =IF(OR($A11="",$D11=""),0,$G11*$D11) | V11: =IF(OR($A11="",$D11=""),0,$H11*$D11) | W11: =IF(OR($A11="",$D11=""),0,$I11*$D11) | X11: =IF(AND($A11<>"",$D11=""),1,0) | Y11: =IF($A11="",0,IF(COUNTIF($O$8:$O$101,$O11)>1,1,0))
A12: Blue Dolphin | B12: PUD PVN 200/300 | C12: Slab | D12: 2 | E12: 2262 | F12: =IF($A12="","",SUMIFS('Daily Entry'!$C$7:$C$5003,'Daily Entry'!$B$7:$B$5003,$O12,'Daily Entry'!$A$7:$A$5003,$E$3)) | G12: =IF($A12="","",SUMIFS('Daily Entry'!$D$7:$D$5003,'Daily Entry'!$B$7:$B$5003,$O12,'Daily Entry'!$A$7:$A$5003,$E$3)) | H12: =IF($A12="","",SUMIFS('Daily Entry'!$C$7:$C$5003,'Daily Entry'!$B$7:$B$5003,$O12)) | I12: =IF($A12="","",SUMIFS('Daily Entry'!$D$7:$D$5003,'Daily Entry'!$B$7:$B$5003,$O12)) | J12: =IF($A12="","",$E12+$H12-$I12) | K12: =IF(OR($A12="",$D12=""),"",$J12*$D12) | L12: 6.3 | M12: =IF(OR($A12="",$D12="",$L12="",$E$4=""),"",$K12*$L12*$E$4) | O12: =IF($A12="","",$A12&" - "&$B12) | P12: =IF($A12="",0,IF(OR($F12<>0,$G12<>0),1,0)) | Q12: =IF($P12=1,SUM($P$8:$P12),"") | R12: =IF($A12="","",$A12&"#"&COUNTIF($A$8:$A12,$A12)) | S12: =IF(OR($A12="",$D12=""),0,$E12*$D12) | T12: =IF(OR($A12="",$D12=""),0,$F12*$D12) | U12: =IF(OR($A12="",$D12=""),0,$G12*$D12) | V12: =IF(OR($A12="",$D12=""),0,$H12*$D12) | W12: =IF(OR($A12="",$D12=""),0,$I12*$D12) | X12: =IF(AND($A12<>"",$D12=""),1,0) | Y12: =IF($A12="",0,IF(COUNTIF($O$8:$O$101,$O12)>1,1,0))
A13: Blue Dolphin | B13: PUD KKD 200/300 | C13: Slab | D13: 2 | E13: 2835 | F13: =IF($A13="","",SUMIFS('Daily Entry'!$C$7:$C$5003,'Daily Entry'!$B$7:$B$5003,$O13,'Daily Entry'!$A$7:$A$5003,$E$3)) | G13: =IF($A13="","",SUMIFS('Daily Entry'!$D$7:$D$5003,'Daily Entry'!$B$7:$B$5003,$O13,'Daily Entry'!$A$7:$A$5003,$E$3)) | H13: =IF($A13="","",SUMIFS('Daily Entry'!$C$7:$C$5003,'Daily Entry'!$B$7:$B$5003,$O13)) | I13: =IF($A13="","",SUMIFS('Daily Entry'!$D$7:$D$5003,'Daily Entry'!$B$7:$B$5003,$O13)) | J13: =IF($A13="","",$E13+$H13-$I13) | K13: =IF(OR($A13="",$D13=""),"",$J13*$D13) | L13: 6.3 | M13: =IF(OR($A13="",$D13="",$L13="",$E$4=""),"",$K13*$L13*$E$4) | O13: =IF($A13="","",$A13&" - "&$B13) | P13: =IF($A13="",0,IF(OR($F13<>0,$G13<>0),1,0)) | Q13: =IF($P13=1,SUM($P$8:$P13),"") | R13: =IF($A13="","",$A13&"#"&COUNTIF($A$8:$A13,$A13)) | S13: =IF(OR($A13="",$D13=""),0,$E13*$D13) | T13: =IF(OR($A13="",$D13=""),0,$F13*$D13) | U13: =IF(OR($A13="",$D13=""),0,$G13*$D13) | V13: =IF(OR($A13="",$D13=""),0,$H13*$D13) | W13: =IF(OR($A13="",$D13=""),0,$I13*$D13) | X13: =IF(AND($A13<>"",$D13=""),1,0) | Y13: =IF($A13="",0,IF(COUNTIF($O$8:$O$101,$O13)>1,1,0))
A14: Blue Dolphin | B14: PUD PVN 300/500 | C14: Slab | D14: 2 | E14: 1673 | F14: =IF($A14="","",SUMIFS('Daily Entry'!$C$7:$C$5003,'Daily Entry'!$B$7:$B$5003,$O14,'Daily Entry'!$A$7:$A$5003,$E$3)) | G14: =IF($A14="","",SUMIFS('Daily Entry'!$D$7:$D$5003,'Daily Entry'!$B$7:$B$5003,$O14,'Daily Entry'!$A$7:$A$5003,$E$3)) | H14: =IF($A14="","",SUMIFS('Daily Entry'!$C$7:$C$5003,'Daily Entry'!$B$7:$B$5003,$O14)) | I14: =IF($A14="","",SUMIFS('Daily Entry'!$D$7:$D$5003,'Daily Entry'!$B$7:$B$5003,$O14)) | J14: =IF($A14="","",$E14+$H14-$I14) | K14: =IF(OR($A14="",$D14=""),"",$J14*$D14) | L14: 6.25 | M14: =IF(OR($A14="",$D14="",$L14="",$E$4=""),"",$K14*$L14*$E$4) | O14: =IF($A14="","",$A14&" - "&$B14) | P14: =IF($A14="",0,IF(OR($F14<>0,$G14<>0),1,0)) | Q14: =IF($P14=1,SUM($P$8:$P14),"") | R14: =IF($A14="","",$A14&"#"&COUNTIF($A$8:$A14,$A14)) | S14: =IF(OR($A14="",$D14=""),0,$E14*$D14) | T14: =IF(OR($A14="",$D14=""),0,$F14*$D14) | U14: =IF(OR($A14="",$D14=""),0,$G14*$D14) | V14: =IF(OR($A14="",$D14=""),0,$H14*$D14) | W14: =IF(OR($A14="",$D14=""),0,$I14*$D14) | X14: =IF(AND($A14<>"",$D14=""),1,0) | Y14: =IF($A14="",0,IF(COUNTIF($O$8:$O$101,$O14)>1,1,0))
A15: Blue Dolphin | B15: PUD KKD 300/500 | C15: Slab | D15: 2 | E15: 7542 | F15: =IF($A15="","",SUMIFS('Daily Entry'!$C$7:$C$5003,'Daily Entry'!$B$7:$B$5003,$O15,'Daily Entry'!$A$7:$A$5003,$E$3)) | G15: =IF($A15="","",SUMIFS('Daily Entry'!$D$7:$D$5003,'Daily Entry'!$B$7:$B$5003,$O15,'Daily Entry'!$A$7:$A$5003,$E$3)) | H15: =IF($A15="","",SUMIFS('Daily Entry'!$C$7:$C$5003,'Daily Entry'!$B$7:$B$5003,$O15)) | I15: =IF($A15="","",SUMIFS('Daily Entry'!$D$7:$D$5003,'Daily Entry'!$B$7:$B$5003,$O15)) | J15: =IF($A15="","",$E15+$H15-$I15) | K15: =IF(OR($A15="",$D15=""),"",$J15*$D15) | L15: 6.25 | M15: =IF(OR($A15="",$D15="",$L15="",$E$4=""),"",$K15*$L15*$E$4) | O15: =IF($A15="","",$A15&" - "&$B15) | P15: =IF($A15="",0,IF(OR($F15<>0,$G15<>0),1,0)) | Q15: =IF($P15=1,SUM($P$8:$P15),"") | R15: =IF($A15="","",$A15&"#"&COUNTIF($A$8:$A15,$A15)) | S15: =IF(OR($A15="",$D15=""),0,$E15*$D15) | T15: =IF(OR($A15="",$D15=""),0,$F15*$D15) | U15: =IF(OR($A15="",$D15=""),0,$G15*$D15) | V15: =IF(OR($A15="",$D15=""),0,$H15*$D15) | W15: =IF(OR($A15="",$D15=""),0,$I15*$D15) | X15: =IF(AND($A15<>"",$D15=""),1,0) | Y15: =IF($A15="",0,IF(COUNTIF($O$8:$O$101,$O15)>1,1,0))
A16: Primus Japan | B16: PD PVN 100/200 | C16: Slab | D16: 2 | E16: 0 | F16: =IF($A16="","",SUMIFS('Daily Entry'!$C$7:$C$5003,'Daily Entry'!$B$7:$B$5003,$O16,'Daily Entry'!$A$7:$A$5003,$E$3)) | G16: =IF($A16="","",SUMIFS('Daily Entry'!$D$7:$D$5003,'Daily Entry'!$B$7:$B$5003,$O16,'Daily Entry'!$A$7:$A$5003,$E$3)) | H16: =IF($A16="","",SUMIFS('Daily Entry'!$C$7:$C$5003,'Daily Entry'!$B$7:$B$5003,$O16)) | I16: =IF($A16="","",SUMIFS('Daily Entry'!$D$7:$D$5003,'Daily Entry'!$B$7:$B$5003,$O16)) | J16: =IF($A16="","",$E16+$H16-$I16) | K16: =IF(OR($A16="",$D16=""),"",$J16*$D16) | L16: 7 | M16: =IF(OR($A16="",$D16="",$L16="",$E$4=""),"",$K16*$L16*$E$4) | O16: =IF($A16="","",$A16&" - "&$B16) | P16: =IF($A16="",0,IF(OR($F16<>0,$G16<>0),1,0)) | Q16: =IF($P16=1,SUM($P$8:$P16),"") | R16: =IF($A16="","",$A16&"#"&COUNTIF($A$8:$A16,$A16)) | S16: =IF(OR($A16="",$D16=""),0,$E16*$D16) | T16: =IF(OR($A16="",$D16=""),0,$F16*$D16) | U16: =IF(OR($A16="",$D16=""),0,$G16*$D16) | V16: =IF(OR($A16="",$D16=""),0,$H16*$D16) | W16: =IF(OR($A16="",$D16=""),0,$I16*$D16) | X16: =IF(AND($A16<>"",$D16=""),1,0) | Y16: =IF($A16="",0,IF(COUNTIF($O$8:$O$101,$O16)>1,1,0))
A17: Primus Japan | B17: PD KKD 100/200 | C17: Slab | D17: 2 | E17: 0 | F17: =IF($A17="","",SUMIFS('Daily Entry'!$C$7:$C$5003,'Daily Entry'!$B$7:$B$5003,$O17,'Daily Entry'!$A$7:$A$5003,$E$3)) | G17: =IF($A17="","",SUMIFS('Daily Entry'!$D$7:$D$5003,'Daily Entry'!$B$7:$B$5003,$O17,'Daily Entry'!$A$7:$A$5003,$E$3)) | H17: =IF($A17="","",SUMIFS('Daily Entry'!$C$7:$C$5003,'Daily Entry'!$B$7:$B$5003,$O17)) | I17: =IF($A17="","",SUMIFS('Daily Entry'!$D$7:$D$5003,'Daily Entry'!$B$7:$B$5003,$O17)) | J17: =IF($A17="","",$E17+$H17-$I17) | K17: =IF(OR($A17="",$D17=""),"",$J17*$D17) | M17: =IF(OR($A17="",$D17="",$L17="",$E$4=""),"",$K17*$L17*$E$4) | O17: =IF($A17="","",$A17&" - "&$B17) | P17: =IF($A17="",0,IF(OR($F17<>0,$G17<>0),1,0)) | Q17: =IF($P17=1,SUM($P$8:$P17),"") | R17: =IF($A17="","",$A17&"#"&COUNTIF($A$8:$A17,$A17)) | S17: =IF(OR($A17="",$D17=""),0,$E17*$D17) | T17: =IF(OR($A17="",$D17=""),0,$F17*$D17) | U17: =IF(OR($A17="",$D17=""),0,$G17*$D17) | V17: =IF(OR($A17="",$D17=""),0,$H17*$D17) | W17: =IF(OR($A17="",$D17=""),0,$I17*$D17) | X17: =IF(AND($A17<>"",$D17=""),1,0) | Y17: =IF($A17="",0,IF(COUNTIF($O$8:$O$101,$O17)>1,1,0))
A18: Primus Japan | B18: PD PVN 200/300 | C18: Slab | D18: 2 | E18: 0 | F18: =IF($A18="","",SUMIFS('Daily Entry'!$C$7:$C$5003,'Daily Entry'!$B$7:$B$5003,$O18,'Daily Entry'!$A$7:$A$5003,$E$3)) | G18: =IF($A18="","",SUMIFS('Daily Entry'!$D$7:$D$5003,'Daily Entry'!$B$7:$B$5003,$O18,'Daily Entry'!$A$7:$A$5003,$E$3)) | H18: =IF($A18="","",SUMIFS('Daily Entry'!$C$7:$C$5003,'Daily Entry'!$B$7:$B$5003,$O18)) | I18: =IF($A18="","",SUMIFS('Daily Entry'!$D$7:$D$5003,'Daily Entry'!$B$7:$B$5003,$O18)) | J18: =IF($A18="","",$E18+$H18-$I18) | K18: =IF(OR($A18="",$D18=""),"",$J18*$D18) | M18: =IF(OR($A18="",$D18="",$L18="",$E$4=""),"",$K18*$L18*$E$4) | O18: =IF($A18="","",$A18&" - "&$B18) | P18: =IF($A18="",0,IF(OR($F18<>0,$G18<>0),1,0)) | Q18: =IF($P18=1,SUM($P$8:$P18),"") | R18: =IF($A18="","",$A18&"#"&COUNTIF($A$8:$A18,$A18)) | S18: =IF(OR($A18="",$D18=""),0,$E18*$D18) | T18: =IF(OR($A18="",$D18=""),0,$F18*$D18) | U18: =IF(OR($A18="",$D18=""),0,$G18*$D18) | V18: =IF(OR($A18="",$D18=""),0,$H18*$D18) | W18: =IF(OR($A18="",$D18=""),0,$I18*$D18) | X18: =IF(AND($A18<>"",$D18=""),1,0) | Y18: =IF($A18="",0,IF(COUNTIF($O$8:$O$101,$O18)>1,1,0))
A19: Primus Japan | B19: PD KKD 200/300 | C19: Slab | D19: 2 | E19: 0 | F19: =IF($A19="","",SUMIFS('Daily Entry'!$C$7:$C$5003,'Daily Entry'!$B$7:$B$5003,$O19,'Daily Entry'!$A$7:$A$5003,$E$3)) | G19: =IF($A19="","",SUMIFS('Daily Entry'!$D$7:$D$5003,'Daily Entry'!$B$7:$B$5003,$O19,'Daily Entry'!$A$7:$A$5003,$E$3)) | H19: =IF($A19="","",SUMIFS('Daily Entry'!$C$7:$C$5003,'Daily Entry'!$B$7:$B$5003,$O19)) | I19: =IF($A19="","",SUMIFS('Daily Entry'!$D$7:$D$5003,'Daily Entry'!$B$7:$B$5003,$O19)) | J19: =IF($A19="","",$E19+$H19-$I19) | K19: =IF(OR($A19="",$D19=""),"",$J19*$D19) | M19: =IF(OR($A19="",$D19="",$L19="",$E$4=""),"",$K19*$L19*$E$4) | O19: =IF($A19="","",$A19&" - "&$B19) | P19: =IF($A19="",0,IF(OR($F19<>0,$G19<>0),1,0)) | Q19: =IF($P19=1,SUM($P$8:$P19),"") | R19: =IF($A19="","",$A19&"#"&COUNTIF($A$8:$A19,$A19)) | S19: =IF(OR($A19="",$D19=""),0,$E19*$D19) | T19: =IF(OR($A19="",$D19=""),0,$F19*$D19) | U19: =IF(OR($A19="",$D19=""),0,$G19*$D19) | V19: =IF(OR($A19="",$D19=""),0,$H19*$D19) | W19: =IF(OR($A19="",$D19=""),0,$I19*$D19) | X19: =IF(AND($A19<>"",$D19=""),1,0) | Y19: =IF($A19="",0,IF(COUNTIF($O$8:$O$101,$O19)>1,1,0))
A20: Primus Japan | B20: PUD KZN 40/60 | C20: Slab | D20: 2 | E20: 64 | F20: =IF($A20="","",SUMIFS('Daily Entry'!$C$7:$C$5003,'Daily Entry'!$B$7:$B$5003,$O20,'Daily Entry'!$A$7:$A$5003,$E$3)) | G20: =IF($A20="","",SUMIFS('Daily Entry'!$D$7:$D$5003,'Daily Entry'!$B$7:$B$5003,$O20,'Daily Entry'!$A$7:$A$5003,$E$3)) | H20: =IF($A20="","",SUMIFS('Daily Entry'!$C$7:$C$5003,'Daily Entry'!$B$7:$B$5003,$O20)) | I20: =IF($A20="","",SUMIFS('Daily Entry'!$D$7:$D$5003,'Daily Entry'!$B$7:$B$5003,$O20)) | J20: =IF($A20="","",$E20+$H20-$I20) | K20: =IF(OR($A20="",$D20=""),"",$J20*$D20) | L20: 6.5 | M20: =IF(OR($A20="",$D20="",$L20="",$E$4=""),"",$K20*$L20*$E$4) | O20: =IF($A20="","",$A20&" - "&$B20) | P20: =IF($A20="",0,IF(OR($F20<>0,$G20<>0),1,0)) | Q20: =IF($P20=1,SUM($P$8:$P20),"") | R20: =IF($A20="","",$A20&"#"&COUNTIF($A$8:$A20,$A20)) | S20: =IF(OR($A20="",$D20=""),0,$E20*$D20) | T20: =IF(OR($A20="",$D20=""),0,$F20*$D20) | U20: =IF(OR($A20="",$D20=""),0,$G20*$D20) | V20: =IF(OR($A20="",$D20=""),0,$H20*$D20) | W20: =IF(OR($A20="",$D20=""),0,$I20*$D20) | X20: =IF(AND($A20<>"",$D20=""),1,0) | Y20: =IF($A20="",0,IF(COUNTIF($O$8:$O$101,$O20)>1,1,0))
A21: Primus Japan | B21: PUD KZN 60/80 | C21: Slab | D21: 2 | E21: 191 | F21: =IF($A21="","",SUMIFS('Daily Entry'!$C$7:$C$5003,'Daily Entry'!$B$7:$B$5003,$O21,'Daily Entry'!$A$7:$A$5003,$E$3)) | G21: =IF($A21="","",SUMIFS('Daily Entry'!$D$7:$D$5003,'Daily Entry'!$B$7:$B$5003,$O21,'Daily Entry'!$A$7:$A$5003,$E$3)) | H21: =IF($A21="","",SUMIFS('Daily Entry'!$C$7:$C$5003,'Daily Entry'!$B$7:$B$5003,$O21)) | I21: =IF($A21="","",SUMIFS('Daily Entry'!$D$7:$D$5003,'Daily Entry'!$B$7:$B$5003,$O21)) | J21: =IF($A21="","",$E21+$H21-$I21) | K21: =IF(OR($A21="",$D21=""),"",$J21*$D21) | L21: 6.5 | M21: =IF(OR($A21="",$D21="",$L21="",$E$4=""),"",$K21*$L21*$E$4) | O21: =IF($A21="","",$A21&" - "&$B21) | P21: =IF($A21="",0,IF(OR($F21<>0,$G21<>0),1,0)) | Q21: =IF($P21=1,SUM($P$8:$P21),"") | R21: =IF($A21="","",$A21&"#"&COUNTIF($A$8:$A21,$A21)) | S21: =IF(OR($A21="",$D21=""),0,$E21*$D21) | T21: =IF(OR($A21="",$D21=""),0,$F21*$D21) | U21: =IF(OR($A21="",$D21=""),0,$G21*$D21) | V21: =IF(OR($A21="",$D21=""),0,$H21*$D21) | W21: =IF(OR($A21="",$D21=""),0,$I21*$D21) | X21: =IF(AND($A21<>"",$D21=""),1,0) | Y21: =IF($A21="",0,IF(COUNTIF($O$8:$O$101,$O21)>1,1,0))
A22: Primus Japan | B22: PUD PVN 80/120 | C22: Slab | D22: 2 | E22: 16849 | F22: =IF($A22="","",SUMIFS('Daily Entry'!$C$7:$C$5003,'Daily Entry'!$B$7:$B$5003,$O22,'Daily Entry'!$A$7:$A$5003,$E$3)) | G22: =IF($A22="","",SUMIFS('Daily Entry'!$D$7:$D$5003,'Daily Entry'!$B$7:$B$5003,$O22,'Daily Entry'!$A$7:$A$5003,$E$3)) | H22: =IF($A22="","",SUMIFS('Daily Entry'!$C$7:$C$5003,'Daily Entry'!$B$7:$B$5003,$O22)) | I22: =IF($A22="","",SUMIFS('Daily Entry'!$D$7:$D$5003,'Daily Entry'!$B$7:$B$5003,$O22)) | J22: =IF($A22="","",$E22+$H22-$I22) | K22: =IF(OR($A22="",$D22=""),"",$J22*$D22) | L22: 6.5 | M22: =IF(OR($A22="",$D22="",$L22="",$E$4=""),"",$K22*$L22*$E$4) | O22: =IF($A22="","",$A22&" - "&$B22) | P22: =IF($A22="",0,IF(OR($F22<>0,$G22<>0),1,0)) | Q22: =IF($P22=1,SUM($P$8:$P22),"") | R22: =IF($A22="","",$A22&"#"&COUNTIF($A$8:$A22,$A22)) | S22: =IF(OR($A22="",$D22=""),0,$E22*$D22) | T22: =IF(OR($A22="",$D22=""),0,$F22*$D22) | U22: =IF(OR($A22="",$D22=""),0,$G22*$D22) | V22: =IF(OR($A22="",$D22=""),0,$H22*$D22) | W22: =IF(OR($A22="",$D22=""),0,$I22*$D22) | X22: =IF(AND($A22<>"",$D22=""),1,0) | Y22: =IF($A22="",0,IF(COUNTIF($O$8:$O$101,$O22)>1,1,0))
A23: Primus Japan | B23: PUD KZN 80/120 | C23: Slab | D23: 2 | E23: 466 | F23: =IF($A23="","",SUMIFS('Daily Entry'!$C$7:$C$5003,'Daily Entry'!$B$7:$B$5003,$O23,'Daily Entry'!$A$7:$A$5003,$E$3)) | G23: =IF($A23="","",SUMIFS('Daily Entry'!$D$7:$D$5003,'Daily Entry'!$B$7:$B$5003,$O23,'Daily Entry'!$A$7:$A$5003,$E$3)) | H23: =IF($A23="","",SUMIFS('Daily Entry'!$C$7:$C$5003,'Daily Entry'!$B$7:$B$5003,$O23)) | I23: =IF($A23="","",SUMIFS('Daily Entry'!$D$7:$D$5003,'Daily Entry'!$B$7:$B$5003,$O23)) | J23: =IF($A23="","",$E23+$H23-$I23) | K23: =IF(OR($A23="",$D23=""),"",$J23*$D23) | L23: 6.5 | M23: =IF(OR($A23="",$D23="",$L23="",$E$4=""),"",$K23*$L23*$E$4) | O23: =IF($A23="","",$A23&" - "&$B23) | P23: =IF($A23="",0,IF(OR($F23<>0,$G23<>0),1,0)) | Q23: =IF($P23=1,SUM($P$8:$P23),"") | R23: =IF($A23="","",$A23&"#"&COUNTIF($A$8:$A23,$A23)) | S23: =IF(OR($A23="",$D23=""),0,$E23*$D23) | T23: =IF(OR($A23="",$D23=""),0,$F23*$D23) | U23: =IF(OR($A23="",$D23=""),0,$G23*$D23) | V23: =IF(OR($A23="",$D23=""),0,$H23*$D23) | W23: =IF(OR($A23="",$D23=""),0,$I23*$D23) | X23: =IF(AND($A23<>"",$D23=""),1,0) | Y23: =IF($A23="",0,IF(COUNTIF($O$8:$O$101,$O23)>1,1,0))
A24: Primus Japan | B24: PUD NRN 80/120 | C24: Slab | D24: 2 | E24: 69 | F24: =IF($A24="","",SUMIFS('Daily Entry'!$C$7:$C$5003,'Daily Entry'!$B$7:$B$5003,$O24,'Daily Entry'!$A$7:$A$5003,$E$3)) | G24: =IF($A24="","",SUMIFS('Daily Entry'!$D$7:$D$5003,'Daily Entry'!$B$7:$B$5003,$O24,'Daily Entry'!$A$7:$A$5003,$E$3)) | H24: =IF($A24="","",SUMIFS('Daily Entry'!$C$7:$C$5003,'Daily Entry'!$B$7:$B$5003,$O24)) | I24: =IF($A24="","",SUMIFS('Daily Entry'!$D$7:$D$5003,'Daily Entry'!$B$7:$B$5003,$O24)) | J24: =IF($A24="","",$E24+$H24-$I24) | K24: =IF(OR($A24="",$D24=""),"",$J24*$D24) | L24: 6.5 | M24: =IF(OR($A24="",$D24="",$L24="",$E$4=""),"",$K24*$L24*$E$4) | O24: =IF($A24="","",$A24&" - "&$B24) | P24: =IF($A24="",0,IF(OR($F24<>0,$G24<>0),1,0)) | Q24: =IF($P24=1,SUM($P$8:$P24),"") | R24: =IF($A24="","",$A24&"#"&COUNTIF($A$8:$A24,$A24)) | S24: =IF(OR($A24="",$D24=""),0,$E24*$D24) | T24: =IF(OR($A24="",$D24=""),0,$F24*$D24) | U24: =IF(OR($A24="",$D24=""),0,$G24*$D24) | V24: =IF(OR($A24="",$D24=""),0,$H24*$D24) | W24: =IF(OR($A24="",$D24=""),0,$I24*$D24) | X24: =IF(AND($A24<>"",$D24=""),1,0) | Y24: =IF($A24="",0,IF(COUNTIF($O$8:$O$101,$O24)>1,1,0))
A25: Primus Japan | B25: PUD PVN 100/200 | C25: Slab | D25: 2 | E25: 2617 | F25: =IF($A25="","",SUMIFS('Daily Entry'!$C$7:$C$5003,'Daily Entry'!$B$7:$B$5003,$O25,'Daily Entry'!$A$7:$A$5003,$E$3)) | G25: =IF($A25="","",SUMIFS('Daily Entry'!$D$7:$D$5003,'Daily Entry'!$B$7:$B$5003,$O25,'Daily Entry'!$A$7:$A$5003,$E$3)) | H25: =IF($A25="","",SUMIFS('Daily Entry'!$C$7:$C$5003,'Daily Entry'!$B$7:$B$5003,$O25)) | I25: =IF($A25="","",SUMIFS('Daily Entry'!$D$7:$D$5003,'Daily Entry'!$B$7:$B$5003,$O25)) | J25: =IF($A25="","",$E25+$H25-$I25) | K25: =IF(OR($A25="",$D25=""),"",$J25*$D25) | L25: 6.5 | M25: =IF(OR($A25="",$D25="",$L25="",$E$4=""),"",$K25*$L25*$E$4) | O25: =IF($A25="","",$A25&" - "&$B25) | P25: =IF($A25="",0,IF(OR($F25<>0,$G25<>0),1,0)) | Q25: =IF($P25=1,SUM($P$8:$P25),"") | R25: =IF($A25="","",$A25&"#"&COUNTIF($A$8:$A25,$A25)) | S25: =IF(OR($A25="",$D25=""),0,$E25*$D25) | T25: =IF(OR($A25="",$D25=""),0,$F25*$D25) | U25: =IF(OR($A25="",$D25=""),0,$G25*$D25) | V25: =IF(OR($A25="",$D25=""),0,$H25*$D25) | W25: =IF(OR($A25="",$D25=""),0,$I25*$D25) | X25: =IF(AND($A25<>"",$D25=""),1,0) | Y25: =IF($A25="",0,IF(COUNTIF($O$8:$O$101,$O25)>1,1,0))
A26: Primus Japan | B26: PUD KKD 100/200 | C26: Slab | D26: 2 | E26: 0 | F26: =IF($A26="","",SUMIFS('Daily Entry'!$C$7:$C$5003,'Daily Entry'!$B$7:$B$5003,$O26,'Daily Entry'!$A$7:$A$5003,$E$3)) | G26: =IF($A26="","",SUMIFS('Daily Entry'!$D$7:$D$5003,'Daily Entry'!$B$7:$B$5003,$O26,'Daily Entry'!$A$7:$A$5003,$E$3)) | H26: =IF($A26="","",SUMIFS('Daily Entry'!$C$7:$C$5003,'Daily Entry'!$B$7:$B$5003,$O26)) | I26: =IF($A26="","",SUMIFS('Daily Entry'!$D$7:$D$5003,'Daily Entry'!$B$7:$B$5003,$O26)) | J26: =IF($A26="","",$E26+$H26-$I26) | K26: =IF(OR($A26="",$D26=""),"",$J26*$D26) | M26: =IF(OR($A26="",$D26="",$L26="",$E$4=""),"",$K26*$L26*$E$4) | O26: =IF($A26="","",$A26&" - "&$B26) | P26: =IF($A26="",0,IF(OR($F26<>0,$G26<>0),1,0)) | Q26: =IF($P26=1,SUM($P$8:$P26),"") | R26: =IF($A26="","",$A26&"#"&COUNTIF($A$8:$A26,$A26)) | S26: =IF(OR($A26="",$D26=""),0,$E26*$D26) | T26: =IF(OR($A26="",$D26=""),0,$F26*$D26) | U26: =IF(OR($A26="",$D26=""),0,$G26*$D26) | V26: =IF(OR($A26="",$D26=""),0,$H26*$D26) | W26: =IF(OR($A26="",$D26=""),0,$I26*$D26) | X26: =IF(AND($A26<>"",$D26=""),1,0) | Y26: =IF($A26="",0,IF(COUNTIF($O$8:$O$101,$O26)>1,1,0))
A27: Primus Japan | B27: PUD KZN 100/200 | C27: Slab | D27: 2 | E27: 4209 | F27: =IF($A27="","",SUMIFS('Daily Entry'!$C$7:$C$5003,'Daily Entry'!$B$7:$B$5003,$O27,'Daily Entry'!$A$7:$A$5003,$E$3)) | G27: =IF($A27="","",SUMIFS('Daily Entry'!$D$7:$D$5003,'Daily Entry'!$B$7:$B$5003,$O27,'Daily Entry'!$A$7:$A$5003,$E$3)) | H27: =IF($A27="","",SUMIFS('Daily Entry'!$C$7:$C$5003,'Daily Entry'!$B$7:$B$5003,$O27)) | I27: =IF($A27="","",SUMIFS('Daily Entry'!$D$7:$D$5003,'Daily Entry'!$B$7:$B$5003,$O27)) | J27: =IF($A27="","",$E27+$H27-$I27) | K27: =IF(OR($A27="",$D27=""),"",$J27*$D27) | L27: 5.5 | M27: =IF(OR($A27="",$D27="",$L27="",$E$4=""),"",$K27*$L27*$E$4) | O27: =IF($A27="","",$A27&" - "&$B27) | P27: =IF($A27="",0,IF(OR($F27<>0,$G27<>0),1,0)) | Q27: =IF($P27=1,SUM($P$8:$P27),"") | R27: =IF($A27="","",$A27&"#"&COUNTIF($A$8:$A27,$A27)) | S27: =IF(OR($A27="",$D27=""),0,$E27*$D27) | T27: =IF(OR($A27="",$D27=""),0,$F27*$D27) | U27: =IF(OR($A27="",$D27=""),0,$G27*$D27) | V27: =IF(OR($A27="",$D27=""),0,$H27*$D27) | W27: =IF(OR($A27="",$D27=""),0,$I27*$D27) | X27: =IF(AND($A27<>"",$D27=""),1,0) | Y27: =IF($A27="",0,IF(COUNTIF($O$8:$O$101,$O27)>1,1,0))
A28: Primus Japan | B28: PUD NRN 100/200 | C28: Slab | D28: 2 | E28: 13 | F28: =IF($A28="","",SUMIFS('Daily Entry'!$C$7:$C$5003,'Daily Entry'!$B$7:$B$5003,$O28,'Daily Entry'!$A$7:$A$5003,$E$3)) | G28: =IF($A28="","",SUMIFS('Daily Entry'!$D$7:$D$5003,'Daily Entry'!$B$7:$B$5003,$O28,'Daily Entry'!$A$7:$A$5003,$E$3)) | H28: =IF($A28="","",SUMIFS('Daily Entry'!$C$7:$C$5003,'Daily Entry'!$B$7:$B$5003,$O28)) | I28: =IF($A28="","",SUMIFS('Daily Entry'!$D$7:$D$5003,'Daily Entry'!$B$7:$B$5003,$O28)) | J28: =IF($A28="","",$E28+$H28-$I28) | K28: =IF(OR($A28="",$D28=""),"",$J28*$D28) | L28: 5.5 | M28: =IF(OR($A28="",$D28="",$L28="",$E$4=""),"",$K28*$L28*$E$4) | O28: =IF($A28="","",$A28&" - "&$B28) | P28: =IF($A28="",0,IF(OR($F28<>0,$G28<>0),1,0)) | Q28: =IF($P28=1,SUM($P$8:$P28),"") | R28: =IF($A28="","",$A28&"#"&COUNTIF($A$8:$A28,$A28)) | S28: =IF(OR($A28="",$D28=""),0,$E28*$D28) | T28: =IF(OR($A28="",$D28=""),0,$F28*$D28) | U28: =IF(OR($A28="",$D28=""),0,$G28*$D28) | V28: =IF(OR($A28="",$D28=""),0,$H28*$D28) | W28: =IF(OR($A28="",$D28=""),0,$I28*$D28) | X28: =IF(AND($A28<>"",$D28=""),1,0) | Y28: =IF($A28="",0,IF(COUNTIF($O$8:$O$101,$O28)>1,1,0))
A29: Primus Japan | B29: PUD PVN 200/300 | C29: Slab | D29: 2 | E29: 0 | F29: =IF($A29="","",SUMIFS('Daily Entry'!$C$7:$C$5003,'Daily Entry'!$B$7:$B$5003,$O29,'Daily Entry'!$A$7:$A$5003,$E$3)) | G29: =IF($A29="","",SUMIFS('Daily Entry'!$D$7:$D$5003,'Daily Entry'!$B$7:$B$5003,$O29,'Daily Entry'!$A$7:$A$5003,$E$3)) | H29: =IF($A29="","",SUMIFS('Daily Entry'!$C$7:$C$5003,'Daily Entry'!$B$7:$B$5003,$O29)) | I29: =IF($A29="","",SUMIFS('Daily Entry'!$D$7:$D$5003,'Daily Entry'!$B$7:$B$5003,$O29)) | J29: =IF($A29="","",$E29+$H29-$I29) | K29: =IF(OR($A29="",$D29=""),"",$J29*$D29) | L29: 6.15 | M29: =IF(OR($A29="",$D29="",$L29="",$E$4=""),"",$K29*$L29*$E$4) | O29: =IF($A29="","",$A29&" - "&$B29) | P29: =IF($A29="",0,IF(OR($F29<>0,$G29<>0),1,0)) | Q29: =IF($P29=1,SUM($P$8:$P29),"") | R29: =IF($A29="","",$A29&"#"&COUNTIF($A$8:$A29,$A29)) | S29: =IF(OR($A29="",$D29=""),0,$E29*$D29) | T29: =IF(OR($A29="",$D29=""),0,$F29*$D29) | U29: =IF(OR($A29="",$D29=""),0,$G29*$D29) | V29: =IF(OR($A29="",$D29=""),0,$H29*$D29) | W29: =IF(OR($A29="",$D29=""),0,$I29*$D29) | X29: =IF(AND($A29<>"",$D29=""),1,0) | Y29: =IF($A29="",0,IF(COUNTIF($O$8:$O$101,$O29)>1,1,0))
A30: Primus Japan | B30: PUD KKD 200/300 | C30: Slab | D30: 2 | E30: 2757 | F30: =IF($A30="","",SUMIFS('Daily Entry'!$C$7:$C$5003,'Daily Entry'!$B$7:$B$5003,$O30,'Daily Entry'!$A$7:$A$5003,$E$3)) | G30: =IF($A30="","",SUMIFS('Daily Entry'!$D$7:$D$5003,'Daily Entry'!$B$7:$B$5003,$O30,'Daily Entry'!$A$7:$A$5003,$E$3)) | H30: =IF($A30="","",SUMIFS('Daily Entry'!$C$7:$C$5003,'Daily Entry'!$B$7:$B$5003,$O30)) | I30: =IF($A30="","",SUMIFS('Daily Entry'!$D$7:$D$5003,'Daily Entry'!$B$7:$B$5003,$O30)) | J30: =IF($A30="","",$E30+$H30-$I30) | K30: =IF(OR($A30="",$D30=""),"",$J30*$D30) | L30: 6.15 | M30: =IF(OR($A30="",$D30="",$L30="",$E$4=""),"",$K30*$L30*$E$4) | O30: =IF($A30="","",$A30&" - "&$B30) | P30: =IF($A30="",0,IF(OR($F30<>0,$G30<>0),1,0)) | Q30: =IF($P30=1,SUM($P$8:$P30),"") | R30: =IF($A30="","",$A30&"#"&COUNTIF($A$8:$A30,$A30)) | S30: =IF(OR($A30="",$D30=""),0,$E30*$D30) | T30: =IF(OR($A30="",$D30=""),0,$F30*$D30) | U30: =IF(OR($A30="",$D30=""),0,$G30*$D30) | V30: =IF(OR($A30="",$D30=""),0,$H30*$D30) | W30: =IF(OR($A30="",$D30=""),0,$I30*$D30) | X30: =IF(AND($A30<>"",$D30=""),1,0) | Y30: =IF($A30="",0,IF(COUNTIF($O$8:$O$101,$O30)>1,1,0))
A31: Primus Japan | B31: PUD KZN 200/300 | C31: Slab | D31: 2 | E31: 1080 | F31: =IF($A31="","",SUMIFS('Daily Entry'!$C$7:$C$5003,'Daily Entry'!$B$7:$B$5003,$O31,'Daily Entry'!$A$7:$A$5003,$E$3)) | G31: =IF($A31="","",SUMIFS('Daily Entry'!$D$7:$D$5003,'Daily Entry'!$B$7:$B$5003,$O31,'Daily Entry'!$A$7:$A$5003,$E$3)) | H31: =IF($A31="","",SUMIFS('Daily Entry'!$C$7:$C$5003,'Daily Entry'!$B$7:$B$5003,$O31)) | I31: =IF($A31="","",SUMIFS('Daily Entry'!$D$7:$D$5003,'Daily Entry'!$B$7:$B$5003,$O31)) | J31: =IF($A31="","",$E31+$H31-$I31) | K31: =IF(OR($A31="",$D31=""),"",$J31*$D31) | L31: 5 | M31: =IF(OR($A31="",$D31="",$L31="",$E$4=""),"",$K31*$L31*$E$4) | O31: =IF($A31="","",$A31&" - "&$B31) | P31: =IF($A31="",0,IF(OR($F31<>0,$G31<>0),1,0)) | Q31: =IF($P31=1,SUM($P$8:$P31),"") | R31: =IF($A31="","",$A31&"#"&COUNTIF($A$8:$A31,$A31)) | S31: =IF(OR($A31="",$D31=""),0,$E31*$D31) | T31: =IF(OR($A31="",$D31=""),0,$F31*$D31) | U31: =IF(OR($A31="",$D31=""),0,$G31*$D31) | V31: =IF(OR($A31="",$D31=""),0,$H31*$D31) | W31: =IF(OR($A31="",$D31=""),0,$I31*$D31) | X31: =IF(AND($A31<>"",$D31=""),1,0) | Y31: =IF($A31="",0,IF(COUNTIF($O$8:$O$101,$O31)>1,1,0))
A32: Primus Japan | B32: PUD NRN 200/300 | C32: Slab | D32: 2 | E32: 0 | F32: =IF($A32="","",SUMIFS('Daily Entry'!$C$7:$C$5003,'Daily Entry'!$B$7:$B$5003,$O32,'Daily Entry'!$A$7:$A$5003,$E$3)) | G32: =IF($A32="","",SUMIFS('Daily Entry'!$D$7:$D$5003,'Daily Entry'!$B$7:$B$5003,$O32,'Daily Entry'!$A$7:$A$5003,$E$3)) | H32: =IF($A32="","",SUMIFS('Daily Entry'!$C$7:$C$5003,'Daily Entry'!$B$7:$B$5003,$O32)) | I32: =IF($A32="","",SUMIFS('Daily Entry'!$D$7:$D$5003,'Daily Entry'!$B$7:$B$5003,$O32)) | J32: =IF($A32="","",$E32+$H32-$I32) | K32: =IF(OR($A32="",$D32=""),"",$J32*$D32) | L32: 5 | M32: =IF(OR($A32="",$D32="",$L32="",$E$4=""),"",$K32*$L32*$E$4) | O32: =IF($A32="","",$A32&" - "&$B32) | P32: =IF($A32="",0,IF(OR($F32<>0,$G32<>0),1,0)) | Q32: =IF($P32=1,SUM($P$8:$P32),"") | R32: =IF($A32="","",$A32&"#"&COUNTIF($A$8:$A32,$A32)) | S32: =IF(OR($A32="",$D32=""),0,$E32*$D32) | T32: =IF(OR($A32="",$D32=""),0,$F32*$D32) | U32: =IF(OR($A32="",$D32=""),0,$G32*$D32) | V32: =IF(OR($A32="",$D32=""),0,$H32*$D32) | W32: =IF(OR($A32="",$D32=""),0,$I32*$D32) | X32: =IF(AND($A32<>"",$D32=""),1,0) | Y32: =IF($A32="",0,IF(COUNTIF($O$8:$O$101,$O32)>1,1,0))
A33: Primus Japan | B33: PUD PVN 300/500 | C33: Slab | D33: 2 | E33: 421 | F33: =IF($A33="","",SUMIFS('Daily Entry'!$C$7:$C$5003,'Daily Entry'!$B$7:$B$5003,$O33,'Daily Entry'!$A$7:$A$5003,$E$3)) | G33: =IF($A33="","",SUMIFS('Daily Entry'!$D$7:$D$5003,'Daily Entry'!$B$7:$B$5003,$O33,'Daily Entry'!$A$7:$A$5003,$E$3)) | H33: =IF($A33="","",SUMIFS('Daily Entry'!$C$7:$C$5003,'Daily Entry'!$B$7:$B$5003,$O33)) | I33: =IF($A33="","",SUMIFS('Daily Entry'!$D$7:$D$5003,'Daily Entry'!$B$7:$B$5003,$O33)) | J33: =IF($A33="","",$E33+$H33-$I33) | K33: =IF(OR($A33="",$D33=""),"",$J33*$D33) | L33: 6.1 | M33: =IF(OR($A33="",$D33="",$L33="",$E$4=""),"",$K33*$L33*$E$4) | O33: =IF($A33="","",$A33&" - "&$B33) | P33: =IF($A33="",0,IF(OR($F33<>0,$G33<>0),1,0)) | Q33: =IF($P33=1,SUM($P$8:$P33),"") | R33: =IF($A33="","",$A33&"#"&COUNTIF($A$8:$A33,$A33)) | S33: =IF(OR($A33="",$D33=""),0,$E33*$D33) | T33: =IF(OR($A33="",$D33=""),0,$F33*$D33) | U33: =IF(OR($A33="",$D33=""),0,$G33*$D33) | V33: =IF(OR($A33="",$D33=""),0,$H33*$D33) | W33: =IF(OR($A33="",$D33=""),0,$I33*$D33) | X33: =IF(AND($A33<>"",$D33=""),1,0) | Y33: =IF($A33="",0,IF(COUNTIF($O$8:$O$101,$O33)>1,1,0))
A34: Primus Japan | B34: PUD KKD 300/500 | C34: Slab | D34: 2 | E34: 580 | F34: =IF($A34="","",SUMIFS('Daily Entry'!$C$7:$C$5003,'Daily Entry'!$B$7:$B$5003,$O34,'Daily Entry'!$A$7:$A$5003,$E$3)) | G34: =IF($A34="","",SUMIFS('Daily Entry'!$D$7:$D$5003,'Daily Entry'!$B$7:$B$5003,$O34,'Daily Entry'!$A$7:$A$5003,$E$3)) | H34: =IF($A34="","",SUMIFS('Daily Entry'!$C$7:$C$5003,'Daily Entry'!$B$7:$B$5003,$O34)) | I34: =IF($A34="","",SUMIFS('Daily Entry'!$D$7:$D$5003,'Daily Entry'!$B$7:$B$5003,$O34)) | J34: =IF($A34="","",$E34+$H34-$I34) | K34: =IF(OR($A34="",$D34=""),"",$J34*$D34) | L34: 6.1 | M34: =IF(OR($A34="",$D34="",$L34="",$E$4=""),"",$K34*$L34*$E$4) | O34: =IF($A34="","",$A34&" - "&$B34) | P34: =IF($A34="",0,IF(OR($F34<>0,$G34<>0),1,0)) | Q34: =IF($P34=1,SUM($P$8:$P34),"") | R34: =IF($A34="","",$A34&"#"&COUNTIF($A$8:$A34,$A34)) | S34: =IF(OR($A34="",$D34=""),0,$E34*$D34) | T34: =IF(OR($A34="",$D34=""),0,$F34*$D34) | U34: =IF(OR($A34="",$D34=""),0,$G34*$D34) | V34: =IF(OR($A34="",$D34=""),0,$H34*$D34) | W34: =IF(OR($A34="",$D34=""),0,$I34*$D34) | X34: =IF(AND($A34<>"",$D34=""),1,0) | Y34: =IF($A34="",0,IF(COUNTIF($O$8:$O$101,$O34)>1,1,0))
A35: Primus EU | B35: PUD 20/40 | C35: Slab | D35: 2 | E35: 185 | F35: =IF($A35="","",SUMIFS('Daily Entry'!$C$7:$C$5003,'Daily Entry'!$B$7:$B$5003,$O35,'Daily Entry'!$A$7:$A$5003,$E$3)) | G35: =IF($A35="","",SUMIFS('Daily Entry'!$D$7:$D$5003,'Daily Entry'!$B$7:$B$5003,$O35,'Daily Entry'!$A$7:$A$5003,$E$3)) | H35: =IF($A35="","",SUMIFS('Daily Entry'!$C$7:$C$5003,'Daily Entry'!$B$7:$B$5003,$O35)) | I35: =IF($A35="","",SUMIFS('Daily Entry'!$D$7:$D$5003,'Daily Entry'!$B$7:$B$5003,$O35)) | J35: =IF($A35="","",$E35+$H35-$I35) | K35: =IF(OR($A35="",$D35=""),"",$J35*$D35) | L35: 6.5 | M35: =IF(OR($A35="",$D35="",$L35="",$E$4=""),"",$K35*$L35*$E$4) | O35: =IF($A35="","",$A35&" - "&$B35) | P35: =IF($A35="",0,IF(OR($F35<>0,$G35<>0),1,0)) | Q35: =IF($P35=1,SUM($P$8:$P35),"") | R35: =IF($A35="","",$A35&"#"&COUNTIF($A$8:$A35,$A35)) | S35: =IF(OR($A35="",$D35=""),0,$E35*$D35) | T35: =IF(OR($A35="",$D35=""),0,$F35*$D35) | U35: =IF(OR($A35="",$D35=""),0,$G35*$D35) | V35: =IF(OR($A35="",$D35=""),0,$H35*$D35) | W35: =IF(OR($A35="",$D35=""),0,$I35*$D35) | X35: =IF(AND($A35<>"",$D35=""),1,0) | Y35: =IF($A35="",0,IF(COUNTIF($O$8:$O$101,$O35)>1,1,0))
A36: Primus EU | B36: PUD 40/60 | C36: Slab | D36: 2 | E36: 368 | F36: =IF($A36="","",SUMIFS('Daily Entry'!$C$7:$C$5003,'Daily Entry'!$B$7:$B$5003,$O36,'Daily Entry'!$A$7:$A$5003,$E$3)) | G36: =IF($A36="","",SUMIFS('Daily Entry'!$D$7:$D$5003,'Daily Entry'!$B$7:$B$5003,$O36,'Daily Entry'!$A$7:$A$5003,$E$3)) | H36: =IF($A36="","",SUMIFS('Daily Entry'!$C$7:$C$5003,'Daily Entry'!$B$7:$B$5003,$O36)) | I36: =IF($A36="","",SUMIFS('Daily Entry'!$D$7:$D$5003,'Daily Entry'!$B$7:$B$5003,$O36)) | J36: =IF($A36="","",$E36+$H36-$I36) | K36: =IF(OR($A36="",$D36=""),"",$J36*$D36) | L36: 6.5 | M36: =IF(OR($A36="",$D36="",$L36="",$E$4=""),"",$K36*$L36*$E$4) | O36: =IF($A36="","",$A36&" - "&$B36) | P36: =IF($A36="",0,IF(OR($F36<>0,$G36<>0),1,0)) | Q36: =IF($P36=1,SUM($P$8:$P36),"") | R36: =IF($A36="","",$A36&"#"&COUNTIF($A$8:$A36,$A36)) | S36: =IF(OR($A36="",$D36=""),0,$E36*$D36) | T36: =IF(OR($A36="",$D36=""),0,$F36*$D36) | U36: =IF(OR($A36="",$D36=""),0,$G36*$D36) | V36: =IF(OR($A36="",$D36=""),0,$H36*$D36) | W36: =IF(OR($A36="",$D36=""),0,$I36*$D36) | X36: =IF(AND($A36<>"",$D36=""),1,0) | Y36: =IF($A36="",0,IF(COUNTIF($O$8:$O$101,$O36)>1,1,0))
A37: Primus EU | B37: PUD 60/80 | C37: Slab | D37: 2 | E37: 380 | F37: =IF($A37="","",SUMIFS('Daily Entry'!$C$7:$C$5003,'Daily Entry'!$B$7:$B$5003,$O37,'Daily Entry'!$A$7:$A$5003,$E$3)) | G37: =IF($A37="","",SUMIFS('Daily Entry'!$D$7:$D$5003,'Daily Entry'!$B$7:$B$5003,$O37,'Daily Entry'!$A$7:$A$5003,$E$3)) | H37: =IF($A37="","",SUMIFS('Daily Entry'!$C$7:$C$5003,'Daily Entry'!$B$7:$B$5003,$O37)) | I37: =IF($A37="","",SUMIFS('Daily Entry'!$D$7:$D$5003,'Daily Entry'!$B$7:$B$5003,$O37)) | J37: =IF($A37="","",$E37+$H37-$I37) | K37: =IF(OR($A37="",$D37=""),"",$J37*$D37) | L37: 6.5 | M37: =IF(OR($A37="",$D37="",$L37="",$E$4=""),"",$K37*$L37*$E$4) | O37: =IF($A37="","",$A37&" - "&$B37) | P37: =IF($A37="",0,IF(OR($F37<>0,$G37<>0),1,0)) | Q37: =IF($P37=1,SUM($P$8:$P37),"") | R37: =IF($A37="","",$A37&"#"&COUNTIF($A$8:$A37,$A37)) | S37: =IF(OR($A37="",$D37=""),0,$E37*$D37) | T37: =IF(OR($A37="",$D37=""),0,$F37*$D37) | U37: =IF(OR($A37="",$D37=""),0,$G37*$D37) | V37: =IF(OR($A37="",$D37=""),0,$H37*$D37) | W37: =IF(OR($A37="",$D37=""),0,$I37*$D37) | X37: =IF(AND($A37<>"",$D37=""),1,0) | Y37: =IF($A37="",0,IF(COUNTIF($O$8:$O$101,$O37)>1,1,0))
A38: Primus EU | B38: PUD 80/120 | C38: Slab | D38: 2 | E38: 1151 | F38: =IF($A38="","",SUMIFS('Daily Entry'!$C$7:$C$5003,'Daily Entry'!$B$7:$B$5003,$O38,'Daily Entry'!$A$7:$A$5003,$E$3)) | G38: =IF($A38="","",SUMIFS('Daily Entry'!$D$7:$D$5003,'Daily Entry'!$B$7:$B$5003,$O38,'Daily Entry'!$A$7:$A$5003,$E$3)) | H38: =IF($A38="","",SUMIFS('Daily Entry'!$C$7:$C$5003,'Daily Entry'!$B$7:$B$5003,$O38)) | I38: =IF($A38="","",SUMIFS('Daily Entry'!$D$7:$D$5003,'Daily Entry'!$B$7:$B$5003,$O38)) | J38: =IF($A38="","",$E38+$H38-$I38) | K38: =IF(OR($A38="",$D38=""),"",$J38*$D38) | L38: 6.5 | M38: =IF(OR($A38="",$D38="",$L38="",$E$4=""),"",$K38*$L38*$E$4) | O38: =IF($A38="","",$A38&" - "&$B38) | P38: =IF($A38="",0,IF(OR($F38<>0,$G38<>0),1,0)) | Q38: =IF($P38=1,SUM($P$8:$P38),"") | R38: =IF($A38="","",$A38&"#"&COUNTIF($A$8:$A38,$A38)) | S38: =IF(OR($A38="",$D38=""),0,$E38*$D38) | T38: =IF(OR($A38="",$D38=""),0,$F38*$D38) | U38: =IF(OR($A38="",$D38=""),0,$G38*$D38) | V38: =IF(OR($A38="",$D38=""),0,$H38*$D38) | W38: =IF(OR($A38="",$D38=""),0,$I38*$D38) | X38: =IF(AND($A38<>"",$D38=""),1,0) | Y38: =IF($A38="",0,IF(COUNTIF($O$8:$O$101,$O38)>1,1,0))
... A59: Shrimp Whole | B59: HOSO PVN 4-7 | C59: Slab | D59: 3 | E59: 0 | F59: =IF($A59="","",SUMIFS('Daily Entry'!$C$7:$C$5003,'Daily Entry'!$B$7:$B$5003,$O59,'Daily Entry'!$A$7:$A$5003,$E$3)) | G59: =IF($A59="","",SUMIFS('Daily Entry'!$D$7:$D$5003,'Daily Entry'!$B$7:$B$5003,$O59,'Daily Entry'!$A$7:$A$5003,$E$3)) | H59: =IF($A59="","",SUMIFS('Daily Entry'!$C$7:$C$5003,'Daily Entry'!$B$7:$B$5003,$O59)) | I59: =IF($A59="","",SUMIFS('Daily Entry'!$D$7:$D$5003,'Daily Entry'!$B$7:$B$5003,$O59)) | J59: =IF($A59="","",$E59+$H59-$I59) | K59: =IF(OR($A59="",$D59=""),"",$J59*$D59) | L59: 4 | M59: =IF(OR($A59="",$D59="",$L59="",$E$4=""),"",$K59*$L59*$E$4) | O59: =IF($A59="","",$A59&" - "&$B59) | P59: =IF($A59="",0,IF(OR($F59<>0,$G59<>0),1,0)) | Q59: =IF($P59=1,SUM($P$8:$P59),"") | R59: =IF($A59="","",$A59&"#"&COUNTIF($A$8:$A59,$A59)) | S59: =IF(OR($A59="",$D59=""),0,$E59*$D59) | T59: =IF(OR($A59="",$D59=""),0,$F59*$D59) | U59: =IF(OR($A59="",$D59=""),0,$G59*$D59) | V59: =IF(OR($A59="",$D59=""),0,$H59*$D59) | W59: =IF(OR($A59="",$D59=""),0,$I59*$D59) | X59: =IF(AND($A59<>"",$D59=""),1,0) | Y59: =IF($A59="",0,IF(COUNTIF($O$8:$O$101,$O59)>1,1,0))
A60: Tuna | B60: SKIPJACK 1/2 | C60: Kg | D60: 1 | E60: 0 | F60: =IF($A60="","",SUMIFS('Daily Entry'!$C$7:$C$5003,'Daily Entry'!$B$7:$B$5003,$O60,'Daily Entry'!$A$7:$A$5003,$E$3)) | G60: =IF($A60="","",SUMIFS('Daily Entry'!$D$7:$D$5003,'Daily Entry'!$B$7:$B$5003,$O60,'Daily Entry'!$A$7:$A$5003,$E$3)) | H60: =IF($A60="","",SUMIFS('Daily Entry'!$C$7:$C$5003,'Daily Entry'!$B$7:$B$5003,$O60)) | I60: =IF($A60="","",SUMIFS('Daily Entry'!$D$7:$D$5003,'Daily Entry'!$B$7:$B$5003,$O60)) | J60: =IF($A60="","",$E60+$H60-$I60) | K60: =IF(OR($A60="",$D60=""),"",$J60*$D60) | M60: =IF(OR($A60="",$D60="",$L60="",$E$4=""),"",$K60*$L60*$E$4) | O60: =IF($A60="","",$A60&" - "&$B60) | P60: =IF($A60="",0,IF(OR($F60<>0,$G60<>0),1,0)) | Q60: =IF($P60=1,SUM($P$8:$P60),"") | R60: =IF($A60="","",$A60&"#"&COUNTIF($A$8:$A60,$A60)) | S60: =IF(OR($A60="",$D60=""),0,$E60*$D60) | T60: =IF(OR($A60="",$D60=""),0,$F60*$D60) | U60: =IF(OR($A60="",$D60=""),0,$G60*$D60) | V60: =IF(OR($A60="",$D60=""),0,$H60*$D60) | W60: =IF(OR($A60="",$D60=""),0,$I60*$D60) | X60: =IF(AND($A60<>"",$D60=""),1,0) | Y60: =IF($A60="",0,IF(COUNTIF($O$8:$O$101,$O60)>1,1,0))
A61: Tuna | B61: SKIPJACK 2/4 | C61: Kg | D61: 1 | E61: 14946.5 | F61: =IF($A61="","",SUMIFS('Daily Entry'!$C$7:$C$5003,'Daily Entry'!$B$7:$B$5003,$O61,'Daily Entry'!$A$7:$A$5003,$E$3)) | G61: =IF($A61="","",SUMIFS('Daily Entry'!$D$7:$D$5003,'Daily Entry'!$B$7:$B$5003,$O61,'Daily Entry'!$A$7:$A$5003,$E$3)) | H61: =IF($A61="","",SUMIFS('Daily Entry'!$C$7:$C$5003,'Daily Entry'!$B$7:$B$5003,$O61)) | I61: =IF($A61="","",SUMIFS('Daily Entry'!$D$7:$D$5003,'Daily Entry'!$B$7:$B$5003,$O61)) | J61: =IF($A61="","",$E61+$H61-$I61) | K61: =IF(OR($A61="",$D61=""),"",$J61*$D61) | L61: 1.58 | M61: =IF(OR($A61="",$D61="",$L61="",$E$4=""),"",$K61*$L61*$E$4) | O61: =IF($A61="","",$A61&" - "&$B61) | P61: =IF($A61="",0,IF(OR($F61<>0,$G61<>0),1,0)) | Q61: =IF($P61=1,SUM($P$8:$P61),"") | R61: =IF($A61="","",$A61&"#"&COUNTIF($A$8:$A61,$A61)) | S61: =IF(OR($A61="",$D61=""),0,$E61*$D61) | T61: =IF(OR($A61="",$D61=""),0,$F61*$D61) | U61: =IF(OR($A61="",$D61=""),0,$G61*$D61) | V61: =IF(OR($A61="",$D61=""),0,$H61*$D61) | W61: =IF(OR($A61="",$D61=""),0,$I61*$D61) | X61: =IF(AND($A61<>"",$D61=""),1,0) | Y61: =IF($A61="",0,IF(COUNTIF($O$8:$O$101,$O61)>1,1,0))
...

Sheet Daily Entry
A1: PREMIER EXPORTS INTERNATIONAL
A2: DAILY ENTRY — ADD ONE ROW PER PRODUCT THAT MOVED
A4: After production, add a row below: date, product from the dropdown, and the quantity in that product's own unit — slabs for the shrimp brands, kilos for tuna and mackerel. Never delete past rows. | G4: Rows that will not reach Stock: | J4: =SUMPRODUCT((B7:B5003<>"")*(COUNTIF(Stock!$O$8:$O$101,B7:B5003)=0)) | K4: ← must stay at 0; anything else is a mistyped product
A6: Date | B6: Item (pick from list) | C6: Production (in product unit) | D6: Shipment (in product unit) | E6: Note
A7: 46254 | B7: Blue Dolphin - PD PVN 100/200 | C7: 1068
A8: 46254 | B8: Blue Dolphin - PD KKD 100/200 | C8: 65
A9: 46254 | B9: Blue Dolphin - PUD PVN 200/300 | C9: 267
A10: 46254 | B10: Primus Japan - PUD KZN 40/60 | C10: 29
A11: 46254 | B11: Primus Japan - PUD KZN 60/80 | C11: 39
A12: 46254 | B12: Primus Japan - PUD KZN 80/120 | C12: 50
A13: 46254 | B13: Primus Japan - PUD NRN 80/120 | C13: 3
A14: 46254 | B14: Primus Japan - PUD KZN 100/200 | C14: 50
A15: 46254 | B15: Primus Japan - PUD KZN 200/300 | C15: 33
A16: 46254 | B16: Primus Japan - PUD PVN 300/500 | C16: 156
A17: 46254 | B17: Primus Japan - PUD KKD 300/500 | C17: 596
A18: 46254 | B18: Primus EU - BKN | C18: 52
... A31: 46255 | B31: Primus EU - BKN | C31: 31
A32: 46255 | B32: Blue Dolphin - PD PVN 100/200 | C32: 0 | D32: 5770
A33: 46255 | B33: Blue Dolphin - PUD PVN 200/300 | C33: 0 | D33: 1200
A34: 46255 | B34: Blue Dolphin - PUD KKD 200/300 | C34: 0 | D34: 1200
A35: 46255 | B35: Blue Dolphin - PUD PVN 300/500 | C35: 0 | D35: 660
A36: 46255 | B36: Blue Dolphin - PUD KKD 300/500 | C36: 0 | D36: 1170
A37: 46256 | B37: Blue Dolphin - PD PVN 100/200 | C37: 588
A38: 46256 | B38: Blue Dolphin - PD KKD 100/200 | C38: 52
A39: 46256 | B39: Blue Dolphin - PUD PVN 200/300 | C39: 419
A40: 46256 | B40: THT Brand - PUD PVN 80/120 | C40: 413
A41: 46256 | B41: THT Brand - PUD PVN 100/200 | C41: 556
A42: 46256 | B42: Primus Japan - PUD KKD 200/300 | C42: 22
A43: 46256 | B43: Primus Japan - PUD KKD 300/500 | C43: 374
A44: 46256 | B44: Primus Japan - PUD PVN 300/500 | C44: 12
A45: 46256 | B45: Primus Japan - PUD KZN 80/120 | C45: 2
A46: 46256 | B46: Primus Japan - PUD KZN 100/200 | C46: 37
A47: 46256 | B47: Primus Japan - PUD KZN 200/300 | C47: 12
A48: 46256 | B48: Primus EU - BKN | C48: 16
A49: 46256 | B49: Primus Japan - PUD PVN 80/120 | C49: 0 | D49: 10000
A50: 46256 | B50: Semi Needle Squid - SQW 20/40 | C50: 165
A51: 46256 | B51: Semi Needle Squid - SQW 40/60 | C51: 801
A52: 46256 | B52: Semi Needle Squid - SQW 60/80 | C52: 137
A53: 46257 | B53: Blue Dolphin - PD PVN 100/200 | C53: 52
A54: 46257 | B54: Blue Dolphin - PUD PVN 200/300 | C54: 62
...

Sheet Summary
A1: PREMIER EXPORTS INTERNATIONAL
A2: VALUATION BY BRAND
A4: Closing Stock | C4: Stock Value (₹) | G4: Stock Value ($)
A5: =Stock!$K$102 | C5: =IF(Stock!$M$102="","—",Stock!$M$102) | G5: =IF(OR(Stock!$E$4="",Stock!$M$102=""),"—",Stock!$M$102/Stock!$E$4)
A6: kilos, across every product | C6: at the per-kilo export prices | G6: the same stock in dollars
A7: =IF(SUM(Stock!$X$8:$X$101)=0,"",SUM(Stock!$X$8:$X$101)&" product(s) have no Kg / Unit on Stock — they are counted in kilos as zero and are not valued.")
A9: Blue Dolphin
A10: Product | B10: Unit | C10: Kg / Unit | D10: Closing Balance | E10: Closing Stock (Kg) | F10: No. of Cases | G10: Rate / Kg ($) | H10: Stock Value (₹)
A11: =IF($J11="","",INDEX(Stock!$B$8:$B$101,$J11)) | B11: =IF($J11="","",IF(INDEX(Stock!$C$8:$C$101,$J11)=0,"",INDEX(Stock!$C$8:$C$101,$J11))) | C11: =IF($J11="","",IF(INDEX(Stock!$D$8:$D$101,$J11)=0,"",INDEX(Stock!$D$8:$D$101,$J11))) | D11: =IF($J11="","",INDEX(Stock!$J$8:$J$101,$J11)) | E11: =IF($J11="","",INDEX(Stock!$K$8:$K$101,$J11)) | F11: =+$D11/10 | G11: =IF($J11="","",IF(INDEX(Stock!$L$8:$L$101,$J11)=0,"",INDEX(Stock!$L$8:$L$101,$J11))) | H11: =IF($J11="","",INDEX(Stock!$M$8:$M$101,$J11)) | J11: =IFERROR(MATCH($A$9&"#"&1,Stock!$R$8:$R$101,0),"")
A12: =IF($J12="","",INDEX(Stock!$B$8:$B$101,$J12)) | B12: =IF($J12="","",IF(INDEX(Stock!$C$8:$C$101,$J12)=0,"",INDEX(Stock!$C$8:$C$101,$J12))) | C12: =IF($J12="","",IF(INDEX(Stock!$D$8:$D$101,$J12)=0,"",INDEX(Stock!$D$8:$D$101,$J12))) | D12: =IF($J12="","",INDEX(Stock!$J$8:$J$101,$J12)) | E12: =IF($J12="","",INDEX(Stock!$K$8:$K$101,$J12)) | F12: =+$D12/10 | G12: =IF($J12="","",IF(INDEX(Stock!$L$8:$L$101,$J12)=0,"",INDEX(Stock!$L$8:$L$101,$J12))) | H12: =IF($J12="","",INDEX(Stock!$M$8:$M$101,$J12)) | J12: =IFERROR(MATCH($A$9&"#"&2,Stock!$R$8:$R$101,0),"")
A13: =IF($J13="","",INDEX(Stock!$B$8:$B$101,$J13)) | B13: =IF($J13="","",IF(INDEX(Stock!$C$8:$C$101,$J13)=0,"",INDEX(Stock!$C$8:$C$101,$J13))) | C13: =IF($J13="","",IF(INDEX(Stock!$D$8:$D$101,$J13)=0,"",INDEX(Stock!$D$8:$D$101,$J13))) | D13: =IF($J13="","",INDEX(Stock!$J$8:$J$101,$J13)) | E13: =IF($J13="","",INDEX(Stock!$K$8:$K$101,$J13)) | F13: =+$D13/10 | G13: =IF($J13="","",IF(INDEX(Stock!$L$8:$L$101,$J13)=0,"",INDEX(Stock!$L$8:$L$101,$J13))) | H13: =IF($J13="","",INDEX(Stock!$M$8:$M$101,$J13)) | J13: =IFERROR(MATCH($A$9&"#"&3,Stock!$R$8:$R$101,0),"")
A14: =IF($J14="","",INDEX(Stock!$B$8:$B$101,$J14)) | B14: =IF($J14="","",IF(INDEX(Stock!$C$8:$C$101,$J14)=0,"",INDEX(Stock!$C$8:$C$101,$J14))) | C14: =IF($J14="","",IF(INDEX(Stock!$D$8:$D$101,$J14)=0,"",INDEX(Stock!$D$8:$D$101,$J14))) | D14: =IF($J14="","",INDEX(Stock!$J$8:$J$101,$J14)) | E14: =IF($J14="","",INDEX(Stock!$K$8:$K$101,$J14)) | F14: =+$D14/10 | G14: =IF($J14="","",IF(INDEX(Stock!$L$8:$L$101,$J14)=0,"",INDEX(Stock!$L$8:$L$101,$J14))) | H14: =IF($J14="","",INDEX(Stock!$M$8:$M$101,$J14)) | J14: =IFERROR(MATCH($A$9&"#"&4,Stock!$R$8:$R$101,0),"")
A15: =IF($J15="","",INDEX(Stock!$B$8:$B$101,$J15)) | B15: =IF($J15="","",IF(INDEX(Stock!$C$8:$C$101,$J15)=0,"",INDEX(Stock!$C$8:$C$101,$J15))) | C15: =IF($J15="","",IF(INDEX(Stock!$D$8:$D$101,$J15)=0,"",INDEX(Stock!$D$8:$D$101,$J15))) | D15: =IF($J15="","",INDEX(Stock!$J$8:$J$101,$J15)) | E15: =IF($J15="","",INDEX(Stock!$K$8:$K$101,$J15)) | F15: =+$D15/10 | G15: =IF($J15="","",IF(INDEX(Stock!$L$8:$L$101,$J15)=0,"",INDEX(Stock!$L$8:$L$101,$J15))) | H15: =IF($J15="","",INDEX(Stock!$M$8:$M$101,$J15)) | J15: =IFERROR(MATCH($A$9&"#"&5,Stock!$R$8:$R$101,0),"")
A16: =IF($J16="","",INDEX(Stock!$B$8:$B$101,$J16)) | B16: =IF($J16="","",IF(INDEX(Stock!$C$8:$C$101,$J16)=0,"",INDEX(Stock!$C$8:$C$101,$J16))) | C16: =IF($J16="","",IF(INDEX(Stock!$D$8:$D$101,$J16)=0,"",INDEX(Stock!$D$8:$D$101,$J16))) | D16: =IF($J16="","",INDEX(Stock!$J$8:$J$101,$J16)) | E16: =IF($J16="","",INDEX(Stock!$K$8:$K$101,$J16)) | F16: =+$D16/10 | G16: =IF($J16="","",IF(INDEX(Stock!$L$8:$L$101,$J16)=0,"",INDEX(Stock!$L$8:$L$101,$J16))) | H16: =IF($J16="","",INDEX(Stock!$M$8:$M$101,$J16)) | J16: =IFERROR(MATCH($A$9&"#"&6,Stock!$R$8:$R$101,0),"")
A17: =IF($J17="","",INDEX(Stock!$B$8:$B$101,$J17)) | B17: =IF($J17="","",IF(INDEX(Stock!$C$8:$C$101,$J17)=0,"",INDEX(Stock!$C$8:$C$101,$J17))) | C17: =IF($J17="","",IF(INDEX(Stock!$D$8:$D$101,$J17)=0,"",INDEX(Stock!$D$8:$D$101,$J17))) | D17: =IF($J17="","",INDEX(Stock!$J$8:$J$101,$J17)) | E17: =IF($J17="","",INDEX(Stock!$K$8:$K$101,$J17)) | F17: =+$D17/10 | G17: =IF($J17="","",IF(INDEX(Stock!$L$8:$L$101,$J17)=0,"",INDEX(Stock!$L$8:$L$101,$J17))) | H17: =IF($J17="","",INDEX(Stock!$M$8:$M$101,$J17)) | J17: =IFERROR(MATCH($A$9&"#"&7,Stock!$R$8:$R$101,0),"")
A18: =IF($J18="","",INDEX(Stock!$B$8:$B$101,$J18)) | B18: =IF($J18="","",IF(INDEX(Stock!$C$8:$C$101,$J18)=0,"",INDEX(Stock!$C$8:$C$101,$J18))) | C18: =IF($J18="","",IF(INDEX(Stock!$D$8:$D$101,$J18)=0,"",INDEX(Stock!$D$8:$D$101,$J18))) | D18: =IF($J18="","",INDEX(Stock!$J$8:$J$101,$J18)) | E18: =IF($J18="","",INDEX(Stock!$K$8:$K$101,$J18)) | F18: =+$D18/10 | G18: =IF($J18="","",IF(INDEX(Stock!$L$8:$L$101,$J18)=0,"",INDEX(Stock!$L$8:$L$101,$J18))) | H18: =IF($J18="","",INDEX(Stock!$M$8:$M$101,$J18)) | J18: =IFERROR(MATCH($A$9&"#"&8,Stock!$R$8:$R$101,0),"")
A19: =IF($J19="","",INDEX(Stock!$B$8:$B$101,$J19)) | B19: =IF($J19="","",IF(INDEX(Stock!$C$8:$C$101,$J19)=0,"",INDEX(Stock!$C$8:$C$101,$J19))) | C19: =IF($J19="","",IF(INDEX(Stock!$D$8:$D$101,$J19)=0,"",INDEX(Stock!$D$8:$D$101,$J19))) | D19: =IF($J19="","",INDEX(Stock!$J$8:$J$101,$J19)) | E19: =IF($J19="","",INDEX(Stock!$K$8:$K$101,$J19)) | G19: =IF($J19="","",IF(INDEX(Stock!$L$8:$L$101,$J19)=0,"",INDEX(Stock!$L$8:$L$101,$J19))) | H19: =IF($J19="","",INDEX(Stock!$M$8:$M$101,$J19)) | J19: =IFERROR(MATCH($A$9&"#"&9,Stock!$R$8:$R$101,0),"")
A20: =IF($J20="","",INDEX(Stock!$B$8:$B$101,$J20)) | B20: =IF($J20="","",IF(INDEX(Stock!$C$8:$C$101,$J20)=0,"",INDEX(Stock!$C$8:$C$101,$J20))) | C20: =IF($J20="","",IF(INDEX(Stock!$D$8:$D$101,$J20)=0,"",INDEX(Stock!$D$8:$D$101,$J20))) | D20: =IF($J20="","",INDEX(Stock!$J$8:$J$101,$J20)) | E20: =IF($J20="","",INDEX(Stock!$K$8:$K$101,$J20)) | G20: =IF($J20="","",IF(INDEX(Stock!$L$8:$L$101,$J20)=0,"",INDEX(Stock!$L$8:$L$101,$J20))) | H20: =IF($J20="","",INDEX(Stock!$M$8:$M$101,$J20)) | J20: =IFERROR(MATCH($A$9&"#"&10,Stock!$R$8:$R$101,0),"")
A21: =IF($J21="","",INDEX(Stock!$B$8:$B$101,$J21)) | B21: =IF($J21="","",IF(INDEX(Stock!$C$8:$C$101,$J21)=0,"",INDEX(Stock!$C$8:$C$101,$J21))) | C21: =IF($J21="","",IF(INDEX(Stock!$D$8:$D$101,$J21)=0,"",INDEX(Stock!$D$8:$D$101,$J21))) | D21: =IF($J21="","",INDEX(Stock!$J$8:$J$101,$J21)) | E21: =IF($J21="","",INDEX(Stock!$K$8:$K$101,$J21)) | G21: =IF($J21="","",IF(INDEX(Stock!$L$8:$L$101,$J21)=0,"",INDEX(Stock!$L$8:$L$101,$J21))) | H21: =IF($J21="","",INDEX(Stock!$M$8:$M$101,$J21)) | J21: =IFERROR(MATCH($A$9&"#"&11,Stock!$R$8:$R$101,0),"")
A22: =IF($A$9="","",$A$9&" total") | D22: =SUM(D11:D21) | E22: =SUM(E11:E21) | F22: =SUM(F11:F21) | H22: =SUM(H11:H21)
A24: Primus Japan
A25: Product | B25: Unit | C25: Kg / Unit | D25: Closing Balance | E25: Closing Stock (Kg) | F25: No. of Cases | G25: Rate / Kg ($) | H25: Stock Value (₹)
A26: =IF($J26="","",INDEX(Stock!$B$8:$B$101,$J26)) | B26: =IF($J26="","",IF(INDEX(Stock!$C$8:$C$101,$J26)=0,"",INDEX(Stock!$C$8:$C$101,$J26))) | C26: =IF($J26="","",IF(INDEX(Stock!$D$8:$D$101,$J26)=0,"",INDEX(Stock!$D$8:$D$101,$J26))) | D26: =IF($J26="","",INDEX(Stock!$J$8:$J$101,$J26)) | E26: =IF($J26="","",INDEX(Stock!$K$8:$K$101,$J26)) | F26: =+$D26/10 | G26: =IF($J26="","",IF(INDEX(Stock!$L$8:$L$101,$J26)=0,"",INDEX(Stock!$L$8:$L$101,$J26))) | H26: =IF($J26="","",INDEX(Stock!$M$8:$M$101,$J26)) | J26: =IFERROR(MATCH($A$24&"#"&1,Stock!$R$8:$R$101,0),"")
A27: =IF($J27="","",INDEX(Stock!$B$8:$B$101,$J27)) | B27: =IF($J27="","",IF(INDEX(Stock!$C$8:$C$101,$J27)=0,"",INDEX(Stock!$C$8:$C$101,$J27))) | C27: =IF($J27="","",IF(INDEX(Stock!$D$8:$D$101,$J27)=0,"",INDEX(Stock!$D$8:$D$101,$J27))) | D27: =IF($J27="","",INDEX(Stock!$J$8:$J$101,$J27)) | E27: =IF($J27="","",INDEX(Stock!$K$8:$K$101,$J27)) | F27: =+$D27/10 | G27: =IF($J27="","",IF(INDEX(Stock!$L$8:$L$101,$J27)=0,"",INDEX(Stock!$L$8:$L$101,$J27))) | H27: =IF($J27="","",INDEX(Stock!$M$8:$M$101,$J27)) | J27: =IFERROR(MATCH($A$24&"#"&2,Stock!$R$8:$R$101,0),"")
A28: =IF($J28="","",INDEX(Stock!$B$8:$B$101,$J28)) | B28: =IF($J28="","",IF(INDEX(Stock!$C$8:$C$101,$J28)=0,"",INDEX(Stock!$C$8:$C$101,$J28))) | C28: =IF($J28="","",IF(INDEX(Stock!$D$8:$D$101,$J28)=0,"",INDEX(Stock!$D$8:$D$101,$J28))) | D28: =IF($J28="","",INDEX(Stock!$J$8:$J$101,$J28)) | E28: =IF($J28="","",INDEX(Stock!$K$8:$K$101,$J28)) | F28: =+$D28/10 | G28: =IF($J28="","",IF(INDEX(Stock!$L$8:$L$101,$J28)=0,"",INDEX(Stock!$L$8:$L$101,$J28))) | H28: =IF($J28="","",INDEX(Stock!$M$8:$M$101,$J28)) | J28: =IFERROR(MATCH($A$24&"#"&3,Stock!$R$8:$R$101,0),"")
A29: =IF($J29="","",INDEX(Stock!$B$8:$B$101,$J29)) | B29: =IF($J29="","",IF(INDEX(Stock!$C$8:$C$101,$J29)=0,"",INDEX(Stock!$C$8:$C$101,$J29))) | C29: =IF($J29="","",IF(INDEX(Stock!$D$8:$D$101,$J29)=0,"",INDEX(Stock!$D$8:$D$101,$J29))) | D29: =IF($J29="","",INDEX(Stock!$J$8:$J$101,$J29)) | E29: =IF($J29="","",INDEX(Stock!$K$8:$K$101,$J29)) | F29: =+$D29/10 | G29: =IF($J29="","",IF(INDEX(Stock!$L$8:$L$101,$J29)=0,"",INDEX(Stock!$L$8:$L$101,$J29))) | H29: =IF($J29="","",INDEX(Stock!$M$8:$M$101,$J29)) | J29: =IFERROR(MATCH($A$24&"#"&4,Stock!$R$8:$R$101,0),"")
A30: =IF($J30="","",INDEX(Stock!$B$8:$B$101,$J30)) | B30: =IF($J30="","",IF(INDEX(Stock!$C$8:$C$101,$J30)=0,"",INDEX(Stock!$C$8:$C$101,$J30))) | C30: =IF($J30="","",IF(INDEX(Stock!$D$8:$D$101,$J30)=0,"",INDEX(Stock!$D$8:$D$101,$J30))) | D30: =IF($J30="","",INDEX(Stock!$J$8:$J$101,$J30)) | E30: =IF($J30="","",INDEX(Stock!$K$8:$K$101,$J30)) | F30: =+$D30/10 | G30: =IF($J30="","",IF(INDEX(Stock!$L$8:$L$101,$J30)=0,"",INDEX(Stock!$L$8:$L$101,$J30))) | H30: =IF($J30="","",INDEX(Stock!$M$8:$M$101,$J30)) | J30: =IFERROR(MATCH($A$24&"#"&5,Stock!$R$8:$R$101,0),"")
A31: =IF($J31="","",INDEX(Stock!$B$8:$B$101,$J31)) | B31: =IF($J31="","",IF(INDEX(Stock!$C$8:$C$101,$J31)=0,"",INDEX(Stock!$C$8:$C$101,$J31))) | C31: =IF($J31="","",IF(INDEX(Stock!$D$8:$D$101,$J31)=0,"",INDEX(Stock!$D$8:$D$101,$J31))) | D31: =IF($J31="","",INDEX(Stock!$J$8:$J$101,$J31)) | E31: =IF($J31="","",INDEX(Stock!$K$8:$K$101,$J31)) | F31: =+$D31/10 | G31: =IF($J31="","",IF(INDEX(Stock!$L$8:$L$101,$J31)=0,"",INDEX(Stock!$L$8:$L$101,$J31))) | H31: =IF($J31="","",INDEX(Stock!$M$8:$M$101,$J31)) | J31: =IFERROR(MATCH($A$24&"#"&6,Stock!$R$8:$R$101,0),"")
A32: =IF($J32="","",INDEX(Stock!$B$8:$B$101,$J32)) | B32: =IF($J32="","",IF(INDEX(Stock!$C$8:$C$101,$J32)=0,"",INDEX(Stock!$C$8:$C$101,$J32))) | C32: =IF($J32="","",IF(INDEX(Stock!$D$8:$D$101,$J32)=0,"",INDEX(Stock!$D$8:$D$101,$J32))) | D32: =IF($J32="","",INDEX(Stock!$J$8:$J$101,$J32)) | E32: =IF($J32="","",INDEX(Stock!$K$8:$K$101,$J32)) | F32: =+$D32/10 | G32: =IF($J32="","",IF(INDEX(Stock!$L$8:$L$101,$J32)=0,"",INDEX(Stock!$L$8:$L$101,$J32))) | H32: =IF($J32="","",INDEX(Stock!$M$8:$M$101,$J32)) | J32: =IFERROR(MATCH($A$24&"#"&7,Stock!$R$8:$R$101,0),"")
A33: =IF($J33="","",INDEX(Stock!$B$8:$B$101,$J33)) | B33: =IF($J33="","",IF(INDEX(Stock!$C$8:$C$101,$J33)=0,"",INDEX(Stock!$C$8:$C$101,$J33))) | C33: =IF($J33="","",IF(INDEX(Stock!$D$8:$D$101,$J33)=0,"",INDEX(Stock!$D$8:$D$101,$J33))) | D33: =IF($J33="","",INDEX(Stock!$J$8:$J$101,$J33)) | E33: =IF($J33="","",INDEX(Stock!$K$8:$K$101,$J33)) | F33: =+$D33/10 | G33: =IF($J33="","",IF(INDEX(Stock!$L$8:$L$101,$J33)=0,"",INDEX(Stock!$L$8:$L$101,$J33))) | H33: =IF($J33="","",INDEX(Stock!$M$8:$M$101,$J33)) | J33: =IFERROR(MATCH($A$24&"#"&8,Stock!$R$8:$R$101,0),"")
A34: =IF($J34="","",INDEX(Stock!$B$8:$B$101,$J34)) | B34: =IF($J34="","",IF(INDEX(Stock!$C$8:$C$101,$J34)=0,"",INDEX(Stock!$C$8:$C$101,$J34))) | C34: =IF($J34="","",IF(INDEX(Stock!$D$8:$D$101,$J34)=0,"",INDEX(Stock!$D$8:$D$101,$J34))) | D34: =IF($J34="","",INDEX(Stock!$J$8:$J$101,$J34)) | E34: =IF($J34="","",INDEX(Stock!$K$8:$K$101,$J34)) | F34: =+$D34/10 | G34: =IF($J34="","",IF(INDEX(Stock!$L$8:$L$101,$J34)=0,"",INDEX(Stock!$L$8:$L$101,$J34))) | H34: =IF($J34="","",INDEX(Stock!$M$8:$M$101,$J34)) | J34: =IFERROR(MATCH($A$24&"#"&9,Stock!$R$8:$R$101,0),"")
A35: =IF($J35="","",INDEX(Stock!$B$8:$B$101,$J35)) | B35: =IF($J35="","",IF(INDEX(Stock!$C$8:$C$101,$J35)=0,"",INDEX(Stock!$C$8:$C$101,$J35))) | C35: =IF($J35="","",IF(INDEX(Stock!$D$8:$D$101,$J35)=0,"",INDEX(Stock!$D$8:$D$101,$J35))) | D35: =IF($J35="","",INDEX(Stock!$J$8:$J$101,$J35)) | E35: =IF($J35="","",INDEX(Stock!$K$8:$K$101,$J35)) | F35: =+$D35/10 | G35: =IF($J35="","",IF(INDEX(Stock!$L$8:$L$101,$J35)=0,"",INDEX(Stock!$L$8:$L$101,$J35))) | H35: =IF($J35="","",INDEX(Stock!$M$8:$M$101,$J35)) | J35: =IFERROR(MATCH($A$24&"#"&10,Stock!$R$8:$R$101,0),"")
A36: =IF($J36="","",INDEX(Stock!$B$8:$B$101,$J36)) | B36: =IF($J36="","",IF(INDEX(Stock!$C$8:$C$101,$J36)=0,"",INDEX(Stock!$C$8:$C$101,$J36))) | C36: =IF($J36="","",IF(INDEX(Stock!$D$8:$D$101,$J36)=0,"",INDEX(Stock!$D$8:$D$101,$J36))) | D36: =IF($J36="","",INDEX(Stock!$J$8:$J$101,$J36)) | E36: =IF($J36="","",INDEX(Stock!$K$8:$K$101,$J36)) | F36: =+$D36/10 | G36: =IF($J36="","",IF(INDEX(Stock!$L$8:$L$101,$J36)=0,"",INDEX(Stock!$L$8:$L$101,$J36))) | H36: =IF($J36="","",INDEX(Stock!$M$8:$M$101,$J36)) | J36: =IFERROR(MATCH($A$24&"#"&11,Stock!$R$8:$R$101,0),"")
A37: =IF($J37="","",INDEX(Stock!$B$8:$B$101,$J37)) | B37: =IF($J37="","",IF(INDEX(Stock!$C$8:$C$101,$J37)=0,"",INDEX(Stock!$C$8:$C$101,$J37))) | C37: =IF($J37="","",IF(INDEX(Stock!$D$8:$D$101,$J37)=0,"",INDEX(Stock!$D$8:$D$101,$J37))) | D37: =IF($J37="","",INDEX(Stock!$J$8:$J$101,$J37)) | E37: =IF($J37="","",INDEX(Stock!$K$8:$K$101,$J37)) | F37: =+$D37/10 | G37: =IF($J37="","",IF(INDEX(Stock!$L$8:$L$101,$J37)=0,"",INDEX(Stock!$L$8:$L$101,$J37))) | H37: =IF($J37="","",INDEX(Stock!$M$8:$M$101,$J37)) | J37: =IFERROR(MATCH($A$24&"#"&12,Stock!$R$8:$R$101,0),"")
A38: =IF($J38="","",INDEX(Stock!$B$8:$B$101,$J38)) | B38: =IF($J38="","",IF(INDEX(Stock!$C$8:$C$101,$J38)=0,"",INDEX(Stock!$C$8:$C$101,$J38))) | C38: =IF($J38="","",IF(INDEX(Stock!$D$8:$D$101,$J38)=0,"",INDEX(Stock!$D$8:$D$101,$J38))) | D38: =IF($J38="","",INDEX(Stock!$J$8:$J$101,$J38)) | E38: =IF($J38="","",INDEX(Stock!$K$8:$K$101,$J38)) | F38: =+$D38/10 | G38: =IF($J38="","",IF(INDEX(Stock!$L$8:$L$101,$J38)=0,"",INDEX(Stock!$L$8:$L$101,$J38))) | H38: =IF($J38="","",INDEX(Stock!$M$8:$M$101,$J38)) | J38: =IFERROR(MATCH($A$24&"#"&13,Stock!$R$8:$R$101,0),"")
A39: =IF($J39="","",INDEX(Stock!$B$8:$B$101,$J39)) | B39: =IF($J39="","",IF(INDEX(Stock!$C$8:$C$101,$J39)=0,"",INDEX(Stock!$C$8:$C$101,$J39))) | C39: =IF($J39="","",IF(INDEX(Stock!$D$8:$D$101,$J39)=0,"",INDEX(Stock!$D$8:$D$101,$J39))) | D39: =IF($J39="","",INDEX(Stock!$J$8:$J$101,$J39)) | E39: =IF($J39="","",INDEX(Stock!$K$8:$K$101,$J39)) | F39: =+$D39/10 | G39: =IF($J39="","",IF(INDEX(Stock!$L$8:$L$101,$J39)=0,"",INDEX(Stock!$L$8:$L$101,$J39))) | H39: =IF($J39="","",INDEX(Stock!$M$8:$M$101,$J39)) | J39: =IFERROR(MATCH($A$24&"#"&14,Stock!$R$8:$R$101,0),"")
A40: =IF($J40="","",INDEX(Stock!$B$8:$B$101,$J40)) | B40: =IF($J40="","",IF(INDEX(Stock!$C$8:$C$101,$J40)=0,"",INDEX(Stock!$C$8:$C$101,$J40))) | C40: =IF($J40="","",IF(INDEX(Stock!$D$8:$D$101,$J40)=0,"",INDEX(Stock!$D$8:$D$101,$J40))) | D40: =IF($J40="","",INDEX(Stock!$J$8:$J$101,$J40)) | E40: =IF($J40="","",INDEX(Stock!$K$8:$K$101,$J40)) | F40: =+$D40/10 | G40: =IF($J40="","",IF(INDEX(Stock!$L$8:$L$101,$J40)=0,"",INDEX(Stock!$L$8:$L$101,$J40))) | H40: =IF($J40="","",INDEX(Stock!$M$8:$M$101,$J40)) | J40: =IFERROR(MATCH($A$24&"#"&15,Stock!$R$8:$R$101,0),"")
A41: =IF($J41="","",INDEX(Stock!$B$8:$B$101,$J41)) | B41: =IF($J41="","",IF(INDEX(Stock!$C$8:$C$101,$J41)=0,"",INDEX(Stock!$C$8:$C$101,$J41))) | C41: =IF($J41="","",IF(INDEX(Stock!$D$8:$D$101,$J41)=0,"",INDEX(Stock!$D$8:$D$101,$J41))) | D41: =IF($J41="","",INDEX(Stock!$J$8:$J$101,$J41)) | E41: =IF($J41="","",INDEX(Stock!$K$8:$K$101,$J41)) | F41: =+$D41/10 | G41: =IF($J41="","",IF(INDEX(Stock!$L$8:$L$101,$J41)=0,"",INDEX(Stock!$L$8:$L$101,$J41))) | H41: =IF($J41="","",INDEX(Stock!$M$8:$M$101,$J41)) | J41: =IFERROR(MATCH($A$24&"#"&16,Stock!$R$8:$R$101,0),"")
