Workbook

Sheet Read me
A1: PREMIER EXPORTS INTERNATIONAL
A2: LOT ANALYSIS — HOW IT WORKS
B4: For each lot
B5: 1. On 'Lots' add a row: lot no, dates, party, raw kg, raw amount, peeling ₹/kg,
B6: and the exchange rate. Those eight are all you type.
B7: 2. On 'Lot Entry' add one row per grade produced: slabs, net kg per slab,
B8: gross weight per slab and the sale price per kg.
B9: 3. On 'Lot Report' put the lot number in the yellow cell.
B10: 4. File ▸ Export ▸ Create PDF/XPS, "Selected sheet" — the directors' copy.
B12: The two weights are not the same
B13: Net kg per slab (usually 2) is what the buyer pays for: Packed kg = slabs × net.
B14: Gross weight per slab (2.150, 2.200 …) is the final weight: F.WT = slabs × gross.
B15: Yield is measured on F.WT, but the sale is on packed kg — so both are carried.
B17: The arithmetic
... B42: that carries into the profit. This workbook is arithmetically consistent.

Sheet Grades
A1: PREMIER EXPORTS INTERNATIONAL
A2: GRADE MASTER — SPEC, GRADE AND THE USUAL WEIGHT AND PRICE
A4: The dropdown on Lot Entry reads this list. Gross wt and price here are the usual figures — enter the actual ones on each lot line.
A5: Spec | B5: Grade | C5: Gross wt / slab (kg) | D5: Usual price (US$/kg) | F5: Key (do not edit)
A6: PVN PMS | B6: 80/120 | C6: 2.15 | D6: 7 | F6: =IF($A6="","",$A6&" "&$B6) -> PVN PMS 80/120
A7: PVN BD | B7: 100/200 PD | C7: 2.2 | D7: 7 | F7: =IF($A7="","",$A7&" "&$B7) -> PVN BD 100/200 PD
A8: KKD BD | B8: 100/200 PD | C8: 2.22 | D8: 7 | F8: =IF($A8="","",$A8&" "&$B8) -> KKD BD 100/200 PD
A9: PVN BD | B9: 200/300 PUD | C9: 2.2 | D9: 6 | F9: =IF($A9="","",$A9&" "&$B9) -> PVN BD 200/300 PUD
A10: KKD BD | B10: 200/300 PUD | C10: 2.22 | D10: 6 | F10: =IF($A10="","",$A10&" "&$B10) -> KKD BD 200/300 PUD
A11: PVN PMS | B11: 200/300 PD | C11: 2.2 | D11: 6.4 | F11: =IF($A11="","",$A11&" "&$B11) -> PVN PMS 200/300 PD
A12: KKD PMS | B12: 200/300 PD | C12: 2.22 | D12: 6.4 | F12: =IF($A12="","",$A12&" "&$B12) -> KKD PMS 200/300 PD
A13: PVN PMS | B13: 300/500 | C13: 2.22 | D13: 6 | F13: =IF($A13="","",$A13&" "&$B13) -> PVN PMS 300/500
A14: KKD PMS | B14: 300/500 | C14: 2.25 | D14: 6 | F14: =IF($A14="","",$A14&" "&$B14) -> KKD PMS 300/500
A15: EU | B15: 80/120 | C15: 2.12 | D15: 4 | F15: =IF($A15="","",$A15&" "&$B15) -> EU 80/120
A16: EU | B16: 100/200 | C16: 2.2 | D16: 3.5 | F16: =IF($A16="","",$A16&" "&$B16) -> EU 100/200
A17: EU | B17: 200/300 | C17: 2.2 | D17: 3 | F17: =IF($A17="","",$A17&" "&$B17) -> EU 200/300
... A25: PVN PMS | B25: 100/200 PUD | C25: 2.2 | D25: 6.4 | F25: =IF($A25="","",$A25&" "&$B25) -> PVN PMS 100/200 PUD
F26: =IF($A26="","",$A26&" "&$B26)
F27: =IF($A27="","",$A27&" "&$B27)
F28: =IF($A28="","",$A28&" "&$B28)
F29: =IF($A29="","",$A29&" "&$B29)
F30: =IF($A30="","",$A30&" "&$B30)
F31: =IF($A31="","",$A31&" "&$B31)
F32: =IF($A32="","",$A32&" "&$B32)
F33: =IF($A33="","",$A33&" "&$B33)
F34: =IF($A34="","",$A34&" "&$B34)
F35: =IF($A35="","",$A35&" "&$B35)
F36: =IF($A36="","",$A36&" "&$B36)
F37: =IF($A37="","",$A37&" "&$B37)
... F45: =IF($A45="","",$A45&" "&$B45)

Sheet Expenses
A1: PREMIER EXPORTS INTERNATIONAL
A2: EXPENSE HEADS — STANDARD RATE PER KG OF PACKED PRODUCT
A4: These rates apply to every lot. A lot that differs can override any head on the Lots sheet without changing them here.
A5: Expense head | B5: Rate ₹ / kg
A6: Freezing Charges | B6: 15
A7: Polythene | B7: 1.94
A8: Cartons | B8: 2.6
A9: Loading | B9: 0.15
A10: C&F Charges | B10: 0.75
A11: Freight | B11: 10
A12: THC | B12: 1.75
A13: Shipment Expenses | B13: 0.25
A14: Preship Survey | B14: 0.06
A15: Nego. Int. | B15: 0.1
A16: Neg. Exp. | B16: 0.1
A17: Prop. Staff | B17: 5
A18: Other unseen | B18: 2
A19: TOTAL | B19: =SUM(B6:B18) -> 39.7

Sheet Lots
A1: PREMIER EXPORTS INTERNATIONAL
A2: LOTS — ONE ROW PER RAW-MATERIAL PURCHASE
A4: Type the eight blue columns. Everything from Peeling Amount rightwards is calculated. Leave an expense override blank to use the standard rate.
A7: Lot No | B7: Statement Date | C7: Purchase Date | D7: Party | E7: Supervisor | F7: Raw Qty (kg) | G7: Raw Amount (₹) | H7: Peeling ₹/kg | I7: Exch. rate US$→₹ | J7: Peeling Amount (₹) | K7: Total Raw Cost (₹) | L7: Avg Price /kg (₹) | M7: Packed (kg) | N7: F.WT (kg) | O7: Yield % | P7: Sales (US$) | Q7: Sales Value (₹) | R7: Expense ₹/kg | S7: Expenses (₹) | T7: Total Cost (₹) | U7: Profit (₹) | V7: Profit / raw kg (₹) | W7: Freezing Charges ovr | X7: Polythene ovr | Y7: Cartons ovr | Z7: Loading ovr | AA7: C&F Charges ovr | AB7: Freight ovr | AC7: THC ovr | AD7: Shipment Expenses ovr | AE7: Preship Survey ovr | AF7: Nego. Int. ovr | AG7: Neg. Exp. ovr | AH7: Prop. Staff ovr | AI7: Other unseen ovr
A8: C 1374 | B8: 46258 | C8: 46253 | D8: FRIENDS FISHERIES KARWAR | F8: 5991 | G8: 1258110 | H8: 45 | I8: 90 | J8: =IF($A8="","",$H8*$F8) -> 269595 | K8: =IF($A8="","",$G8+$J8) -> 1527705 | L8: =IF(OR($A8="",$F8=0),"",$K8/$F8) -> 255 | M8: =IF($A8="","",SUMIF('Lot Entry'!$A$7:$A$2000,$A8,'Lot Entry'!$H$7:$H$2000)) -> 2706 | N8: =IF($A8="","",SUMIF('Lot Entry'!$A$7:$A$2000,$A8,'Lot Entry'!$I$7:$I$2000)) -> 2947.85 | O8: =IF(OR($A8="",$F8=0),"",$N8/$F8) -> 0.4920464 | P8: =IF($A8="","",SUMIF('Lot Entry'!$A$7:$A$2000,$A8,'Lot Entry'!$J$7:$J$2000)) -> 18581 | Q8: =IF($A8="","",$P8*$I8) -> 1672290 | R8: =IF($A8="","",IF(W8="",Expenses!$B$6,W8)+IF(X8="",Expenses!$B$7,X8)+IF(Y8="",Expenses!$B$8,Y8)+IF(Z8="",Expenses!$B$9,Z8)+IF(AA8="",Expenses!$B$10,AA8)+IF(AB8="",Expenses!$B$11,AB8)+IF(AC8="",Expenses!$B$12,AC8)+IF(AD8="",Expenses!$B$13,AD8)+IF(AE8="",Expenses!$B$14,AE8)+IF(AF8="",Expenses!$B$15,AF8)+IF(AG8="",Expenses!$B$16,AG8)+IF(AH8="",Expenses!$B$17,AH8)+IF(AI8="",Expenses!$B$18,AI8)) -> 39.7 | S8: =IF($A8="","",$R8*$M8) -> 107428.2 | T8: =IF($A8="","",$K8+$S8) -> 1635133.2 | U8: =IF($A8="","",$Q8-$T8) -> 37156.8 | V8: =IF(OR($A8="",$F8=0),"",$U8/$F8) -> 6.2021032
J9: =IF($A9="","",$H9*$F9) | K9: =IF($A9="","",$G9+$J9) | L9: =IF(OR($A9="",$F9=0),"",$K9/$F9) | M9: =IF($A9="","",SUMIF('Lot Entry'!$A$7:$A$2000,$A9,'Lot Entry'!$H$7:$H$2000)) | N9: =IF($A9="","",SUMIF('Lot Entry'!$A$7:$A$2000,$A9,'Lot Entry'!$I$7:$I$2000)) | O9: =IF(OR($A9="",$F9=0),"",$N9/$F9) | P9: =IF($A9="","",SUMIF('Lot Entry'!$A$7:$A$2000,$A9,'Lot Entry'!$J$7:$J$2000)) | Q9: =IF($A9="","",$P9*$I9) | R9: =IF($A9="","",IF(W9="",Expenses!$B$6,W9)+IF(X9="",Expenses!$B$7,X9)+IF(Y9="",Expenses!$B$8,Y9)+IF(Z9="",Expenses!$B$9,Z9)+IF(AA9="",Expenses!$B$10,AA9)+IF(AB9="",Expenses!$B$11,AB9)+IF(AC9="",Expenses!$B$12,AC9)+IF(AD9="",Expenses!$B$13,AD9)+IF(AE9="",Expenses!$B$14,AE9)+IF(AF9="",Expenses!$B$15,AF9)+IF(AG9="",Expenses!$B$16,AG9)+IF(AH9="",Expenses!$B$17,AH9)+IF(AI9="",Expenses!$B$18,AI9)) | S9: =IF($A9="","",$R9*$M9) | T9: =IF($A9="","",$K9+$S9) | U9: =IF($A9="","",$Q9-$T9) | V9: =IF(OR($A9="",$F9=0),"",$U9/$F9)
J10: =IF($A10="","",$H10*$F10) | K10: =IF($A10="","",$G10+$J10) | L10: =IF(OR($A10="",$F10=0),"",$K10/$F10) | M10: =IF($A10="","",SUMIF('Lot Entry'!$A$7:$A$2000,$A10,'Lot Entry'!$H$7:$H$2000)) | N10: =IF($A10="","",SUMIF('Lot Entry'!$A$7:$A$2000,$A10,'Lot Entry'!$I$7:$I$2000)) | O10: =IF(OR($A10="",$F10=0),"",$N10/$F10) | P10: =IF($A10="","",SUMIF('Lot Entry'!$A$7:$A$2000,$A10,'Lot Entry'!$J$7:$J$2000)) | Q10: =IF($A10="","",$P10*$I10) | R10: =IF($A10="","",IF(W10="",Expenses!$B$6,W10)+IF(X10="",Expenses!$B$7,X10)+IF(Y10="",Expenses!$B$8,Y10)+IF(Z10="",Expenses!$B$9,Z10)+IF(AA10="",Expenses!$B$10,AA10)+IF(AB10="",Expenses!$B$11,AB10)+IF(AC10="",Expenses!$B$12,AC10)+IF(AD10="",Expenses!$B$13,AD10)+IF(AE10="",Expenses!$B$14,AE10)+IF(AF10="",Expenses!$B$15,AF10)+IF(AG10="",Expenses!$B$16,AG10)+IF(AH10="",Expenses!$B$17,AH10)+IF(AI10="",Expenses!$B$18,AI10)) | S10: =IF($A10="","",$R10*$M10) | T10: =IF($A10="","",$K10+$S10) | U10: =IF($A10="","",$Q10-$T10) | V10: =IF(OR($A10="",$F10=0),"",$U10/$F10)
J11: =IF($A11="","",$H11*$F11) | K11: =IF($A11="","",$G11+$J11) | L11: =IF(OR($A11="",$F11=0),"",$K11/$F11) | M11: =IF($A11="","",SUMIF('Lot Entry'!$A$7:$A$2000,$A11,'Lot Entry'!$H$7:$H$2000)) | N11: =IF($A11="","",SUMIF('Lot Entry'!$A$7:$A$2000,$A11,'Lot Entry'!$I$7:$I$2000)) | O11: =IF(OR($A11="",$F11=0),"",$N11/$F11) | P11: =IF($A11="","",SUMIF('Lot Entry'!$A$7:$A$2000,$A11,'Lot Entry'!$J$7:$J$2000)) | Q11: =IF($A11="","",$P11*$I11) | R11: =IF($A11="","",IF(W11="",Expenses!$B$6,W11)+IF(X11="",Expenses!$B$7,X11)+IF(Y11="",Expenses!$B$8,Y11)+IF(Z11="",Expenses!$B$9,Z11)+IF(AA11="",Expenses!$B$10,AA11)+IF(AB11="",Expenses!$B$11,AB11)+IF(AC11="",Expenses!$B$12,AC11)+IF(AD11="",Expenses!$B$13,AD11)+IF(AE11="",Expenses!$B$14,AE11)+IF(AF11="",Expenses!$B$15,AF11)+IF(AG11="",Expenses!$B$16,AG11)+IF(AH11="",Expenses!$B$17,AH11)+IF(AI11="",Expenses!$B$18,AI11)) | S11: =IF($A11="","",$R11*$M11) | T11: =IF($A11="","",$K11+$S11) | U11: =IF($A11="","",$Q11-$T11) | V11: =IF(OR($A11="",$F11=0),"",$U11/$F11)
J12: =IF($A12="","",$H12*$F12) | K12: =IF($A12="","",$G12+$J12) | L12: =IF(OR($A12="",$F12=0),"",$K12/$F12) | M12: =IF($A12="","",SUMIF('Lot Entry'!$A$7:$A$2000,$A12,'Lot Entry'!$H$7:$H$2000)) | N12: =IF($A12="","",SUMIF('Lot Entry'!$A$7:$A$2000,$A12,'Lot Entry'!$I$7:$I$2000)) | O12: =IF(OR($A12="",$F12=0),"",$N12/$F12) | P12: =IF($A12="","",SUMIF('Lot Entry'!$A$7:$A$2000,$A12,'Lot Entry'!$J$7:$J$2000)) | Q12: =IF($A12="","",$P12*$I12) | R12: =IF($A12="","",IF(W12="",Expenses!$B$6,W12)+IF(X12="",Expenses!$B$7,X12)+IF(Y12="",Expenses!$B$8,Y12)+IF(Z12="",Expenses!$B$9,Z12)+IF(AA12="",Expenses!$B$10,AA12)+IF(AB12="",Expenses!$B$11,AB12)+IF(AC12="",Expenses!$B$12,AC12)+IF(AD12="",Expenses!$B$13,AD12)+IF(AE12="",Expenses!$B$14,AE12)+IF(AF12="",Expenses!$B$15,AF12)+IF(AG12="",Expenses!$B$16,AG12)+IF(AH12="",Expenses!$B$17,AH12)+IF(AI12="",Expenses!$B$18,AI12)) | S12: =IF($A12="","",$R12*$M12) | T12: =IF($A12="","",$K12+$S12) | U12: =IF($A12="","",$Q12-$T12) | V12: =IF(OR($A12="",$F12=0),"",$U12/$F12)
J13: =IF($A13="","",$H13*$F13) | K13: =IF($A13="","",$G13+$J13) | L13: =IF(OR($A13="",$F13=0),"",$K13/$F13) | M13: =IF($A13="","",SUMIF('Lot Entry'!$A$7:$A$2000,$A13,'Lot Entry'!$H$7:$H$2000)) | N13: =IF($A13="","",SUMIF('Lot Entry'!$A$7:$A$2000,$A13,'Lot Entry'!$I$7:$I$2000)) | O13: =IF(OR($A13="",$F13=0),"",$N13/$F13) | P13: =IF($A13="","",SUMIF('Lot Entry'!$A$7:$A$2000,$A13,'Lot Entry'!$J$7:$J$2000)) | Q13: =IF($A13="","",$P13*$I13) | R13: =IF($A13="","",IF(W13="",Expenses!$B$6,W13)+IF(X13="",Expenses!$B$7,X13)+IF(Y13="",Expenses!$B$8,Y13)+IF(Z13="",Expenses!$B$9,Z13)+IF(AA13="",Expenses!$B$10,AA13)+IF(AB13="",Expenses!$B$11,AB13)+IF(AC13="",Expenses!$B$12,AC13)+IF(AD13="",Expenses!$B$13,AD13)+IF(AE13="",Expenses!$B$14,AE13)+IF(AF13="",Expenses!$B$15,AF13)+IF(AG13="",Expenses!$B$16,AG13)+IF(AH13="",Expenses!$B$17,AH13)+IF(AI13="",Expenses!$B$18,AI13)) | S13: =IF($A13="","",$R13*$M13) | T13: =IF($A13="","",$K13+$S13) | U13: =IF($A13="","",$Q13-$T13) | V13: =IF(OR($A13="",$F13=0),"",$U13/$F13)
J14: =IF($A14="","",$H14*$F14) | K14: =IF($A14="","",$G14+$J14) | L14: =IF(OR($A14="",$F14=0),"",$K14/$F14) | M14: =IF($A14="","",SUMIF('Lot Entry'!$A$7:$A$2000,$A14,'Lot Entry'!$H$7:$H$2000)) | N14: =IF($A14="","",SUMIF('Lot Entry'!$A$7:$A$2000,$A14,'Lot Entry'!$I$7:$I$2000)) | O14: =IF(OR($A14="",$F14=0),"",$N14/$F14) | P14: =IF($A14="","",SUMIF('Lot Entry'!$A$7:$A$2000,$A14,'Lot Entry'!$J$7:$J$2000)) | Q14: =IF($A14="","",$P14*$I14) | R14: =IF($A14="","",IF(W14="",Expenses!$B$6,W14)+IF(X14="",Expenses!$B$7,X14)+IF(Y14="",Expenses!$B$8,Y14)+IF(Z14="",Expenses!$B$9,Z14)+IF(AA14="",Expenses!$B$10,AA14)+IF(AB14="",Expenses!$B$11,AB14)+IF(AC14="",Expenses!$B$12,AC14)+IF(AD14="",Expenses!$B$13,AD14)+IF(AE14="",Expenses!$B$14,AE14)+IF(AF14="",Expenses!$B$15,AF14)+IF(AG14="",Expenses!$B$16,AG14)+IF(AH14="",Expenses!$B$17,AH14)+IF(AI14="",Expenses!$B$18,AI14)) | S14: =IF($A14="","",$R14*$M14) | T14: =IF($A14="","",$K14+$S14) | U14: =IF($A14="","",$Q14-$T14) | V14: =IF(OR($A14="",$F14=0),"",$U14/$F14)
J15: =IF($A15="","",$H15*$F15) | K15: =IF($A15="","",$G15+$J15) | L15: =IF(OR($A15="",$F15=0),"",$K15/$F15) | M15: =IF($A15="","",SUMIF('Lot Entry'!$A$7:$A$2000,$A15,'Lot Entry'!$H$7:$H$2000)) | N15: =IF($A15="","",SUMIF('Lot Entry'!$A$7:$A$2000,$A15,'Lot Entry'!$I$7:$I$2000)) | O15: =IF(OR($A15="",$F15=0),"",$N15/$F15) | P15: =IF($A15="","",SUMIF('Lot Entry'!$A$7:$A$2000,$A15,'Lot Entry'!$J$7:$J$2000)) | Q15: =IF($A15="","",$P15*$I15) | R15: =IF($A15="","",IF(W15="",Expenses!$B$6,W15)+IF(X15="",Expenses!$B$7,X15)+IF(Y15="",Expenses!$B$8,Y15)+IF(Z15="",Expenses!$B$9,Z15)+IF(AA15="",Expenses!$B$10,AA15)+IF(AB15="",Expenses!$B$11,AB15)+IF(AC15="",Expenses!$B$12,AC15)+IF(AD15="",Expenses!$B$13,AD15)+IF(AE15="",Expenses!$B$14,AE15)+IF(AF15="",Expenses!$B$15,AF15)+IF(AG15="",Expenses!$B$16,AG15)+IF(AH15="",Expenses!$B$17,AH15)+IF(AI15="",Expenses!$B$18,AI15)) | S15: =IF($A15="","",$R15*$M15) | T15: =IF($A15="","",$K15+$S15) | U15: =IF($A15="","",$Q15-$T15) | V15: =IF(OR($A15="",$F15=0),"",$U15/$F15)
J16: =IF($A16="","",$H16*$F16) | K16: =IF($A16="","",$G16+$J16) | L16: =IF(OR($A16="",$F16=0),"",$K16/$F16) | M16: =IF($A16="","",SUMIF('Lot Entry'!$A$7:$A$2000,$A16,'Lot Entry'!$H$7:$H$2000)) | N16: =IF($A16="","",SUMIF('Lot Entry'!$A$7:$A$2000,$A16,'Lot Entry'!$I$7:$I$2000)) | O16: =IF(OR($A16="",$F16=0),"",$N16/$F16) | P16: =IF($A16="","",SUMIF('Lot Entry'!$A$7:$A$2000,$A16,'Lot Entry'!$J$7:$J$2000)) | Q16: =IF($A16="","",$P16*$I16) | R16: =IF($A16="","",IF(W16="",Expenses!$B$6,W16)+IF(X16="",Expenses!$B$7,X16)+IF(Y16="",Expenses!$B$8,Y16)+IF(Z16="",Expenses!$B$9,Z16)+IF(AA16="",Expenses!$B$10,AA16)+IF(AB16="",Expenses!$B$11,AB16)+IF(AC16="",Expenses!$B$12,AC16)+IF(AD16="",Expenses!$B$13,AD16)+IF(AE16="",Expenses!$B$14,AE16)+IF(AF16="",Expenses!$B$15,AF16)+IF(AG16="",Expenses!$B$16,AG16)+IF(AH16="",Expenses!$B$17,AH16)+IF(AI16="",Expenses!$B$18,AI16)) | S16: =IF($A16="","",$R16*$M16) | T16: =IF($A16="","",$K16+$S16) | U16: =IF($A16="","",$Q16-$T16) | V16: =IF(OR($A16="",$F16=0),"",$U16/$F16)
J17: =IF($A17="","",$H17*$F17) | K17: =IF($A17="","",$G17+$J17) | L17: =IF(OR($A17="",$F17=0),"",$K17/$F17) | M17: =IF($A17="","",SUMIF('Lot Entry'!$A$7:$A$2000,$A17,'Lot Entry'!$H$7:$H$2000)) | N17: =IF($A17="","",SUMIF('Lot Entry'!$A$7:$A$2000,$A17,'Lot Entry'!$I$7:$I$2000)) | O17: =IF(OR($A17="",$F17=0),"",$N17/$F17) | P17: =IF($A17="","",SUMIF('Lot Entry'!$A$7:$A$2000,$A17,'Lot Entry'!$J$7:$J$2000)) | Q17: =IF($A17="","",$P17*$I17) | R17: =IF($A17="","",IF(W17="",Expenses!$B$6,W17)+IF(X17="",Expenses!$B$7,X17)+IF(Y17="",Expenses!$B$8,Y17)+IF(Z17="",Expenses!$B$9,Z17)+IF(AA17="",Expenses!$B$10,AA17)+IF(AB17="",Expenses!$B$11,AB17)+IF(AC17="",Expenses!$B$12,AC17)+IF(AD17="",Expenses!$B$13,AD17)+IF(AE17="",Expenses!$B$14,AE17)+IF(AF17="",Expenses!$B$15,AF17)+IF(AG17="",Expenses!$B$16,AG17)+IF(AH17="",Expenses!$B$17,AH17)+IF(AI17="",Expenses!$B$18,AI17)) | S17: =IF($A17="","",$R17*$M17) | T17: =IF($A17="","",$K17+$S17) | U17: =IF($A17="","",$Q17-$T17) | V17: =IF(OR($A17="",$F17=0),"",$U17/$F17)
J18: =IF($A18="","",$H18*$F18) | K18: =IF($A18="","",$G18+$J18) | L18: =IF(OR($A18="",$F18=0),"",$K18/$F18) | M18: =IF($A18="","",SUMIF('Lot Entry'!$A$7:$A$2000,$A18,'Lot Entry'!$H$7:$H$2000)) | N18: =IF($A18="","",SUMIF('Lot Entry'!$A$7:$A$2000,$A18,'Lot Entry'!$I$7:$I$2000)) | O18: =IF(OR($A18="",$F18=0),"",$N18/$F18) | P18: =IF($A18="","",SUMIF('Lot Entry'!$A$7:$A$2000,$A18,'Lot Entry'!$J$7:$J$2000)) | Q18: =IF($A18="","",$P18*$I18) | R18: =IF($A18="","",IF(W18="",Expenses!$B$6,W18)+IF(X18="",Expenses!$B$7,X18)+IF(Y18="",Expenses!$B$8,Y18)+IF(Z18="",Expenses!$B$9,Z18)+IF(AA18="",Expenses!$B$10,AA18)+IF(AB18="",Expenses!$B$11,AB18)+IF(AC18="",Expenses!$B$12,AC18)+IF(AD18="",Expenses!$B$13,AD18)+IF(AE18="",Expenses!$B$14,AE18)+IF(AF18="",Expenses!$B$15,AF18)+IF(AG18="",Expenses!$B$16,AG18)+IF(AH18="",Expenses!$B$17,AH18)+IF(AI18="",Expenses!$B$18,AI18)) | S18: =IF($A18="","",$R18*$M18) | T18: =IF($A18="","",$K18+$S18) | U18: =IF($A18="","",$Q18-$T18) | V18: =IF(OR($A18="",$F18=0),"",$U18/$F18)
J19: =IF($A19="","",$H19*$F19) | K19: =IF($A19="","",$G19+$J19) | L19: =IF(OR($A19="",$F19=0),"",$K19/$F19) | M19: =IF($A19="","",SUMIF('Lot Entry'!$A$7:$A$2000,$A19,'Lot Entry'!$H$7:$H$2000)) | N19: =IF($A19="","",SUMIF('Lot Entry'!$A$7:$A$2000,$A19,'Lot Entry'!$I$7:$I$2000)) | O19: =IF(OR($A19="",$F19=0),"",$N19/$F19) | P19: =IF($A19="","",SUMIF('Lot Entry'!$A$7:$A$2000,$A19,'Lot Entry'!$J$7:$J$2000)) | Q19: =IF($A19="","",$P19*$I19) | R19: =IF($A19="","",IF(W19="",Expenses!$B$6,W19)+IF(X19="",Expenses!$B$7,X19)+IF(Y19="",Expenses!$B$8,Y19)+IF(Z19="",Expenses!$B$9,Z19)+IF(AA19="",Expenses!$B$10,AA19)+IF(AB19="",Expenses!$B$11,AB19)+IF(AC19="",Expenses!$B$12,AC19)+IF(AD19="",Expenses!$B$13,AD19)+IF(AE19="",Expenses!$B$14,AE19)+IF(AF19="",Expenses!$B$15,AF19)+IF(AG19="",Expenses!$B$16,AG19)+IF(AH19="",Expenses!$B$17,AH19)+IF(AI19="",Expenses!$B$18,AI19)) | S19: =IF($A19="","",$R19*$M19) | T19: =IF($A19="","",$K19+$S19) | U19: =IF($A19="","",$Q19-$T19) | V19: =IF(OR($A19="",$F19=0),"",$U19/$F19)
J20: =IF($A20="","",$H20*$F20) | K20: =IF($A20="","",$G20+$J20) | L20: =IF(OR($A20="",$F20=0),"",$K20/$F20) | M20: =IF($A20="","",SUMIF('Lot Entry'!$A$7:$A$2000,$A20,'Lot Entry'!$H$7:$H$2000)) | N20: =IF($A20="","",SUMIF('Lot Entry'!$A$7:$A$2000,$A20,'Lot Entry'!$I$7:$I$2000)) | O20: =IF(OR($A20="",$F20=0),"",$N20/$F20) | P20: =IF($A20="","",SUMIF('Lot Entry'!$A$7:$A$2000,$A20,'Lot Entry'!$J$7:$J$2000)) | Q20: =IF($A20="","",$P20*$I20) | R20: =IF($A20="","",IF(W20="",Expenses!$B$6,W20)+IF(X20="",Expenses!$B$7,X20)+IF(Y20="",Expenses!$B$8,Y20)+IF(Z20="",Expenses!$B$9,Z20)+IF(AA20="",Expenses!$B$10,AA20)+IF(AB20="",Expenses!$B$11,AB20)+IF(AC20="",Expenses!$B$12,AC20)+IF(AD20="",Expenses!$B$13,AD20)+IF(AE20="",Expenses!$B$14,AE20)+IF(AF20="",Expenses!$B$15,AF20)+IF(AG20="",Expenses!$B$16,AG20)+IF(AH20="",Expenses!$B$17,AH20)+IF(AI20="",Expenses!$B$18,AI20)) | S20: =IF($A20="","",$R20*$M20) | T20: =IF($A20="","",$K20+$S20) | U20: =IF($A20="","",$Q20-$T20) | V20: =IF(OR($A20="",$F20=0),"",$U20/$F20)
... J200: =IF($A200="","",$H200*$F200) | K200: =IF($A200="","",$G200+$J200) | L200: =IF(OR($A200="",$F200=0),"",$K200/$F200) | M200: =IF($A200="","",SUMIF('Lot Entry'!$A$7:$A$2000,$A200,'Lot Entry'!$H$7:$H$2000)) | N200: =IF($A200="","",SUMIF('Lot Entry'!$A$7:$A$2000,$A200,'Lot Entry'!$I$7:$I$2000)) | O200: =IF(OR($A200="",$F200=0),"",$N200/$F200) | P200: =IF($A200="","",SUMIF('Lot Entry'!$A$7:$A$2000,$A200,'Lot Entry'!$J$7:$J$2000)) | Q200: =IF($A200="","",$P200*$I200) | R200: =IF($A200="","",IF(W200="",Expenses!$B$6,W200)+IF(X200="",Expenses!$B$7,X200)+IF(Y200="",Expenses!$B$8,Y200)+IF(Z200="",Expenses!$B$9,Z200)+IF(AA200="",Expenses!$B$10,AA200)+IF(AB200="",Expenses!$B$11,AB200)+IF(AC200="",Expenses!$B$12,AC200)+IF(AD200="",Expenses!$B$13,AD200)+IF(AE200="",Expenses!$B$14,AE200)+IF(AF200="",Expenses!$B$15,AF200)+IF(AG200="",Expenses!$B$16,AG200)+IF(AH200="",Expenses!$B$17,AH200)+IF(AI200="",Expenses!$B$18,AI200)) | S200: =IF($A200="","",$R200*$M200) | T200: =IF($A200="","",$K200+$S200) | U200: =IF($A200="","",$Q200-$T200) | V200: =IF(OR($A200="",$F200=0),"",$U200/$F200)

Sheet Lot Entry
A1: PREMIER EXPORTS INTERNATIONAL
A2: LOT ENTRY — ONE ROW PER GRADE PRODUCED FROM A LOT
A4: Pick the lot and the spec/grade, then enter slabs, the net kg per slab (2 unless the buyer differs), the gross weight per slab and the sale price per kg. | N4: Lines whose lot is not on the Lots sheet: | R4: =SUMPRODUCT((A7:A2000<>"")*(COUNTIF(Lots!$A$8:$A$200,A7:A2000)=0)) -> 0 | S4: ← must stay at 0
A6: Lot No | B6: Spec | C6: Grade | D6: Slabs | E6: Net kg / slab | F6: Gross wt / slab | G6: Price (US$/kg) | H6: Packed kg | I6: F.WT (kg) | J6: Amount (US$) | L6: Lot seq (do not edit)
A7: C 1374 | B7: PVN PMS | C7: 80/120 | D7: 617 | E7: 2 | F7: 2.15 | G7: 7 | H7: =IF($A7="","",$D7*$E7) -> 1234 | I7: =IF($A7="","",$D7*$F7) -> 1326.55 | J7: =IF($A7="","",$H7*$G7) -> 8638 | L7: =IF($A7="","",$A7&"#"&COUNTIF($A$7:$A7,$A7)) -> C 1374#1
A8: C 1374 | B8: PVN BD | C8: 100/200 PD | D8: 629 | E8: 2 | F8: 2.2 | G8: 7 | H8: =IF($A8="","",$D8*$E8) -> 1258 | I8: =IF($A8="","",$D8*$F8) -> 1383.8 | J8: =IF($A8="","",$H8*$G8) -> 8806 | L8: =IF($A8="","",$A8&"#"&COUNTIF($A$7:$A8,$A8)) -> C 1374#2
A9: C 1374 | B9: PVN BD | C9: 200/300 PUD | D9: 86 | E9: 2 | F9: 2.2 | G9: 6 | H9: =IF($A9="","",$D9*$E9) -> 172 | I9: =IF($A9="","",$D9*$F9) -> 189.2 | J9: =IF($A9="","",$H9*$G9) -> 1032 | L9: =IF($A9="","",$A9&"#"&COUNTIF($A$7:$A9,$A9)) -> C 1374#3
A10: C 1374 | B10: EU | C10: BKN | D10: 21 | E10: 2 | F10: 2.3 | G10: 2.5 | H10: =IF($A10="","",$D10*$E10) -> 42 | I10: =IF($A10="","",$D10*$F10) -> 48.3 | J10: =IF($A10="","",$H10*$G10) -> 105 | L10: =IF($A10="","",$A10&"#"&COUNTIF($A$7:$A10,$A10)) -> C 1374#4
H11: =IF($A11="","",$D11*$E11) | I11: =IF($A11="","",$D11*$F11) | J11: =IF($A11="","",$H11*$G11) | L11: =IF($A11="","",$A11&"#"&COUNTIF($A$7:$A11,$A11))
H12: =IF($A12="","",$D12*$E12) | I12: =IF($A12="","",$D12*$F12) | J12: =IF($A12="","",$H12*$G12) | L12: =IF($A12="","",$A12&"#"&COUNTIF($A$7:$A12,$A12))
H13: =IF($A13="","",$D13*$E13) | I13: =IF($A13="","",$D13*$F13) | J13: =IF($A13="","",$H13*$G13) | L13: =IF($A13="","",$A13&"#"&COUNTIF($A$7:$A13,$A13))
H14: =IF($A14="","",$D14*$E14) | I14: =IF($A14="","",$D14*$F14) | J14: =IF($A14="","",$H14*$G14) | L14: =IF($A14="","",$A14&"#"&COUNTIF($A$7:$A14,$A14))
H15: =IF($A15="","",$D15*$E15) | I15: =IF($A15="","",$D15*$F15) | J15: =IF($A15="","",$H15*$G15) | L15: =IF($A15="","",$A15&"#"&COUNTIF($A$7:$A15,$A15))
H16: =IF($A16="","",$D16*$E16) | I16: =IF($A16="","",$D16*$F16) | J16: =IF($A16="","",$H16*$G16) | L16: =IF($A16="","",$A16&"#"&COUNTIF($A$7:$A16,$A16))
H17: =IF($A17="","",$D17*$E17) | I17: =IF($A17="","",$D17*$F17) | J17: =IF($A17="","",$H17*$G17) | L17: =IF($A17="","",$A17&"#"&COUNTIF($A$7:$A17,$A17))
H18: =IF($A18="","",$D18*$E18) | I18: =IF($A18="","",$D18*$F18) | J18: =IF($A18="","",$H18*$G18) | L18: =IF($A18="","",$A18&"#"&COUNTIF($A$7:$A18,$A18))
H19: =IF($A19="","",$D19*$E19) | I19: =IF($A19="","",$D19*$F19) | J19: =IF($A19="","",$H19*$G19) | L19: =IF($A19="","",$A19&"#"&COUNTIF($A$7:$A19,$A19))
H20: =IF($A20="","",$D20*$E20) | I20: =IF($A20="","",$D20*$F20) | J20: =IF($A20="","",$H20*$G20) | L20: =IF($A20="","",$A20&"#"&COUNTIF($A$7:$A20,$A20))
H21: =IF($A21="","",$D21*$E21) | I21: =IF($A21="","",$D21*$F21) | J21: =IF($A21="","",$H21*$G21) | L21: =IF($A21="","",$A21&"#"&COUNTIF($A$7:$A21,$A21))
H22: =IF($A22="","",$D22*$E22) | I22: =IF($A22="","",$D22*$F22) | J22: =IF($A22="","",$H22*$G22) | L22: =IF($A22="","",$A22&"#"&COUNTIF($A$7:$A22,$A22))
... H400: =IF($A400="","",$D400*$E400) | I400: =IF($A400="","",$D400*$F400) | J400: =IF($A400="","",$H400*$G400) | L400: =IF($A400="","",$A400&"#"&COUNTIF($A$7:$A400,$A400))

Sheet Lot Report
B1: Premier Exports International | E1: AP X/453, NH-66 Highway, Chandiroor P.O., | H1: =IFERROR(MATCH($F$5,Lots!$A$8:$A$200,0),"") -> 1
E2: Aroor, Alappuzha, Kerala - 688 537, India
E3: GSTIN 32AADFP3158P1ZZ
A5: PURCHASE & PROCESSING REPORT | F5: C 1374
A6: YIELD AND COST ANALYSIS BY LOT | F6: LOT NO — TYPE OR PICK
A8: Purchase date | B8: =IF($H$1="","",INDEX(Lots!$C$8:$C$200,$H$1)) -> 46253 | E8: Purchases (kg) | G8: =IF($H$1="","",INDEX(Lots!$F$8:$F$200,$H$1)) -> 5991
A9: Party | B9: =IF($H$1="","",IF(INDEX(Lots!$D$8:$D$200,$H$1)=0,"",INDEX(Lots!$D$8:$D$200,$H$1))) -> FRIENDS FISHERIES KARWAR | E9: Purchases (₹) | G9: =IF($H$1="","",INDEX(Lots!$G$8:$G$200,$H$1)) -> 1258110
A10: Supervisor | B10: =IF($H$1="","",IF(INDEX(Lots!$E$8:$E$200,$H$1)=0,"",INDEX(Lots!$E$8:$E$200,$H$1))) | E10: Peeling @ ₹/kg | G10: =IF($H$1="","",INDEX(Lots!$H$8:$H$200,$H$1)) -> 45
A11: Statement date | B11: =IF($H$1="","",INDEX(Lots!$B$8:$B$200,$H$1)) -> 46258 | E11: Peeling (₹) | G11: =IF($H$1="","",INDEX(Lots!$J$8:$J$200,$H$1)) -> 269595
E12: Total raw cost (₹) | G12: =IF($H$1="","",INDEX(Lots!$K$8:$K$200,$H$1)) -> 1527705
E13: Average price / kg (₹) | G13: =IF($H$1="","",INDEX(Lots!$L$8:$L$200,$H$1)) -> 255
A15: YIELD | B15: NET PROFIT / RAW KG | D15: SALES VALUE (₹) | F15: NET PROFIT (₹)
A16: =IF($H$1="","",INDEX(Lots!$O$8:$O$200,$H$1)) -> 0.4920464 | B16: =IF($H$1="","",INDEX(Lots!$V$8:$V$200,$H$1)) -> 6.2021032 | D16: =IF($H$1="","",INDEX(Lots!$Q$8:$Q$200,$H$1)) -> 1672290 | F16: =IF($H$1="","",INDEX(Lots!$U$8:$U$200,$H$1)) -> 37156.8
A18: PRODUCTION BY GRADE
A19: Spec | B19: Grade | C19: Slabs | D19: Packed kg | E19: F.WT (kg) | F19: US$/kg | G19: Amount (US$)
A20: =IF($H20="","",INDEX('Lot Entry'!$B$7:$B$2000,$H20)) -> PVN PMS | B20: =IF($H20="","",INDEX('Lot Entry'!$C$7:$C$2000,$H20)) -> 80/120 | C20: =IF($H20="","",INDEX('Lot Entry'!$D$7:$D$2000,$H20)) -> 617 | D20: =IF($H20="","",INDEX('Lot Entry'!$H$7:$H$2000,$H20)) -> 1234 | E20: =IF($H20="","",INDEX('Lot Entry'!$I$7:$I$2000,$H20)) -> 1326.55 | F20: =IF($H20="","",INDEX('Lot Entry'!$G$7:$G$2000,$H20)) -> 7 | G20: =IF($H20="","",INDEX('Lot Entry'!$J$7:$J$2000,$H20)) -> 8638 | H20: =IFERROR(MATCH($F$5&"#"&1,'Lot Entry'!$L$7:$L$2000,0),"") -> 1
A21: =IF($H21="","",INDEX('Lot Entry'!$B$7:$B$2000,$H21)) -> PVN BD | B21: =IF($H21="","",INDEX('Lot Entry'!$C$7:$C$2000,$H21)) -> 100/200 PD | C21: =IF($H21="","",INDEX('Lot Entry'!$D$7:$D$2000,$H21)) -> 629 | D21: =IF($H21="","",INDEX('Lot Entry'!$H$7:$H$2000,$H21)) -> 1258 | E21: =IF($H21="","",INDEX('Lot Entry'!$I$7:$I$2000,$H21)) -> 1383.8 | F21: =IF($H21="","",INDEX('Lot Entry'!$G$7:$G$2000,$H21)) -> 7 | G21: =IF($H21="","",INDEX('Lot Entry'!$J$7:$J$2000,$H21)) -> 8806 | H21: =IFERROR(MATCH($F$5&"#"&2,'Lot Entry'!$L$7:$L$2000,0),"") -> 2
A22: =IF($H22="","",INDEX('Lot Entry'!$B$7:$B$2000,$H22)) -> PVN BD | B22: =IF($H22="","",INDEX('Lot Entry'!$C$7:$C$2000,$H22)) -> 200/300 PUD | C22: =IF($H22="","",INDEX('Lot Entry'!$D$7:$D$2000,$H22)) -> 86 | D22: =IF($H22="","",INDEX('Lot Entry'!$H$7:$H$2000,$H22)) -> 172 | E22: =IF($H22="","",INDEX('Lot Entry'!$I$7:$I$2000,$H22)) -> 189.2 | F22: =IF($H22="","",INDEX('Lot Entry'!$G$7:$G$2000,$H22)) -> 6 | G22: =IF($H22="","",INDEX('Lot Entry'!$J$7:$J$2000,$H22)) -> 1032 | H22: =IFERROR(MATCH($F$5&"#"&3,'Lot Entry'!$L$7:$L$2000,0),"") -> 3
A23: =IF($H23="","",INDEX('Lot Entry'!$B$7:$B$2000,$H23)) -> EU | B23: =IF($H23="","",INDEX('Lot Entry'!$C$7:$C$2000,$H23)) -> BKN | C23: =IF($H23="","",INDEX('Lot Entry'!$D$7:$D$2000,$H23)) -> 21 | D23: =IF($H23="","",INDEX('Lot Entry'!$H$7:$H$2000,$H23)) -> 42 | E23: =IF($H23="","",INDEX('Lot Entry'!$I$7:$I$2000,$H23)) -> 48.3 | F23: =IF($H23="","",INDEX('Lot Entry'!$G$7:$G$2000,$H23)) -> 2.5 | G23: =IF($H23="","",INDEX('Lot Entry'!$J$7:$J$2000,$H23)) -> 105 | H23: =IFERROR(MATCH($F$5&"#"&4,'Lot Entry'!$L$7:$L$2000,0),"") -> 4
A24: =IF($H24="","",INDEX('Lot Entry'!$B$7:$B$2000,$H24)) | B24: =IF($H24="","",INDEX('Lot Entry'!$C$7:$C$2000,$H24)) | C24: =IF($H24="","",INDEX('Lot Entry'!$D$7:$D$2000,$H24)) | D24: =IF($H24="","",INDEX('Lot Entry'!$H$7:$H$2000,$H24)) | E24: =IF($H24="","",INDEX('Lot Entry'!$I$7:$I$2000,$H24)) | F24: =IF($H24="","",INDEX('Lot Entry'!$G$7:$G$2000,$H24)) | G24: =IF($H24="","",INDEX('Lot Entry'!$J$7:$J$2000,$H24)) | H24: =IFERROR(MATCH($F$5&"#"&5,'Lot Entry'!$L$7:$L$2000,0),"")
A25: =IF($H25="","",INDEX('Lot Entry'!$B$7:$B$2000,$H25)) | B25: =IF($H25="","",INDEX('Lot Entry'!$C$7:$C$2000,$H25)) | C25: =IF($H25="","",INDEX('Lot Entry'!$D$7:$D$2000,$H25)) | D25: =IF($H25="","",INDEX('Lot Entry'!$H$7:$H$2000,$H25)) | E25: =IF($H25="","",INDEX('Lot Entry'!$I$7:$I$2000,$H25)) | F25: =IF($H25="","",INDEX('Lot Entry'!$G$7:$G$2000,$H25)) | G25: =IF($H25="","",INDEX('Lot Entry'!$J$7:$J$2000,$H25)) | H25: =IFERROR(MATCH($F$5&"#"&6,'Lot Entry'!$L$7:$L$2000,0),"")
A26: =IF($H26="","",INDEX('Lot Entry'!$B$7:$B$2000,$H26)) | B26: =IF($H26="","",INDEX('Lot Entry'!$C$7:$C$2000,$H26)) | C26: =IF($H26="","",INDEX('Lot Entry'!$D$7:$D$2000,$H26)) | D26: =IF($H26="","",INDEX('Lot Entry'!$H$7:$H$2000,$H26)) | E26: =IF($H26="","",INDEX('Lot Entry'!$I$7:$I$2000,$H26)) | F26: =IF($H26="","",INDEX('Lot Entry'!$G$7:$G$2000,$H26)) | G26: =IF($H26="","",INDEX('Lot Entry'!$J$7:$J$2000,$H26)) | H26: =IFERROR(MATCH($F$5&"#"&7,'Lot Entry'!$L$7:$L$2000,0),"")
A27: =IF($H27="","",INDEX('Lot Entry'!$B$7:$B$2000,$H27)) | B27: =IF($H27="","",INDEX('Lot Entry'!$C$7:$C$2000,$H27)) | C27: =IF($H27="","",INDEX('Lot Entry'!$D$7:$D$2000,$H27)) | D27: =IF($H27="","",INDEX('Lot Entry'!$H$7:$H$2000,$H27)) | E27: =IF($H27="","",INDEX('Lot Entry'!$I$7:$I$2000,$H27)) | F27: =IF($H27="","",INDEX('Lot Entry'!$G$7:$G$2000,$H27)) | G27: =IF($H27="","",INDEX('Lot Entry'!$J$7:$J$2000,$H27)) | H27: =IFERROR(MATCH($F$5&"#"&8,'Lot Entry'!$L$7:$L$2000,0),"")
A28: =IF($H28="","",INDEX('Lot Entry'!$B$7:$B$2000,$H28)) | B28: =IF($H28="","",INDEX('Lot Entry'!$C$7:$C$2000,$H28)) | C28: =IF($H28="","",INDEX('Lot Entry'!$D$7:$D$2000,$H28)) | D28: =IF($H28="","",INDEX('Lot Entry'!$H$7:$H$2000,$H28)) | E28: =IF($H28="","",INDEX('Lot Entry'!$I$7:$I$2000,$H28)) | F28: =IF($H28="","",INDEX('Lot Entry'!$G$7:$G$2000,$H28)) | G28: =IF($H28="","",INDEX('Lot Entry'!$J$7:$J$2000,$H28)) | H28: =IFERROR(MATCH($F$5&"#"&9,'Lot Entry'!$L$7:$L$2000,0),"")
A29: =IF($H29="","",INDEX('Lot Entry'!$B$7:$B$2000,$H29)) | B29: =IF($H29="","",INDEX('Lot Entry'!$C$7:$C$2000,$H29)) | C29: =IF($H29="","",INDEX('Lot Entry'!$D$7:$D$2000,$H29)) | D29: =IF($H29="","",INDEX('Lot Entry'!$H$7:$H$2000,$H29)) | E29: =IF($H29="","",INDEX('Lot Entry'!$I$7:$I$2000,$H29)) | F29: =IF($H29="","",INDEX('Lot Entry'!$G$7:$G$2000,$H29)) | G29: =IF($H29="","",INDEX('Lot Entry'!$J$7:$J$2000,$H29)) | H29: =IFERROR(MATCH($F$5&"#"&10,'Lot Entry'!$L$7:$L$2000,0),"")
A30: =IF($H30="","",INDEX('Lot Entry'!$B$7:$B$2000,$H30)) | B30: =IF($H30="","",INDEX('Lot Entry'!$C$7:$C$2000,$H30)) | C30: =IF($H30="","",INDEX('Lot Entry'!$D$7:$D$2000,$H30)) | D30: =IF($H30="","",INDEX('Lot Entry'!$H$7:$H$2000,$H30)) | E30: =IF($H30="","",INDEX('Lot Entry'!$I$7:$I$2000,$H30)) | F30: =IF($H30="","",INDEX('Lot Entry'!$G$7:$G$2000,$H30)) | G30: =IF($H30="","",INDEX('Lot Entry'!$J$7:$J$2000,$H30)) | H30: =IFERROR(MATCH($F$5&"#"&11,'Lot Entry'!$L$7:$L$2000,0),"")
A31: =IF($H31="","",INDEX('Lot Entry'!$B$7:$B$2000,$H31)) | B31: =IF($H31="","",INDEX('Lot Entry'!$C$7:$C$2000,$H31)) | C31: =IF($H31="","",INDEX('Lot Entry'!$D$7:$D$2000,$H31)) | D31: =IF($H31="","",INDEX('Lot Entry'!$H$7:$H$2000,$H31)) | E31: =IF($H31="","",INDEX('Lot Entry'!$I$7:$I$2000,$H31)) | F31: =IF($H31="","",INDEX('Lot Entry'!$G$7:$G$2000,$H31)) | G31: =IF($H31="","",INDEX('Lot Entry'!$J$7:$J$2000,$H31)) | H31: =IFERROR(MATCH($F$5&"#"&12,'Lot Entry'!$L$7:$L$2000,0),"")
A32: TOTAL | C32: =SUM(C20:C31) -> 1353 | D32: =SUM(D20:D31) -> 2706 | E32: =SUM(E20:E31) -> 2947.85 | G32: =SUM(G20:G31) -> 18581
A33: =IF($H$1="","",IF(COUNTIF('Lot Entry'!$A$7:$A$2000,$F$5)>12,"Note: "&(COUNTIF('Lot Entry'!$A$7:$A$2000,$F$5)-12)&" further grade line(s) — see Lot Entry.",""))
A34: EXPENSES AND RESULT
A35: Expense head | C35: Rate ₹/kg | D35: Amount (₹)
A36: Freezing Charges | C36: =IF($H$1="","",IF(INDEX(Lots!$W$8:$W$200,$H$1)="",Expenses!$B$6,INDEX(Lots!$W$8:$W$200,$H$1))) -> 15 | D36: =IF($H$1="","",$C36*INDEX(Lots!$M$8:$M$200,$H$1)) -> 40590 | F36: Sales value (₹) | G36: =IF($H$1="","",INDEX(Lots!$Q$8:$Q$200,$H$1)) -> 1672290
A37: Polythene | C37: =IF($H$1="","",IF(INDEX(Lots!$X$8:$X$200,$H$1)="",Expenses!$B$7,INDEX(Lots!$X$8:$X$200,$H$1))) -> 1.94 | D37: =IF($H$1="","",$C37*INDEX(Lots!$M$8:$M$200,$H$1)) -> 5249.64 | F37: Less: total raw cost (₹) | G37: =IF($H$1="","",INDEX(Lots!$K$8:$K$200,$H$1)) -> 1527705
A38: Cartons | C38: =IF($H$1="","",IF(INDEX(Lots!$Y$8:$Y$200,$H$1)="",Expenses!$B$8,INDEX(Lots!$Y$8:$Y$200,$H$1))) -> 2.6 | D38: =IF($H$1="","",$C38*INDEX(Lots!$M$8:$M$200,$H$1)) -> 7035.6 | F38: Less: expenses (₹) | G38: =IF($H$1="","",INDEX(Lots!$S$8:$S$200,$H$1)) -> 107428.2
A39: Loading | C39: =IF($H$1="","",IF(INDEX(Lots!$Z$8:$Z$200,$H$1)="",Expenses!$B$9,INDEX(Lots!$Z$8:$Z$200,$H$1))) -> 0.15 | D39: =IF($H$1="","",$C39*INDEX(Lots!$M$8:$M$200,$H$1)) -> 405.9 | F39: Total cost (₹) | G39: =IF($H$1="","",INDEX(Lots!$T$8:$T$200,$H$1)) -> 1635133.2
A40: C&F Charges | C40: =IF($H$1="","",IF(INDEX(Lots!$AA$8:$AA$200,$H$1)="",Expenses!$B$10,INDEX(Lots!$AA$8:$AA$200,$H$1))) -> 0.75 | D40: =IF($H$1="","",$C40*INDEX(Lots!$M$8:$M$200,$H$1)) -> 2029.5 | F40: NET PROFIT (₹) | G40: =IF($H$1="","",INDEX(Lots!$U$8:$U$200,$H$1)) -> 37156.8
A41: Freight | C41: =IF($H$1="","",IF(INDEX(Lots!$AB$8:$AB$200,$H$1)="",Expenses!$B$11,INDEX(Lots!$AB$8:$AB$200,$H$1))) -> 10 | D41: =IF($H$1="","",$C41*INDEX(Lots!$M$8:$M$200,$H$1)) -> 27060 | F41: Net profit / raw kg (₹) | G41: =IF($H$1="","",INDEX(Lots!$V$8:$V$200,$H$1)) -> 6.2021032
A42: THC | C42: =IF($H$1="","",IF(INDEX(Lots!$AC$8:$AC$200,$H$1)="",Expenses!$B$12,INDEX(Lots!$AC$8:$AC$200,$H$1))) -> 1.75 | D42: =IF($H$1="","",$C42*INDEX(Lots!$M$8:$M$200,$H$1)) -> 4735.5
A43: Shipment Expenses | C43: =IF($H$1="","",IF(INDEX(Lots!$AD$8:$AD$200,$H$1)="",Expenses!$B$13,INDEX(Lots!$AD$8:$AD$200,$H$1))) -> 0.25 | D43: =IF($H$1="","",$C43*INDEX(Lots!$M$8:$M$200,$H$1)) -> 676.5
A44: Preship Survey | C44: =IF($H$1="","",IF(INDEX(Lots!$AE$8:$AE$200,$H$1)="",Expenses!$B$14,INDEX(Lots!$AE$8:$AE$200,$H$1))) -> 0.06 | D44: =IF($H$1="","",$C44*INDEX(Lots!$M$8:$M$200,$H$1)) -> 162.36
...

Sheet Summary
A1: PREMIER EXPORTS INTERNATIONAL
A2: ALL LOTS — YIELD AND PROFIT
A6: Lot No | B6: Purchase date | C6: Party | D6: Raw (kg) | E6: Yield % | F6: Avg price /kg (₹) | G6: Sales value (₹) | H6: Net profit (₹) | I6: Profit / raw kg (₹)
A7: =IF(Lots!$A$8="","",Lots!$A$8) -> C 1374 | B7: =IF(Lots!$A$8="","",Lots!$C$8) -> 46253 | C7: =IF(Lots!$A$8="","",Lots!$D$8) -> FRIENDS FISHERIES KARWAR | D7: =IF(Lots!$A$8="","",Lots!$F$8) -> 5991 | E7: =IF(Lots!$A$8="","",Lots!$O$8) -> 0.4920464 | F7: =IF(Lots!$A$8="","",Lots!$L$8) -> 255 | G7: =IF(Lots!$A$8="","",Lots!$Q$8) -> 1672290 | H7: =IF(Lots!$A$8="","",Lots!$U$8) -> 37156.8 | I7: =IF(Lots!$A$8="","",Lots!$V$8) -> 6.2021032
A8: =IF(Lots!$A$9="","",Lots!$A$9) | B8: =IF(Lots!$A$9="","",Lots!$C$9) | C8: =IF(Lots!$A$9="","",Lots!$D$9) | D8: =IF(Lots!$A$9="","",Lots!$F$9) | E8: =IF(Lots!$A$9="","",Lots!$O$9) | F8: =IF(Lots!$A$9="","",Lots!$L$9) | G8: =IF(Lots!$A$9="","",Lots!$Q$9) | H8: =IF(Lots!$A$9="","",Lots!$U$9) | I8: =IF(Lots!$A$9="","",Lots!$V$9)
A9: =IF(Lots!$A$10="","",Lots!$A$10) | B9: =IF(Lots!$A$10="","",Lots!$C$10) | C9: =IF(Lots!$A$10="","",Lots!$D$10) | D9: =IF(Lots!$A$10="","",Lots!$F$10) | E9: =IF(Lots!$A$10="","",Lots!$O$10) | F9: =IF(Lots!$A$10="","",Lots!$L$10) | G9: =IF(Lots!$A$10="","",Lots!$Q$10) | H9: =IF(Lots!$A$10="","",Lots!$U$10) | I9: =IF(Lots!$A$10="","",Lots!$V$10)
A10: =IF(Lots!$A$11="","",Lots!$A$11) | B10: =IF(Lots!$A$11="","",Lots!$C$11) | C10: =IF(Lots!$A$11="","",Lots!$D$11) | D10: =IF(Lots!$A$11="","",Lots!$F$11) | E10: =IF(Lots!$A$11="","",Lots!$O$11) | F10: =IF(Lots!$A$11="","",Lots!$L$11) | G10: =IF(Lots!$A$11="","",Lots!$Q$11) | H10: =IF(Lots!$A$11="","",Lots!$U$11) | I10: =IF(Lots!$A$11="","",Lots!$V$11)
A11: =IF(Lots!$A$12="","",Lots!$A$12) | B11: =IF(Lots!$A$12="","",Lots!$C$12) | C11: =IF(Lots!$A$12="","",Lots!$D$12) | D11: =IF(Lots!$A$12="","",Lots!$F$12) | E11: =IF(Lots!$A$12="","",Lots!$O$12) | F11: =IF(Lots!$A$12="","",Lots!$L$12) | G11: =IF(Lots!$A$12="","",Lots!$Q$12) | H11: =IF(Lots!$A$12="","",Lots!$U$12) | I11: =IF(Lots!$A$12="","",Lots!$V$12)
A12: =IF(Lots!$A$13="","",Lots!$A$13) | B12: =IF(Lots!$A$13="","",Lots!$C$13) | C12: =IF(Lots!$A$13="","",Lots!$D$13) | D12: =IF(Lots!$A$13="","",Lots!$F$13) | E12: =IF(Lots!$A$13="","",Lots!$O$13) | F12: =IF(Lots!$A$13="","",Lots!$L$13) | G12: =IF(Lots!$A$13="","",Lots!$Q$13) | H12: =IF(Lots!$A$13="","",Lots!$U$13) | I12: =IF(Lots!$A$13="","",Lots!$V$13)
A13: =IF(Lots!$A$14="","",Lots!$A$14) | B13: =IF(Lots!$A$14="","",Lots!$C$14) | C13: =IF(Lots!$A$14="","",Lots!$D$14) | D13: =IF(Lots!$A$14="","",Lots!$F$14) | E13: =IF(Lots!$A$14="","",Lots!$O$14) | F13: =IF(Lots!$A$14="","",Lots!$L$14) | G13: =IF(Lots!$A$14="","",Lots!$Q$14) | H13: =IF(Lots!$A$14="","",Lots!$U$14) | I13: =IF(Lots!$A$14="","",Lots!$V$14)
A14: =IF(Lots!$A$15="","",Lots!$A$15) | B14: =IF(Lots!$A$15="","",Lots!$C$15) | C14: =IF(Lots!$A$15="","",Lots!$D$15) | D14: =IF(Lots!$A$15="","",Lots!$F$15) | E14: =IF(Lots!$A$15="","",Lots!$O$15) | F14: =IF(Lots!$A$15="","",Lots!$L$15) | G14: =IF(Lots!$A$15="","",Lots!$Q$15) | H14: =IF(Lots!$A$15="","",Lots!$U$15) | I14: =IF(Lots!$A$15="","",Lots!$V$15)
A15: =IF(Lots!$A$16="","",Lots!$A$16) | B15: =IF(Lots!$A$16="","",Lots!$C$16) | C15: =IF(Lots!$A$16="","",Lots!$D$16) | D15: =IF(Lots!$A$16="","",Lots!$F$16) | E15: =IF(Lots!$A$16="","",Lots!$O$16) | F15: =IF(Lots!$A$16="","",Lots!$L$16) | G15: =IF(Lots!$A$16="","",Lots!$Q$16) | H15: =IF(Lots!$A$16="","",Lots!$U$16) | I15: =IF(Lots!$A$16="","",Lots!$V$16)
A16: =IF(Lots!$A$17="","",Lots!$A$17) | B16: =IF(Lots!$A$17="","",Lots!$C$17) | C16: =IF(Lots!$A$17="","",Lots!$D$17) | D16: =IF(Lots!$A$17="","",Lots!$F$17) | E16: =IF(Lots!$A$17="","",Lots!$O$17) | F16: =IF(Lots!$A$17="","",Lots!$L$17) | G16: =IF(Lots!$A$17="","",Lots!$Q$17) | H16: =IF(Lots!$A$17="","",Lots!$U$17) | I16: =IF(Lots!$A$17="","",Lots!$V$17)
A17: =IF(Lots!$A$18="","",Lots!$A$18) | B17: =IF(Lots!$A$18="","",Lots!$C$18) | C17: =IF(Lots!$A$18="","",Lots!$D$18) | D17: =IF(Lots!$A$18="","",Lots!$F$18) | E17: =IF(Lots!$A$18="","",Lots!$O$18) | F17: =IF(Lots!$A$18="","",Lots!$L$18) | G17: =IF(Lots!$A$18="","",Lots!$Q$18) | H17: =IF(Lots!$A$18="","",Lots!$U$18) | I17: =IF(Lots!$A$18="","",Lots!$V$18)
A18: =IF(Lots!$A$19="","",Lots!$A$19) | B18: =IF(Lots!$A$19="","",Lots!$C$19) | C18: =IF(Lots!$A$19="","",Lots!$D$19) | D18: =IF(Lots!$A$19="","",Lots!$F$19) | E18: =IF(Lots!$A$19="","",Lots!$O$19) | F18: =IF(Lots!$A$19="","",Lots!$L$19) | G18: =IF(Lots!$A$19="","",Lots!$Q$19) | H18: =IF(Lots!$A$19="","",Lots!$U$19) | I18: =IF(Lots!$A$19="","",Lots!$V$19)
A19: =IF(Lots!$A$20="","",Lots!$A$20) | B19: =IF(Lots!$A$20="","",Lots!$C$20) | C19: =IF(Lots!$A$20="","",Lots!$D$20) | D19: =IF(Lots!$A$20="","",Lots!$F$20) | E19: =IF(Lots!$A$20="","",Lots!$O$20) | F19: =IF(Lots!$A$20="","",Lots!$L$20) | G19: =IF(Lots!$A$20="","",Lots!$Q$20) | H19: =IF(Lots!$A$20="","",Lots!$U$20) | I19: =IF(Lots!$A$20="","",Lots!$V$20)
A20: =IF(Lots!$A$21="","",Lots!$A$21) | B20: =IF(Lots!$A$21="","",Lots!$C$21) | C20: =IF(Lots!$A$21="","",Lots!$D$21) | D20: =IF(Lots!$A$21="","",Lots!$F$21) | E20: =IF(Lots!$A$21="","",Lots!$O$21) | F20: =IF(Lots!$A$21="","",Lots!$L$21) | G20: =IF(Lots!$A$21="","",Lots!$Q$21) | H20: =IF(Lots!$A$21="","",Lots!$U$21) | I20: =IF(Lots!$A$21="","",Lots!$V$21)
A21: =IF(Lots!$A$22="","",Lots!$A$22) | B21: =IF(Lots!$A$22="","",Lots!$C$22) | C21: =IF(Lots!$A$22="","",Lots!$D$22) | D21: =IF(Lots!$A$22="","",Lots!$F$22) | E21: =IF(Lots!$A$22="","",Lots!$O$22) | F21: =IF(Lots!$A$22="","",Lots!$L$22) | G21: =IF(Lots!$A$22="","",Lots!$Q$22) | H21: =IF(Lots!$A$22="","",Lots!$U$22) | I21: =IF(Lots!$A$22="","",Lots!$V$22)
A22: =IF(Lots!$A$23="","",Lots!$A$23) | B22: =IF(Lots!$A$23="","",Lots!$C$23) | C22: =IF(Lots!$A$23="","",Lots!$D$23) | D22: =IF(Lots!$A$23="","",Lots!$F$23) | E22: =IF(Lots!$A$23="","",Lots!$O$23) | F22: =IF(Lots!$A$23="","",Lots!$L$23) | G22: =IF(Lots!$A$23="","",Lots!$Q$23) | H22: =IF(Lots!$A$23="","",Lots!$U$23) | I22: =IF(Lots!$A$23="","",Lots!$V$23)
A23: =IF(Lots!$A$24="","",Lots!$A$24) | B23: =IF(Lots!$A$24="","",Lots!$C$24) | C23: =IF(Lots!$A$24="","",Lots!$D$24) | D23: =IF(Lots!$A$24="","",Lots!$F$24) | E23: =IF(Lots!$A$24="","",Lots!$O$24) | F23: =IF(Lots!$A$24="","",Lots!$L$24) | G23: =IF(Lots!$A$24="","",Lots!$Q$24) | H23: =IF(Lots!$A$24="","",Lots!$U$24) | I23: =IF(Lots!$A$24="","",Lots!$V$24)
A24: =IF(Lots!$A$25="","",Lots!$A$25) | B24: =IF(Lots!$A$25="","",Lots!$C$25) | C24: =IF(Lots!$A$25="","",Lots!$D$25) | D24: =IF(Lots!$A$25="","",Lots!$F$25) | E24: =IF(Lots!$A$25="","",Lots!$O$25) | F24: =IF(Lots!$A$25="","",Lots!$L$25) | G24: =IF(Lots!$A$25="","",Lots!$Q$25) | H24: =IF(Lots!$A$25="","",Lots!$U$25) | I24: =IF(Lots!$A$25="","",Lots!$V$25)
A25: =IF(Lots!$A$26="","",Lots!$A$26) | B25: =IF(Lots!$A$26="","",Lots!$C$26) | C25: =IF(Lots!$A$26="","",Lots!$D$26) | D25: =IF(Lots!$A$26="","",Lots!$F$26) | E25: =IF(Lots!$A$26="","",Lots!$O$26) | F25: =IF(Lots!$A$26="","",Lots!$L$26) | G25: =IF(Lots!$A$26="","",Lots!$Q$26) | H25: =IF(Lots!$A$26="","",Lots!$U$26) | I25: =IF(Lots!$A$26="","",Lots!$V$26)
A26: =IF(Lots!$A$27="","",Lots!$A$27) | B26: =IF(Lots!$A$27="","",Lots!$C$27) | C26: =IF(Lots!$A$27="","",Lots!$D$27) | D26: =IF(Lots!$A$27="","",Lots!$F$27) | E26: =IF(Lots!$A$27="","",Lots!$O$27) | F26: =IF(Lots!$A$27="","",Lots!$L$27) | G26: =IF(Lots!$A$27="","",Lots!$Q$27) | H26: =IF(Lots!$A$27="","",Lots!$U$27) | I26: =IF(Lots!$A$27="","",Lots!$V$27)
A27: =IF(Lots!$A$28="","",Lots!$A$28) | B27: =IF(Lots!$A$28="","",Lots!$C$28) | C27: =IF(Lots!$A$28="","",Lots!$D$28) | D27: =IF(Lots!$A$28="","",Lots!$F$28) | E27: =IF(Lots!$A$28="","",Lots!$O$28) | F27: =IF(Lots!$A$28="","",Lots!$L$28) | G27: =IF(Lots!$A$28="","",Lots!$Q$28) | H27: =IF(Lots!$A$28="","",Lots!$U$28) | I27: =IF(Lots!$A$28="","",Lots!$V$28)
A28: =IF(Lots!$A$29="","",Lots!$A$29) | B28: =IF(Lots!$A$29="","",Lots!$C$29) | C28: =IF(Lots!$A$29="","",Lots!$D$29) | D28: =IF(Lots!$A$29="","",Lots!$F$29) | E28: =IF(Lots!$A$29="","",Lots!$O$29) | F28: =IF(Lots!$A$29="","",Lots!$L$29) | G28: =IF(Lots!$A$29="","",Lots!$Q$29) | H28: =IF(Lots!$A$29="","",Lots!$U$29) | I28: =IF(Lots!$A$29="","",Lots!$V$29)
A29: =IF(Lots!$A$30="","",Lots!$A$30) | B29: =IF(Lots!$A$30="","",Lots!$C$30) | C29: =IF(Lots!$A$30="","",Lots!$D$30) | D29: =IF(Lots!$A$30="","",Lots!$F$30) | E29: =IF(Lots!$A$30="","",Lots!$O$30) | F29: =IF(Lots!$A$30="","",Lots!$L$30) | G29: =IF(Lots!$A$30="","",Lots!$Q$30) | H29: =IF(Lots!$A$30="","",Lots!$U$30) | I29: =IF(Lots!$A$30="","",Lots!$V$30)
A30: =IF(Lots!$A$31="","",Lots!$A$31) | B30: =IF(Lots!$A$31="","",Lots!$C$31) | C30: =IF(Lots!$A$31="","",Lots!$D$31) | D30: =IF(Lots!$A$31="","",Lots!$F$31) | E30: =IF(Lots!$A$31="","",Lots!$O$31) | F30: =IF(Lots!$A$31="","",Lots!$L$31) | G30: =IF(Lots!$A$31="","",Lots!$Q$31) | H30: =IF(Lots!$A$31="","",Lots!$U$31) | I30: =IF(Lots!$A$31="","",Lots!$V$31)
A31: =IF(Lots!$A$32="","",Lots!$A$32) | B31: =IF(Lots!$A$32="","",Lots!$C$32) | C31: =IF(Lots!$A$32="","",Lots!$D$32) | D31: =IF(Lots!$A$32="","",Lots!$F$32) | E31: =IF(Lots!$A$32="","",Lots!$O$32) | F31: =IF(Lots!$A$32="","",Lots!$L$32) | G31: =IF(Lots!$A$32="","",Lots!$Q$32) | H31: =IF(Lots!$A$32="","",Lots!$U$32) | I31: =IF(Lots!$A$32="","",Lots!$V$32)
A32: =IF(Lots!$A$33="","",Lots!$A$33) | B32: =IF(Lots!$A$33="","",Lots!$C$33) | C32: =IF(Lots!$A$33="","",Lots!$D$33) | D32: =IF(Lots!$A$33="","",Lots!$F$33) | E32: =IF(Lots!$A$33="","",Lots!$O$33) | F32: =IF(Lots!$A$33="","",Lots!$L$33) | G32: =IF(Lots!$A$33="","",Lots!$Q$33) | H32: =IF(Lots!$A$33="","",Lots!$U$33) | I32: =IF(Lots!$A$33="","",Lots!$V$33)
A33: =IF(Lots!$A$34="","",Lots!$A$34) | B33: =IF(Lots!$A$34="","",Lots!$C$34) | C33: =IF(Lots!$A$34="","",Lots!$D$34) | D33: =IF(Lots!$A$34="","",Lots!$F$34) | E33: =IF(Lots!$A$34="","",Lots!$O$34) | F33: =IF(Lots!$A$34="","",Lots!$L$34) | G33: =IF(Lots!$A$34="","",Lots!$Q$34) | H33: =IF(Lots!$A$34="","",Lots!$U$34) | I33: =IF(Lots!$A$34="","",Lots!$V$34)
A34: =IF(Lots!$A$35="","",Lots!$A$35) | B34: =IF(Lots!$A$35="","",Lots!$C$35) | C34: =IF(Lots!$A$35="","",Lots!$D$35) | D34: =IF(Lots!$A$35="","",Lots!$F$35) | E34: =IF(Lots!$A$35="","",Lots!$O$35) | F34: =IF(Lots!$A$35="","",Lots!$L$35) | G34: =IF(Lots!$A$35="","",Lots!$Q$35) | H34: =IF(Lots!$A$35="","",Lots!$U$35) | I34: =IF(Lots!$A$35="","",Lots!$V$35)
A35: =IF(Lots!$A$36="","",Lots!$A$36) | B35: =IF(Lots!$A$36="","",Lots!$C$36) | C35: =IF(Lots!$A$36="","",Lots!$D$36) | D35: =IF(Lots!$A$36="","",Lots!$F$36) | E35: =IF(Lots!$A$36="","",Lots!$O$36) | F35: =IF(Lots!$A$36="","",Lots!$L$36) | G35: =IF(Lots!$A$36="","",Lots!$Q$36) | H35: =IF(Lots!$A$36="","",Lots!$U$36) | I35: =IF(Lots!$A$36="","",Lots!$V$36)
A36: =IF(Lots!$A$37="","",Lots!$A$37) | B36: =IF(Lots!$A$37="","",Lots!$C$37) | C36: =IF(Lots!$A$37="","",Lots!$D$37) | D36: =IF(Lots!$A$37="","",Lots!$F$37) | E36: =IF(Lots!$A$37="","",Lots!$O$37) | F36: =IF(Lots!$A$37="","",Lots!$L$37) | G36: =IF(Lots!$A$37="","",Lots!$Q$37) | H36: =IF(Lots!$A$37="","",Lots!$U$37) | I36: =IF(Lots!$A$37="","",Lots!$V$37)
A37: =IF(Lots!$A$38="","",Lots!$A$38) | B37: =IF(Lots!$A$38="","",Lots!$C$38) | C37: =IF(Lots!$A$38="","",Lots!$D$38) | D37: =IF(Lots!$A$38="","",Lots!$F$38) | E37: =IF(Lots!$A$38="","",Lots!$O$38) | F37: =IF(Lots!$A$38="","",Lots!$L$38) | G37: =IF(Lots!$A$38="","",Lots!$Q$38) | H37: =IF(Lots!$A$38="","",Lots!$U$38) | I37: =IF(Lots!$A$38="","",Lots!$V$38)
A38: =IF(Lots!$A$39="","",Lots!$A$39) | B38: =IF(Lots!$A$39="","",Lots!$C$39) | C38: =IF(Lots!$A$39="","",Lots!$D$39) | D38: =IF(Lots!$A$39="","",Lots!$F$39) | E38: =IF(Lots!$A$39="","",Lots!$O$39) | F38: =IF(Lots!$A$39="","",Lots!$L$39) | G38: =IF(Lots!$A$39="","",Lots!$Q$39) | H38: =IF(Lots!$A$39="","",Lots!$U$39) | I38: =IF(Lots!$A$39="","",Lots!$V$39)
A39: =IF(Lots!$A$40="","",Lots!$A$40) | B39: =IF(Lots!$A$40="","",Lots!$C$40) | C39: =IF(Lots!$A$40="","",Lots!$D$40) | D39: =IF(Lots!$A$40="","",Lots!$F$40) | E39: =IF(Lots!$A$40="","",Lots!$O$40) | F39: =IF(Lots!$A$40="","",Lots!$L$40) | G39: =IF(Lots!$A$40="","",Lots!$Q$40) | H39: =IF(Lots!$A$40="","",Lots!$U$40) | I39: =IF(Lots!$A$40="","",Lots!$V$40)
A40: =IF(Lots!$A$41="","",Lots!$A$41) | B40: =IF(Lots!$A$41="","",Lots!$C$41) | C40: =IF(Lots!$A$41="","",Lots!$D$41) | D40: =IF(Lots!$A$41="","",Lots!$F$41) | E40: =IF(Lots!$A$41="","",Lots!$O$41) | F40: =IF(Lots!$A$41="","",Lots!$L$41) | G40: =IF(Lots!$A$41="","",Lots!$Q$41) | H40: =IF(Lots!$A$41="","",Lots!$U$41) | I40: =IF(Lots!$A$41="","",Lots!$V$41)
A41: =IF(Lots!$A$42="","",Lots!$A$42) | B41: =IF(Lots!$A$42="","",Lots!$C$42) | C41: =IF(Lots!$A$42="","",Lots!$D$42) | D41: =IF(Lots!$A$42="","",Lots!$F$42) | E41: =IF(Lots!$A$42="","",Lots!$O$42) | F41: =IF(Lots!$A$42="","",Lots!$L$42) | G41: =IF(Lots!$A$42="","",Lots!$Q$42) | H41: =IF(Lots!$A$42="","",Lots!$U$42) | I41: =IF(Lots!$A$42="","",Lots!$V$42)
A42: =IF(Lots!$A$43="","",Lots!$A$43) | B42: =IF(Lots!$A$43="","",Lots!$C$43) | C42: =IF(Lots!$A$43="","",Lots!$D$43) | D42: =IF(Lots!$A$43="","",Lots!$F$43) | E42: =IF(Lots!$A$43="","",Lots!$O$43) | F42: =IF(Lots!$A$43="","",Lots!$L$43) | G42: =IF(Lots!$A$43="","",Lots!$Q$43) | H42: =IF(Lots!$A$43="","",Lots!$U$43) | I42: =IF(Lots!$A$43="","",Lots!$V$43)
A43: =IF(Lots!$A$44="","",Lots!$A$44) | B43: =IF(Lots!$A$44="","",Lots!$C$44) | C43: =IF(Lots!$A$44="","",Lots!$D$44) | D43: =IF(Lots!$A$44="","",Lots!$F$44) | E43: =IF(Lots!$A$44="","",Lots!$O$44) | F43: =IF(Lots!$A$44="","",Lots!$L$44) | G43: =IF(Lots!$A$44="","",Lots!$Q$44) | H43: =IF(Lots!$A$44="","",Lots!$U$44) | I43: =IF(Lots!$A$44="","",Lots!$V$44)
...
